Workbook

Sheet 01-汇报摘要
A1: 天猫近3个月 · ID周净利润分析汇报（数据源1口径）
A2: 本页周数据均引用「01-整体周趋势」公式汇总（源自数据源1）；其他费用已按周报校准。
A4: 一、核心结论
A5: 序号 | B5: 内容
A6: 结论1 | B6: 近三个月ID口径持续亏损；最好一周是7.6-7.12（推广后约-4109）。
A7: 结论2 | B7: 利润下降主要集中在大链接：551, 747, 438（袋面次链接, 袋面主链接, 杯面主链接）。
A8: 结论3 | B8: 7.6→7.13回落主因是推广前利润下降（袋面主链等）；7.13→7.20更多是推广费抬升。
A9: 结论4 | B9: 大大包有利润补充但推广后常被侵蚀，不是本轮主亏来源；需控加投。
A11: 二、近三个月阶段拆解（按数据源周序）
A12: 阶段 | B12: 周区间 | C12: 主因 | D12: 说明
A13: 阶段A | B13: 5.11 → 6.22 | C13: 主要是推广前利润下降 | D13: 成交与推广前利润同步走弱
A14: 阶段B | B14: 6.22 → 7.6 | C14: 本期改善 | D14: 触底后回升，7.6为最好周
A15: 阶段C | B15: 7.6 → 7.13 | C15: 主要是推广前利润下降 | D15: 主链回落带动整体转差
A16: 阶段D | B16: 7.13 → 7.20 | C16: 主要是推广费上升 | D16: 推广花费抬升，利润再下探
A17: 阶段E | B17: 7.20 → 7.27 | C17: 本期改善 | D17: 推广后利润小幅修复
A20: 三、数据源逐周明细（公式引用整体周趋势）
A21: 周次 | B21: 成交金额 | C21: 推广前利润 | D21: 推广前环比 | E21: 推广花费 | F21: 推广费环比 | G21: 其他费用 | H21: 推广后利润 | I21: 推广后环比 | J21: 推广费率 | K21: 下降主因
A22: 5.11-5.17 | B22: ='01-整体周趋势'!B5 | C22: ='01-整体周趋势'!C5 | E22: ='01-整体周趋势'!D5 | G22: ='01-整体周趋势'!E5 | H22: ='01-整体周趋势'!F5 | J22: =IFERROR(E22/B22,0)
A23: 5.25-5.31 | B23: ='01-整体周趋势'!B6 | C23: ='01-整体周趋势'!C6 | D23: =C23-C22 | E23: ='01-整体周趋势'!D6 | F23: =E23-E22 | G23: ='01-整体周趋势'!E6 | H23: ='01-整体周趋势'!F6 | I23: =H23-H22 | J23: =IFERROR(E23/B23,0) | K23: 本期改善
A24: 6.15-6.21 | B24: ='01-整体周趋势'!B7 | C24: ='01-整体周趋势'!C7 | D24: =C24-C23 | E24: ='01-整体周趋势'!D7 | F24: =E24-E23 | G24: ='01-整体周趋势'!E7 | H24: ='01-整体周趋势'!F7 | I24: =H24-H23 | J24: =IFERROR(E24/B24,0) | K24: 主要是推广前利润下降
A25: 6.22-6.28 | B25: ='01-整体周趋势'!B8 | C25: ='01-整体周趋势'!C8 | D25: =C25-C24 | E25: ='01-整体周趋势'!D8 | F25: =E25-E24 | G25: ='01-整体周趋势'!E8 | H25: ='01-整体周趋势'!F8 | I25: =H25-H24 | J25: =IFERROR(E25/B25,0) | K25: 本期改善
A26: 6.29-7.5 | B26: ='01-整体周趋势'!B9 | C26: ='01-整体周趋势'!C9 | D26: =C26-C25 | E26: ='01-整体周趋势'!D9 | F26: =E26-E25 | G26: ='01-整体周趋势'!E9 | H26: ='01-整体周趋势'!F9 | I26: =H26-H25 | J26: =IFERROR(E26/B26,0) | K26: 本期改善
A27: 7.6-7.12 | B27: ='01-整体周趋势'!B10 | C27: ='01-整体周趋势'!C10 | D27: =C27-C26 | E27: ='01-整体周趋势'!D10 | F27: =E27-E26 | G27: ='01-整体周趋势'!E10 | H27: ='01-整体周趋势'!F10 | I27: =H27-H26 | J27: =IFERROR(E27/B27,0) | K27: 本期改善
A28: 7.13-7.19 | B28: ='01-整体周趋势'!B11 | C28: ='01-整体周趋势'!C11 | D28: =C28-C27 | E28: ='01-整体周趋势'!D11 | F28: =E28-E27 | G28: ='01-整体周趋势'!E11 | H28: ='01-整体周趋势'!F11 | I28: =H28-H27 | J28: =IFERROR(E28/B28,0) | K28: 主要是推广前利润下降
A29: 7.20-7.26 | B29: ='01-整体周趋势'!B12 | C29: ='01-整体周趋势'!C12 | D29: =C29-C28 | E29: ='01-整体周趋势'!D12 | F29: =E29-E28 | G29: ='01-整体周趋势'!E12 | H29: ='01-整体周趋势'!F12 | I29: =H29-H28 | J29: =IFERROR(E29/B29,0) | K29: 主要是推广费上升
A30: 7.27-8.2 | B30: ='01-整体周趋势'!B13 | C30: ='01-整体周趋势'!C13 | D30: =C30-C29 | E30: ='01-整体周趋势'!D13 | F30: =E30-E29 | G30: ='01-整体周趋势'!E13 | H30: ='01-整体周趋势'!F13 | I30: =H30-H29 | J30: =IFERROR(E30/B30,0) | K30: 本期改善

Sheet 01-整体周趋势
A1: 整体经营周趋势（口径：数据源1 · ID周损益合计）
A2: 成交/推广前/推广花费/其他费用/推广后均由数据源1按周SUMIF汇总；推广后也可用 推广前-(推广花费+其他费用)/1.06 校验。
A4: 周次 | B4: 成交金额 | C4: 推广前净利润 | D4: 推广花费 | E4: 其他费用 | F4: 推广后净利润 | G4: 环比_推广后 | I4: 校验_推广后=前-(花费+其他)/1.06
A5: 5.11-5.17 | B5: =SUMIF(数据源1!A:A,A5,数据源1!F:F) | C5: =SUMIF(数据源1!A:A,A5,数据源1!Y:Y) | D5: =SUMIF(数据源1!A:A,A5,数据源1!Q:Q) | E5: =SUMIF(数据源1!A:A,A5,数据源1!X:X) | F5: =SUMIF(数据源1!A:A,A5,数据源1!AC:AC) | I5: =C5-(D5+E5)/1.06
A6: 5.25-5.31 | B6: =SUMIF(数据源1!A:A,A6,数据源1!F:F) | C6: =SUMIF(数据源1!A:A,A6,数据源1!Y:Y) | D6: =SUMIF(数据源1!A:A,A6,数据源1!Q:Q) | E6: =SUMIF(数据源1!A:A,A6,数据源1!X:X) | F6: =SUMIF(数据源1!A:A,A6,数据源1!AC:AC) | G6: =F6-F5 | I6: =C6-(D6+E6)/1.06
A7: 6.15-6.21 | B7: =SUMIF(数据源1!A:A,A7,数据源1!F:F) | C7: =SUMIF(数据源1!A:A,A7,数据源1!Y:Y) | D7: =SUMIF(数据源1!A:A,A7,数据源1!Q:Q) | E7: =SUMIF(数据源1!A:A,A7,数据源1!X:X) | F7: =SUMIF(数据源1!A:A,A7,数据源1!AC:AC) | G7: =F7-F6 | I7: =C7-(D7+E7)/1.06
A8: 6.22-6.28 | B8: =SUMIF(数据源1!A:A,A8,数据源1!F:F) | C8: =SUMIF(数据源1!A:A,A8,数据源1!Y:Y) | D8: =SUMIF(数据源1!A:A,A8,数据源1!Q:Q) | E8: =SUMIF(数据源1!A:A,A8,数据源1!X:X) | F8: =SUMIF(数据源1!A:A,A8,数据源1!AC:AC) | G8: =F8-F7 | I8: =C8-(D8+E8)/1.06
A9: 6.29-7.5 | B9: =SUMIF(数据源1!A:A,A9,数据源1!F:F) | C9: =SUMIF(数据源1!A:A,A9,数据源1!Y:Y) | D9: =SUMIF(数据源1!A:A,A9,数据源1!Q:Q) | E9: =SUMIF(数据源1!A:A,A9,数据源1!X:X) | F9: =SUMIF(数据源1!A:A,A9,数据源1!AC:AC) | G9: =F9-F8 | I9: =C9-(D9+E9)/1.06
A10: 7.6-7.12 | B10: =SUMIF(数据源1!A:A,A10,数据源1!F:F) | C10: =SUMIF(数据源1!A:A,A10,数据源1!Y:Y) | D10: =SUMIF(数据源1!A:A,A10,数据源1!Q:Q) | E10: =SUMIF(数据源1!A:A,A10,数据源1!X:X) | F10: =SUMIF(数据源1!A:A,A10,数据源1!AC:AC) | G10: =F10-F9 | I10: =C10-(D10+E10)/1.06
A11: 7.13-7.19 | B11: =SUMIF(数据源1!A:A,A11,数据源1!F:F) | C11: =SUMIF(数据源1!A:A,A11,数据源1!Y:Y) | D11: =SUMIF(数据源1!A:A,A11,数据源1!Q:Q) | E11: =SUMIF(数据源1!A:A,A11,数据源1!X:X) | F11: =SUMIF(数据源1!A:A,A11,数据源1!AC:AC) | G11: =F11-F10 | I11: =C11-(D11+E11)/1.06
A12: 7.20-7.26 | B12: =SUMIF(数据源1!A:A,A12,数据源1!F:F) | C12: =SUMIF(数据源1!A:A,A12,数据源1!Y:Y) | D12: =SUMIF(数据源1!A:A,A12,数据源1!Q:Q) | E12: =SUMIF(数据源1!A:A,A12,数据源1!X:X) | F12: =SUMIF(数据源1!A:A,A12,数据源1!AC:AC) | G12: =F12-F11 | I12: =C12-(D12+E12)/1.06
A13: 7.27-8.2 | B13: =SUMIF(数据源1!A:A,A13,数据源1!F:F) | C13: =SUMIF(数据源1!A:A,A13,数据源1!Y:Y) | D13: =SUMIF(数据源1!A:A,A13,数据源1!Q:Q) | E13: =SUMIF(数据源1!A:A,A13,数据源1!X:X) | F13: =SUMIF(数据源1!A:A,A13,数据源1!AC:AC) | G13: =F13-F12 | I13: =C13-(D13+E13)/1.06

Sheet 03-近周回落归因
A1: 近周利润回落归因（7.6-7.12 → 7.13-7.19，数据源1·推广后净利润）
A2: 变化=后周-前周；负值=拖累。ID利润取自数据源1（其他费用已按周报×件数占比，推广后=推广前-(推广总花费+其他费用)/1.06）。
A3: 拖累 TOP10（变化越负，拖累越大）
A4: 排名 | B4: 商品ID | C4: 定位 | D4: 商品名称 | E4: 7.6-7.12 | F4: 7.13-7.19 | G4: 变化
A5: 1 | B5: 668566625747 | C5: 袋面主链接 | D5: 印尼营多捞面进口网红泡面袋装方便面速食食品拉面火鸡面拌面整箱 | E5: -911.42 | F5: -1577.82 | G5: =F5-E5
A6: 2 | B6: 648600900806 | C6: 30包 | D6: 进口营多捞面一整箱30包网红速食方便面宿舍速食泡面干拌面拉面 | E6: 41.33 | F6: -202.24 | G6: =F6-E6
A7: 3 | B7: 649369494424 | C7: 24包经典/牛系列 | D7: 营多捞面干拌面一整箱24袋装批发泡面混搭宿舍速食方便面火鸡面 | E7: 457.42 | F7: 246.8 | G7: =F7-E7
A8: 4 | B8: 766165464414 | C8: 12包 | D8: 营多印尼进口营多捞面方便面火鸡面干拌面12包宿舍速食泡面夜宵 | E8: 129.27 | F8: 9.81 | G8: =F8-E8
A9: 5 | B9: 648598580775 | C9: 原味大包 | D9: 印尼进口大大包营多原味捞面5包干拌面速食超大包方便面速食宵夜 | E9: 63.6 | F9: -36.63 | G9: =F9-E9
A10: 6 | B10: 1059563993918 | C10: 原味大包 | D10: indomie印尼进口营多原味大大包129g捞面方便面速食食品宵夜小吃 | E10: -50.18 | F10: -115.11 | G10: =F10-E10
A11: 7 | B11: 649014937782 | C11: 24包 | D11: 印尼营多捞面干拌面一整箱24袋装批发泡面宿舍速食方便面火鸡面 | E11: -4.94 | F11: -62.79 | G11: =F11-E11
A12: 8 | B12: 1013887677295 | C12: 混搭5杯 | D12: 进口营多原味杯面日式杯面韩式杯面泡面方便面汤面宿舍速食夜宵 | E12: -127.65 | F12: -173.79 | G12: =F12-E12
A13: 9 | B13: 648604228786 | C13: 杯面混搭 | D13: INDOMIE营多日式杯面原味经典泡面整箱批发速食宿舍旅行宵夜宿舍 | E13: 16.38 | F13: -14.73 | G13: =F13-E13
A14: 10 | B14: 735014804839 | C14: 24/30包 | D14: 进口营多捞面多口味Indomie网红方便面干拌面泡面30包整箱批发面 | E14: 107.63 | F14: 78.69 | G14: =F14-E14
A16: 改善 TOP5（变化为正，对冲回落）
A17: 排名 | B17: 商品ID | C17: 定位 | D17: 商品名称 | E17: 7.6-7.12 | F17: 7.13-7.19 | G17: 变化
A18: 1 | B18: 649361890551 | C18: 袋面次链接 | D18: 营多捞面印尼进口Indomie网红夜宵早餐方便面火鸡面泡面拌面 | E18: -1807.89 | F18: -1447.22 | G18: =F18-E18
A19: 2 | B19: 649735171438 | C19: 杯面主链接 | D19: 印尼进口indomie营多捞面杯面速食泡面干拌面盒桶装方便面火鸡面 | E19: -1023.86 | F19: -962.74 | G19: =F19-E19
A20: 3 | B20: 648681860568 | C20: 巴东牛肉 | D20: 营多进口新口味巴东炖牛肉味捞面印尼料理方便面泡面捞面夜宵速食 | E20: -160.09 | F20: -99.85 | G20: =F20-E20
A21: 4 | B21: 971242260371 | C21: 韩式袋面 | D21: 新品营多捞面韩式辣蘑菇汤面泡面方便面速食干拌面宿舍宵夜旅行 | E21: -59.92 | F21: -21.25 | G21: =F21-E21
A22: 5 | B22: 1058280415678 | C22: 巴东牛肉 | D22: 【新口味】印尼进口营多捞面巴东炖牛肉味泡面方便面宿舍速食宵夜 | E22: 29.25 | F22: 51.68 | G22: =F22-E22
A24: 本阶段数据源合计变化 | B24: -1072.39 | C24: =SUMIF(数据源1!A:A,"7.13-7.19",数据源1!AC:AC)-SUMIF(数据源1!A:A,"7.6-7.12",数据源1!AC:AC) | D24: ←公式校验（应与B24接近）

Sheet 02-原味大大专题
A1: 原味大大包专题（数据源1：定位=大大 / 原味大包）
A2: 汇总与明细均按数据源1筛选；推广侵蚀=推广前-推广后。
A3: 汇总：大大相关链接按周
A4: 周次 | B4: 成交金额 | C4: 推广前净利润 | D4: 推广花费 | E4: 其他费用 | F4: 推广后净利润 | G4: 推广侵蚀 | H4: 链接数
A5: 6.22-6.28 | B5: =SUMIFS(数据源1!F:F,数据源1!A:A,A5,数据源1!D:D,"大大")+SUMIFS(数据源1!F:F,数据源1!A:A,A5,数据源1!D:D,"原味大包") | C5: =SUMIFS(数据源1!Y:Y,数据源1!A:A,A5,数据源1!D:D,"大大")+SUMIFS(数据源1!Y:Y,数据源1!A:A,A5,数据源1!D:D,"原味大包") | D5: =SUMIFS(数据源1!Q:Q,数据源1!A:A,A5,数据源1!D:D,"大大")+SUMIFS(数据源1!Q:Q,数据源1!A:A,A5,数据源1!D:D,"原味大包") | E5: =SUMIFS(数据源1!X:X,数据源1!A:A,A5,数据源1!D:D,"大大")+SUMIFS(数据源1!X:X,数据源1!A:A,A5,数据源1!D:D,"原味大包") | F5: =SUMIFS(数据源1!AC:AC,数据源1!A:A,A5,数据源1!D:D,"大大")+SUMIFS(数据源1!AC:AC,数据源1!A:A,A5,数据源1!D:D,"原味大包") | G5: =C5-F5 | H5: =COUNTIFS(数据源1!A:A,A5,数据源1!D:D,"大大")+COUNTIFS(数据源1!A:A,A5,数据源1!D:D,"原味大包")
A6: 6.29-7.5 | B6: =SUMIFS(数据源1!F:F,数据源1!A:A,A6,数据源1!D:D,"大大")+SUMIFS(数据源1!F:F,数据源1!A:A,A6,数据源1!D:D,"原味大包") | C6: =SUMIFS(数据源1!Y:Y,数据源1!A:A,A6,数据源1!D:D,"大大")+SUMIFS(数据源1!Y:Y,数据源1!A:A,A6,数据源1!D:D,"原味大包") | D6: =SUMIFS(数据源1!Q:Q,数据源1!A:A,A6,数据源1!D:D,"大大")+SUMIFS(数据源1!Q:Q,数据源1!A:A,A6,数据源1!D:D,"原味大包") | E6: =SUMIFS(数据源1!X:X,数据源1!A:A,A6,数据源1!D:D,"大大")+SUMIFS(数据源1!X:X,数据源1!A:A,A6,数据源1!D:D,"原味大包") | F6: =SUMIFS(数据源1!AC:AC,数据源1!A:A,A6,数据源1!D:D,"大大")+SUMIFS(数据源1!AC:AC,数据源1!A:A,A6,数据源1!D:D,"原味大包") | G6: =C6-F6 | H6: =COUNTIFS(数据源1!A:A,A6,数据源1!D:D,"大大")+COUNTIFS(数据源1!A:A,A6,数据源1!D:D,"原味大包")
A7: 7.6-7.12 | B7: =SUMIFS(数据源1!F:F,数据源1!A:A,A7,数据源1!D:D,"大大")+SUMIFS(数据源1!F:F,数据源1!A:A,A7,数据源1!D:D,"原味大包") | C7: =SUMIFS(数据源1!Y:Y,数据源1!A:A,A7,数据源1!D:D,"大大")+SUMIFS(数据源1!Y:Y,数据源1!A:A,A7,数据源1!D:D,"原味大包") | D7: =SUMIFS(数据源1!Q:Q,数据源1!A:A,A7,数据源1!D:D,"大大")+SUMIFS(数据源1!Q:Q,数据源1!A:A,A7,数据源1!D:D,"原味大包") | E7: =SUMIFS(数据源1!X:X,数据源1!A:A,A7,数据源1!D:D,"大大")+SUMIFS(数据源1!X:X,数据源1!A:A,A7,数据源1!D:D,"原味大包") | F7: =SUMIFS(数据源1!AC:AC,数据源1!A:A,A7,数据源1!D:D,"大大")+SUMIFS(数据源1!AC:AC,数据源1!A:A,A7,数据源1!D:D,"原味大包") | G7: =C7-F7 | H7: =COUNTIFS(数据源1!A:A,A7,数据源1!D:D,"大大")+COUNTIFS(数据源1!A:A,A7,数据源1!D:D,"原味大包")
A8: 7.13-7.19 | B8: =SUMIFS(数据源1!F:F,数据源1!A:A,A8,数据源1!D:D,"大大")+SUMIFS(数据源1!F:F,数据源1!A:A,A8,数据源1!D:D,"原味大包") | C8: =SUMIFS(数据源1!Y:Y,数据源1!A:A,A8,数据源1!D:D,"大大")+SUMIFS(数据源1!Y:Y,数据源1!A:A,A8,数据源1!D:D,"原味大包") | D8: =SUMIFS(数据源1!Q:Q,数据源1!A:A,A8,数据源1!D:D,"大大")+SUMIFS(数据源1!Q:Q,数据源1!A:A,A8,数据源1!D:D,"原味大包") | E8: =SUMIFS(数据源1!X:X,数据源1!A:A,A8,数据源1!D:D,"大大")+SUMIFS(数据源1!X:X,数据源1!A:A,A8,数据源1!D:D,"原味大包") | F8: =SUMIFS(数据源1!AC:AC,数据源1!A:A,A8,数据源1!D:D,"大大")+SUMIFS(数据源1!AC:AC,数据源1!A:A,A8,数据源1!D:D,"原味大包") | G8: =C8-F8 | H8: =COUNTIFS(数据源1!A:A,A8,数据源1!D:D,"大大")+COUNTIFS(数据源1!A:A,A8,数据源1!D:D,"原味大包")
A9: 7.20-7.26 | B9: =SUMIFS(数据源1!F:F,数据源1!A:A,A9,数据源1!D:D,"大大")+SUMIFS(数据源1!F:F,数据源1!A:A,A9,数据源1!D:D,"原味大包") | C9: =SUMIFS(数据源1!Y:Y,数据源1!A:A,A9,数据源1!D:D,"大大")+SUMIFS(数据源1!Y:Y,数据源1!A:A,A9,数据源1!D:D,"原味大包") | D9: =SUMIFS(数据源1!Q:Q,数据源1!A:A,A9,数据源1!D:D,"大大")+SUMIFS(数据源1!Q:Q,数据源1!A:A,A9,数据源1!D:D,"原味大包") | E9: =SUMIFS(数据源1!X:X,数据源1!A:A,A9,数据源1!D:D,"大大")+SUMIFS(数据源1!X:X,数据源1!A:A,A9,数据源1!D:D,"原味大包") | F9: =SUMIFS(数据源1!AC:AC,数据源1!A:A,A9,数据源1!D:D,"大大")+SUMIFS(数据源1!AC:AC,数据源1!A:A,A9,数据源1!D:D,"原味大包") | G9: =C9-F9 | H9: =COUNTIFS(数据源1!A:A,A9,数据源1!D:D,"大大")+COUNTIFS(数据源1!A:A,A9,数据源1!D:D,"原味大包")
A10: 7.27-8.2 | B10: =SUMIFS(数据源1!F:F,数据源1!A:A,A10,数据源1!D:D,"大大")+SUMIFS(数据源1!F:F,数据源1!A:A,A10,数据源1!D:D,"原味大包") | C10: =SUMIFS(数据源1!Y:Y,数据源1!A:A,A10,数据源1!D:D,"大大")+SUMIFS(数据源1!Y:Y,数据源1!A:A,A10,数据源1!D:D,"原味大包") | D10: =SUMIFS(数据源1!Q:Q,数据源1!A:A,A10,数据源1!D:D,"大大")+SUMIFS(数据源1!Q:Q,数据源1!A:A,A10,数据源1!D:D,"原味大包") | E10: =SUMIFS(数据源1!X:X,数据源1!A:A,A10,数据源1!D:D,"大大")+SUMIFS(数据源1!X:X,数据源1!A:A,A10,数据源1!D:D,"原味大包") | F10: =SUMIFS(数据源1!AC:AC,数据源1!A:A,A10,数据源1!D:D,"大大")+SUMIFS(数据源1!AC:AC,数据源1!A:A,A10,数据源1!D:D,"原味大包") | G10: =C10-F10 | H10: =COUNTIFS(数据源1!A:A,A10,数据源1!D:D,"大大")+COUNTIFS(数据源1!A:A,A10,数据源1!D:D,"原味大包")
A13: 明细：大大相关 ID × 周（数据源1）
A14: 周次 | B14: 商品ID | C14: 定位 | D14: 商品名称 | E14: 成交金额 | F14: 推广前净利润 | G14: 推广花费 | H14: 其他费用 | I14: 推广后净利润
A15: 6.22-6.28 | B15: 1058280415678 | C15: 大大 | D15: 印尼进口大大包营多原味捞面5包干拌面速食超大包方便面速食宵夜 | E15: =SUMIFS(数据源1!F:F,数据源1!A:A,A15,数据源1!C:C,B15) | F15: =SUMIFS(数据源1!Y:Y,数据源1!A:A,A15,数据源1!C:C,B15) | G15: =SUMIFS(数据源1!Q:Q,数据源1!A:A,A15,数据源1!C:C,B15) | H15: =SUMIFS(数据源1!X:X,数据源1!A:A,A15,数据源1!C:C,B15) | I15: =SUMIFS(数据源1!AC:AC,数据源1!A:A,A15,数据源1!C:C,B15)
A16: 6.22-6.28 | B16: 1060999732877 | C16: 大大 | D16: indomie印尼进口营多原味大大包129g捞面方便面速食食品宵夜小吃 | E16: =SUMIFS(数据源1!F:F,数据源1!A:A,A16,数据源1!C:C,B16) | F16: =SUMIFS(数据源1!Y:Y,数据源1!A:A,A16,数据源1!C:C,B16) | G16: =SUMIFS(数据源1!Q:Q,数据源1!A:A,A16,数据源1!C:C,B16) | H16: =SUMIFS(数据源1!X:X,数据源1!A:A,A16,数据源1!C:C,B16) | I16: =SUMIFS(数据源1!AC:AC,数据源1!A:A,A16,数据源1!C:C,B16)
A17: 6.29-7.5 | B17: 1058280415678 | C17: 原味大包 | D17: 印尼进口大大包营多原味捞面5包干拌面速食超大包方便面速食宵夜 | E17: =SUMIFS(数据源1!F:F,数据源1!A:A,A17,数据源1!C:C,B17) | F17: =SUMIFS(数据源1!Y:Y,数据源1!A:A,A17,数据源1!C:C,B17) | G17: =SUMIFS(数据源1!Q:Q,数据源1!A:A,A17,数据源1!C:C,B17) | H17: =SUMIFS(数据源1!X:X,数据源1!A:A,A17,数据源1!C:C,B17) | I17: =SUMIFS(数据源1!AC:AC,数据源1!A:A,A17,数据源1!C:C,B17)
A18: 6.29-7.5 | B18: 1060999732877 | C18: 原味大包 | D18: indomie印尼进口营多原味大大包129g捞面方便面速食食品宵夜小吃 | E18: =SUMIFS(数据源1!F:F,数据源1!A:A,A18,数据源1!C:C,B18) | F18: =SUMIFS(数据源1!Y:Y,数据源1!A:A,A18,数据源1!C:C,B18) | G18: =SUMIFS(数据源1!Q:Q,数据源1!A:A,A18,数据源1!C:C,B18) | H18: =SUMIFS(数据源1!X:X,数据源1!A:A,A18,数据源1!C:C,B18) | I18: =SUMIFS(数据源1!AC:AC,数据源1!A:A,A18,数据源1!C:C,B18)
A19: 7.13-7.19 | B19: 648598580775 | C19: 原味大包 | D19: 印尼进口大大包营多原味捞面5包干拌面速食超大包方便面速食宵夜 | E19: =SUMIFS(数据源1!F:F,数据源1!A:A,A19,数据源1!C:C,B19) | F19: =SUMIFS(数据源1!Y:Y,数据源1!A:A,A19,数据源1!C:C,B19) | G19: =SUMIFS(数据源1!Q:Q,数据源1!A:A,A19,数据源1!C:C,B19) | H19: =SUMIFS(数据源1!X:X,数据源1!A:A,A19,数据源1!C:C,B19) | I19: =SUMIFS(数据源1!AC:AC,数据源1!A:A,A19,数据源1!C:C,B19)
A20: 7.13-7.19 | B20: 1060999732877 | C20: 原味大包 | D20: indomie印尼进口营多原味大大包129g捞面方便面速食食品宵夜小吃 | E20: =SUMIFS(数据源1!F:F,数据源1!A:A,A20,数据源1!C:C,B20) | F20: =SUMIFS(数据源1!Y:Y,数据源1!A:A,A20,数据源1!C:C,B20) | G20: =SUMIFS(数据源1!Q:Q,数据源1!A:A,A20,数据源1!C:C,B20) | H20: =SUMIFS(数据源1!X:X,数据源1!A:A,A20,数据源1!C:C,B20) | I20: =SUMIFS(数据源1!AC:AC,数据源1!A:A,A20,数据源1!C:C,B20)
A21: 7.13-7.19 | B21: 1059563993918 | C21: 原味大包 | D21: indomie印尼进口营多原味大大包129g捞面方便面速食食品宵夜小吃 | E21: =SUMIFS(数据源1!F:F,数据源1!A:A,A21,数据源1!C:C,B21) | F21: =SUMIFS(数据源1!Y:Y,数据源1!A:A,A21,数据源1!C:C,B21) | G21: =SUMIFS(数据源1!Q:Q,数据源1!A:A,A21,数据源1!C:C,B21) | H21: =SUMIFS(数据源1!X:X,数据源1!A:A,A21,数据源1!C:C,B21) | I21: =SUMIFS(数据源1!AC:AC,数据源1!A:A,A21,数据源1!C:C,B21)
A22: 7.20-7.26 | B22: 649014937782 | C22: 原味大包 | D22: indomie印尼进口营多原味大大包129g捞面方便面速食食品宵夜小吃 | E22: =SUMIFS(数据源1!F:F,数据源1!A:A,A22,数据源1!C:C,B22) | F22: =SUMIFS(数据源1!Y:Y,数据源1!A:A,A22,数据源1!C:C,B22) | G22: =SUMIFS(数据源1!Q:Q,数据源1!A:A,A22,数据源1!C:C,B22) | H22: =SUMIFS(数据源1!X:X,数据源1!A:A,A22,数据源1!C:C,B22) | I22: =SUMIFS(数据源1!AC:AC,数据源1!A:A,A22,数据源1!C:C,B22)
A23: 7.20-7.26 | B23: 648598580775 | C23: 原味大包 | D23: 印尼进口大大包营多原味捞面5包干拌面速食超大包方便面速食宵夜 | E23: =SUMIFS(数据源1!F:F,数据源1!A:A,A23,数据源1!C:C,B23) | F23: =SUMIFS(数据源1!Y:Y,数据源1!A:A,A23,数据源1!C:C,B23) | G23: =SUMIFS(数据源1!Q:Q,数据源1!A:A,A23,数据源1!C:C,B23) | H23: =SUMIFS(数据源1!X:X,数据源1!A:A,A23,数据源1!C:C,B23) | I23: =SUMIFS(数据源1!AC:AC,数据源1!A:A,A23,数据源1!C:C,B23)
A24: 7.20-7.26 | B24: 1060999732877 | C24: 原味大包 | D24: indomie印尼进口营多原味大大包129g捞面方便面速食食品宵夜小吃 | E24: =SUMIFS(数据源1!F:F,数据源1!A:A,A24,数据源1!C:C,B24) | F24: =SUMIFS(数据源1!Y:Y,数据源1!A:A,A24,数据源1!C:C,B24) | G24: =SUMIFS(数据源1!Q:Q,数据源1!A:A,A24,数据源1!C:C,B24) | H24: =SUMIFS(数据源1!X:X,数据源1!A:A,A24,数据源1!C:C,B24) | I24: =SUMIFS(数据源1!AC:AC,数据源1!A:A,A24,数据源1!C:C,B24)
A25: 7.20-7.26 | B25: 1013887677295 | C25: 原味大包 | D25: indomie印尼进口营多原味大大包129g捞面方便面速食食品宵夜小吃 | E25: =SUMIFS(数据源1!F:F,数据源1!A:A,A25,数据源1!C:C,B25) | F25: =SUMIFS(数据源1!Y:Y,数据源1!A:A,A25,数据源1!C:C,B25) | G25: =SUMIFS(数据源1!Q:Q,数据源1!A:A,A25,数据源1!C:C,B25) | H25: =SUMIFS(数据源1!X:X,数据源1!A:A,A25,数据源1!C:C,B25) | I25: =SUMIFS(数据源1!AC:AC,数据源1!A:A,A25,数据源1!C:C,B25)
A26: 7.27-8.2 | B26: 1058280415678 | C26: 原味大包 | D26: 印尼进口大大包营多原味捞面5包干拌面速食超大包方便面速食宵夜 | E26: =SUMIFS(数据源1!F:F,数据源1!A:A,A26,数据源1!C:C,B26) | F26: =SUMIFS(数据源1!Y:Y,数据源1!A:A,A26,数据源1!C:C,B26) | G26: =SUMIFS(数据源1!Q:Q,数据源1!A:A,A26,数据源1!C:C,B26) | H26: =SUMIFS(数据源1!X:X,数据源1!A:A,A26,数据源1!C:C,B26) | I26: =SUMIFS(数据源1!AC:AC,数据源1!A:A,A26,数据源1!C:C,B26)
... A32: 7.6-7.12 | B32: 648681860568 | C32: 原味大包 | D32: indomie印尼进口营多原味大大包129g捞面方便面速食食品宵夜小吃 | E32: =SUMIFS(数据源1!F:F,数据源1!A:A,A32,数据源1!C:C,B32) | F32: =SUMIFS(数据源1!Y:Y,数据源1!A:A,A32,数据源1!C:C,B32) | G32: =SUMIFS(数据源1!Q:Q,数据源1!A:A,A32,数据源1!C:C,B32) | H32: =SUMIFS(数据源1!X:X,数据源1!A:A,A32,数据源1!C:C,B32) | I32: =SUMIFS(数据源1!AC:AC,数据源1!A:A,A32,数据源1!C:C,B32)

Sheet 03-各周亏损TOP5
A1: 各周亏损最大的前5个ID
A3: 周次 | B3: 排名 | C3: 商品ID | D3: 定位 | E3: 商品名称 | F3: 净利润(推广后) | G3: 成交金额 | H3: 占当周总净利
A4: 5.11-5.17 | B4: 1 | C4: 649361890551 | D4: 袋面次链接 | E4: 营多捞面印尼进口Indomie网红夜宵早餐方便面火鸡面泡面拌面 | F4: -3173 | G4: 28857 | H4: 0.503
B5: 2 | C5: 668566625747 | D5: 袋面主链接 | E5: 印尼营多捞面进口网红泡面袋装方便面速食食品拉面火鸡面拌面整箱 | F5: -1370 | G5: 31186 | H5: 0.217
B6: 3 | C6: 649735171438 | D6: 杯面主链接 | E6: 印尼进口indomie营多捞面杯面速食泡面干拌面盒桶装方便面火鸡面 | F6: -1160 | G6: 20500 | H6: 0.184
B7: 4 | C7: 937005385662 | D7: 日式袋面 | E7: 进口营多正品捞面日式鸡肉鸡汤辛辣味袋装泡面辣味速食方便面汤面 | F7: -109 | G7: 425 | H7: 0.017
B8: 5 | C8: 976479938842 | D8: 【U选】原味5 | E8: 【天猫U选】indomie营多大骨牛肉味捞面拌面5包 | F8: -93 | G8: 145 | H8: 0.015
A9: 5.25-5.31 | B9: 1 | C9: 649361890551 | D9: 袋面次链接 | E9: 营多捞面印尼进口Indomie网红夜宵早餐方便面火鸡面泡面拌面 | F9: -2546 | G9: 21166 | H9: 0.391
B10: 2 | C10: 668566625747 | D10: 袋面主链接 | E10: 印尼营多捞面进口网红泡面袋装方便面速食食品拉面火鸡面拌面整箱 | F10: -2056 | G10: 44845 | H10: 0.315
B11: 3 | C11: 649735171438 | D11: 杯面主链接 | E11: 印尼进口indomie营多捞面杯面速食泡面干拌面盒桶装方便面火鸡面 | F11: -1292 | G11: 20489 | H11: 0.198
B12: 4 | C12: 1013887677295 | D12: 混搭5杯 | E12: 进口营多原味杯面日式杯面韩式杯面泡面方便面汤面宿舍速食夜宵 | F12: -148 | G12: 605 | H12: 0.023
B13: 5 | C13: 649014937782 | D13: 24包 | E13: 印尼营多捞面干拌面一整箱24袋装批发泡面宿舍速食方便面火鸡面 | F13: -145 | G13: 7569 | H13: 0.022
A14: 6.15-6.21 | B14: 1 | C14: 649361890551 | D14: 袋面次链接 | E14: 营多捞面印尼进口Indomie网红夜宵早餐方便面火鸡面泡面拌面 | F14: -3313 | G14: 24398 | H14: 0.5
B15: 2 | C15: 649735171438 | D15: 杯面主链接 | E15: 印尼进口indomie营多捞面杯面速食泡面干拌面盒桶装方便面火鸡面 | F15: -1523 | G15: 13688 | H15: 0.23
B16: 3 | C16: 668566625747 | D16: 袋面主链接 | E16: 印尼营多捞面进口网红泡面袋装方便面速食食品拉面火鸡面拌面整箱 | F16: -950 | G16: 30426 | H16: 0.143
B17: 4 | C17: 929504658691 | D17: 日式袋面 | E17: 营多捞面日式鸡肉汤面原味辛辣味袋装泡面方便面速食宿舍夜宵食品 | F17: -326 | G17: 1236 | H17: 0.049
B18: 5 | C18: 648600900806 | D18: 30包 | E18: 进口营多捞面一整箱30包网红速食方便面宿舍速食泡面干拌面拉面 | F18: -187 | G18: 9519 | H18: 0.028
A19: 6.22-6.28 | B19: 1 | C19: 649361890551 | D19: 袋面次链接 | E19: 营多捞面印尼进口Indomie网红夜宵早餐方便面火鸡面泡面拌面 | F19: -2104 | G19: 16506 | H19: 0.332
B20: 2 | C20: 649735171438 | D20: 杯面主链接 | E20: 印尼进口indomie营多捞面杯面速食泡面干拌面盒桶装方便面火鸡面 | F20: -1456 | G20: 14641 | H20: 0.23
B21: 3 | C21: 668566625747 | D21: 袋面主链接 | E21: 印尼营多捞面进口网红泡面袋装方便面速食食品拉面火鸡面拌面整箱 | F21: -1396 | G21: 25765 | H21: 0.22
B22: 4 | C22: 929504658691 | D22: 日韩袋面 | E22: 营多捞面日式鸡肉汤面原味辛辣味袋装泡面方便面速食宿舍夜宵食品 | F22: -312 | G22: 682 | H22: 0.049
B23: 5 | C23: 648600900806 | D23: 30包 | E23: 进口营多捞面一整箱30包网红速食方便面宿舍速食泡面干拌面拉面 | F23: -257 | G23: 8217 | H23: 0.041
A24: 6.29-7.5 | B24: 1 | C24: 649361890551 | D24: 袋面次链接 | E24: 营多捞面印尼进口Indomie网红夜宵早餐方便面火鸡面泡面拌面 | F24: -1690 | G24: 18111 | H24: 0.323
B25: 2 | C25: 649735171438 | D25: 杯面主链接 | E25: 印尼进口indomie营多捞面杯面速食泡面干拌面盒桶装方便面火鸡面 | F25: -1143 | G25: 14324 | H25: 0.219
B26: 3 | C26: 668566625747 | D26: 袋面主链接 | E26: 印尼营多捞面进口网红泡面袋装方便面速食食品拉面火鸡面拌面整箱 | F26: -1032 | G26: 26236 | H26: 0.197
B27: 4 | C27: 1057479227624 | D27: 巴东牛肉 | E27: 【新口味】印尼进口营多捞面巴东炖牛肉味泡面方便面宿舍速食宵夜 | F27: -469 | G27: 1951 | H27: 0.09
B28: 5 | C28: 1059563993918 | D28: 巴东牛肉 | E28: 营多进口新口味巴东炖牛肉味捞面印尼料理方便面泡面捞面夜宵速食 | F28: -206 | G28: 621 | H28: 0.039
A29: 7.6-7.12 | B29: 1 | C29: 649361890551 | D29: 袋面次链接 | E29: 营多捞面印尼进口Indomie网红夜宵早餐方便面火鸡面泡面拌面 | F29: -1808 | G29: 19322 | H29: 0.44
B30: 2 | C30: 649735171438 | D30: 杯面主链接 | E30: 印尼进口indomie营多捞面杯面速食泡面干拌面盒桶装方便面火鸡面 | F30: -1024 | G30: 16136 | H30: 0.249
B31: 3 | C31: 668566625747 | D31: 袋面主链接 | E31: 印尼营多捞面进口网红泡面袋装方便面速食食品拉面火鸡面拌面整箱 | F31: -911 | G31: 40189 | H31: 0.222
B32: 4 | C32: 1057479227624 | D32: 巴东牛肉 | E32: 【新口味】印尼进口营多捞面巴东炖牛肉味泡面方便面宿舍速食宵夜 | F32: -657 | G32: 2371 | H32: 0.16
B33: 5 | C33: 648681860568 | D33: 原味大包 | E33: indomie印尼进口营多原味大大包129g捞面方便面速食食品宵夜小吃 | F33: -160 | G33: 1204 | H33: 0.039
A34: 7.13-7.19 | B34: 1 | C34: 668566625747 | D34: 袋面主链接 | E34: 印尼营多捞面进口网红泡面袋装方便面速食食品拉面火鸡面拌面整箱 | F34: -1578 | G34: 36984 | H34: 0.305
B35: 2 | C35: 649361890551 | D35: 袋面次链接 | E35: 营多捞面印尼进口Indomie网红夜宵早餐方便面火鸡面泡面拌面 | F35: -1447 | G35: 14292 | H35: 0.279
B36: 3 | C36: 649735171438 | D36: 杯面主链接 | E36: 印尼进口indomie营多捞面杯面速食泡面干拌面盒桶装方便面火鸡面 | F36: -963 | G36: 13725 | H36: 0.186
B37: 4 | C37: 1057479227624 | D37: 巴东牛肉 | E37: 【新口味】印尼进口营多捞面巴东炖牛肉味泡面方便面宿舍速食宵夜 | F37: -674 | G37: 2425 | H37: 0.13
B38: 5 | C38: 648600900806 | D38: 30包 | E38: 进口营多捞面一整箱30包网红速食方便面宿舍速食泡面干拌面拉面 | F38: -202 | G38: 6834 | H38: 0.039
A39: 7.20-8.2 | B39: 1 | C39: 649361890551 | D39: 袋面次链接 | E39: 营多捞面印尼进口Indomie网红夜宵早餐方便面火鸡面泡面拌面 | F39: -1753 | G39: 15823 | H39: 0.343
B40: 2 | C40: 649735171438 | D40: 杯面主链接 | E40: 印尼进口indomie营多捞面杯面速食泡面干拌面盒桶装方便面火鸡面 | F40: -789 | G40: 15355 | H40: 0.154
B41: 3 | C41: 668566625747 | D41: 袋面主链接 | E41: 印尼营多捞面进口网红泡面袋装方便面速食食品拉面火鸡面拌面整箱 | F41: -629 | G41: 38360 | H41: 0.123
...

Sheet 04-全量ID每周净利润
A1: 全量商品ID · 每周推广后净利润明细表
A3: 商品ID | B3: 定位 | C3: 商品名称 | D3: 5.11-5.17 | E3: 5.25-5.31 | F3: 6.15-6.21 | G3: 6.22-6.28 | H3: 6.29-7.5 | I3: 7.6-7.12 | J3: 7.13-7.19 | K3: 7.20-7.26 | L3: 7.27-8.2 | M3: 7.6→7.13变化
A4: 649361890551 | B4: 袋面次链接 | C4: 营多捞面印尼进口Indomie网红夜宵早餐方便面火鸡面泡面拌面 | D4: -3173 | E4: -2546 | F4: -3313 | G4: -2104 | H4: -1690 | I4: -1808 | J4: -1447 | K4: =_xlfn.XLOOKUP(A4,'[1]7.20-7.26'!$B:$B,'[1]7.20-7.26'!$AB:$AB,NA(),0) | L4: -1753 | M4: -667
A5: 668566625747 | B5: 袋面主链接 | C5: 印尼营多捞面进口网红泡面袋装方便面速食食品拉面火鸡面拌面整箱 | D5: -1370 | E5: -2056 | F5: -950 | G5: -1396 | H5: -1032 | I5: -911 | J5: -1578 | K5: =_xlfn.XLOOKUP(A5,'[1]7.20-7.26'!$B:$B,'[1]7.20-7.26'!$AB:$AB,NA(),0) | L5: -629 | M5: -243
A6: 649735171438 | B6: 杯面主链接 | C6: 印尼进口indomie营多捞面杯面速食泡面干拌面盒桶装方便面火鸡面 | D6: -1160 | E6: -1292 | F6: -1523 | G6: -1456 | H6: -1143 | I6: -1024 | J6: -963 | K6: =_xlfn.XLOOKUP(A6,'[1]7.20-7.26'!$B:$B,'[1]7.20-7.26'!$AB:$AB,NA(),0) | L6: -789 | M6: -210
A7: 937005385662 | B7: 日式袋面 | C7: 进口营多正品捞面日式鸡肉鸡汤辛辣味袋装泡面辣味速食方便面汤面 | D7: -109 | E7: -26 | F7: -34 | G7: 15 | H7: 1 | I7: -9 | J7: -13 | K7: =_xlfn.XLOOKUP(A7,'[1]7.20-7.26'!$B:$B,'[1]7.20-7.26'!$AB:$AB,NA(),0) | L7: -68 | M7: -119
A8: 976479938842 | B8: 【U选】原味5 | C8: 【天猫U选】indomie营多大骨牛肉味捞面拌面5包 | D8: -93 | E8: -20 | F8: -34 | G8: -8 | H8: -9 | I8: -37 | J8: -22 | K8: =_xlfn.XLOOKUP(A8,'[1]7.20-7.26'!$B:$B,'[1]7.20-7.26'!$AB:$AB,NA(),0) | L8: -21 | M8: -101
A9: 649014937782 | B9: 24包 | C9: 印尼营多捞面干拌面一整箱24袋装批发泡面宿舍速食方便面火鸡面 | D9: -91 | E9: -145 | F9: -47 | G9: -154 | H9: -164 | I9: -5 | J9: -63 | K9: =_xlfn.XLOOKUP(A9,'[1]7.20-7.26'!$B:$B,'[1]7.20-7.26'!$AB:$AB,NA(),0) | L9: -235 | M9: -65
A10: 648681860568 | B10: 杯面次链接 | C10: 营多捞面杯装方便面泡面速食干拌面原味整箱批发印尼进口桶装拌面 | D10: -87 | E10: -97 | F10: -161 | G10: -69 | H10: 47 | I10: -160 | J10: -100 | K10: =_xlfn.XLOOKUP(A10,'[1]7.20-7.26'!$B:$B,'[1]7.20-7.26'!$AB:$AB,NA(),0) | L10: -279 | M10: -58
A11: 969433743398 | B11: 韩蘑菇 | C11: 新品营多捞面韩式辣蘑菇汤面泡面方便面速食干拌面宿舍宵夜旅行 | D11: -81 | E11: -82 | F11: 3 | G11: -7 | H11: -9 | I11: 0 | J11: -5 | K11: =_xlfn.XLOOKUP(A11,'[1]7.20-7.26'!$B:$B,'[1]7.20-7.26'!$AB:$AB,NA(),0) | L11: 7 | M11: -46
A12: 1013887677295 | B12: 原味大包 | C12: indomie印尼进口营多原味大大包129g捞面方便面速食食品宵夜小吃 | D12: -65 | E12: -148 | F12: -137 | G12: -135 | H12: -107 | I12: -128 | J12: -174 | K12: =_xlfn.XLOOKUP(A12,'[1]7.20-7.26'!$B:$B,'[1]7.20-7.26'!$AB:$AB,NA(),0) | L12: -147 | M12: -31
A13: 929504658691 | B13: 巴东牛肉 | C13: 营多进口新口味巴东炖牛肉味捞面印尼料理方便面泡面捞面夜宵速食 | D13: -59 | E13: -95 | F13: -326 | G13: -312 | H13: -194 | I13: -64 | J13: -49 | K13: =_xlfn.XLOOKUP(A13,'[1]7.20-7.26'!$B:$B,'[1]7.20-7.26'!$AB:$AB,NA(),0) | L13: -79 | M13: -29
A14: 898076297965 | B14: 番茄牛肉 | C14: 进口正品意面风味奶香番茄牛肉味意式拌面营多捞面早餐儿童宝妈餐 | D14: -56 | E14: -11 | F14: -13 | G14: -16 | H14: -13 | I14: -19 | J14: -16 | K14: =_xlfn.XLOOKUP(A14,'[1]7.20-7.26'!$B:$B,'[1]7.20-7.26'!$AB:$AB,NA(),0) | L14: -19 | M14: -18
A15: 949962665617 | B15: 韩式袋面 | C15: 营多捞面韩式火鸡面辣蘑菇汤面袋装泡面辣味速食方便面宿舍宵夜面 | D15: -48 | E15: -69 | F15: -44 | H15: -15 | I15: -21 | M15: -17
A16: 735014804839 | B16: 24/30包 | C16: 进口营多捞面多口味Indomie网红方便面干拌面泡面30包整箱批发面 | D16: -43 | E16: -36 | F16: 130 | G16: -5 | H16: 25 | I16: 108 | J16: 79 | K16: =_xlfn.XLOOKUP(A16,'[1]7.20-7.26'!$B:$B,'[1]7.20-7.26'!$AB:$AB,NA(),0) | L16: -19 | M16: -15
A17: 976466902934 | B17: 杯面混搭 | C17: 营多捞面韩式甜辣炸鸡辣蘑菇杯面方便面拌面泡面宿舍速食面 | D17: -33 | E17: -10 | F17: -6 | G17: -15 | H17: -3 | I17: -4 | J17: -3 | K17: =_xlfn.XLOOKUP(A17,'[1]7.20-7.26'!$B:$B,'[1]7.20-7.26'!$AB:$AB,NA(),0) | M17: -15
A18: 744317232690 | B18: 多规格 | C18: 营多捞面汤面清香牛肉味方便面泡面速食食品泡面拉面整箱旅行宿舍 | D18: -31 | E18: -6 | F18: 66 | G18: -4 | H18: -61 | I18: 8 | J18: -10 | K18: =_xlfn.XLOOKUP(A18,'[1]7.20-7.26'!$B:$B,'[1]7.20-7.26'!$AB:$AB,NA(),0) | L18: -40 | M18: -10
A19: 648604228786 | B19: 杯面混搭 | C19: INDOMIE营多日式杯面原味经典泡面整箱批发速食宿舍旅行宵夜宿舍 | D19: -24 | E19: 6 | F19: 9 | G19: -6 | H19: 6 | I19: 16 | J19: -15 | K19: =_xlfn.XLOOKUP(A19,'[1]7.20-7.26'!$B:$B,'[1]7.20-7.26'!$AB:$AB,NA(),0) | L19: 7 | M19: -9
A20: 773972883430 | B20: 韩式袋面 | C20: 营多捞面韩式火鸡面辣蘑菇汤面袋装泡面辣味速食方便面宿舍宵夜面 | D20: -13 | E20: 7 | F20: 2 | G20: 5 | H20: -1 | M20: -8
A21: 969423151512 | B21: 日韩混搭 | C21: 营多捞面甜辣炸鸡火鸡面辣蘑菇泡面方便面速食干拌面宿舍宵夜旅行 | D21: -12 | E21: -12 | F21: -32 | G21: -41 | H21: -83 | I21: -16 | J21: -26 | K21: =_xlfn.XLOOKUP(A21,'[1]7.20-7.26'!$B:$B,'[1]7.20-7.26'!$AB:$AB,NA(),0) | L21: -61 | M21: -5
A22: 976467954327 | B22: 日韩杯面 | C22: 【天猫U选】indomie营多捞面辣蘑菇味日式辣味杯面 | D22: -8 | E22: -6 | G22: -3 | H22: -6 | I22: -3 | J22: -3 | K22: =_xlfn.XLOOKUP(A22,'[1]7.20-7.26'!$B:$B,'[1]7.20-7.26'!$AB:$AB,NA(),0) | L22: -13 | M22: -4
A23: 916072786304 | B23: 小规格 | C23: 营多印尼进口营多捞面方便面火鸡面干拌面10包宿舍速食泡面夜宵 | D23: -7 | G23: -3 | I23: 0 | J23: -3 | L23: -2 | M23: -4
A24: 1040679932754 | B24: 杯面混搭 | C24: 印尼进口营多捞面杯面原味甜辣蘑菇味整箱速食拌面拉面泡面方便面 | D24: -7 | H24: -2 | M24: -3
A25: 869217868453 | B25: 韩式杯面 | C25: 营多捞面韩式甜辣炸鸡辣蘑菇杯面方便面拌面泡面宿舍速食面 | D25: -7 | E25: -1 | G25: 2 | H25: -8 | I25: 6 | K25: =_xlfn.XLOOKUP(A25,'[1]7.20-7.26'!$B:$B,'[1]7.20-7.26'!$AB:$AB,NA(),0) | L25: -11 | M25: -2
A26: 649729851594 | B26: 小规格 | C26: 营多捞面袋装8包装泡面宿舍速食面热干面干拌面方便面火鸡面食品 | D26: -5 | E26: 20 | F26: 6 | G26: -1 | I26: 8 | J26: -1 | L26: 8 | M26: -1
A27: 885645733215 | B27: 大骨牛肉 | C27: 进口营多大骨番茄牛肉味营多捞面意式泡面宿舍宿舍宵夜速食方便面 | D27: -2 | E27: 1 | F27: -4 | G27: -10 | H27: -5 | I27: -6 | J27: -7 | K27: =_xlfn.XLOOKUP(A27,'[1]7.20-7.26'!$B:$B,'[1]7.20-7.26'!$AB:$AB,NA(),0) | M27: -1
A28: 903183018417 | B28: 七口味混搭 | C28: 进口营多捞面汤面拌面七口味混合方便面速拉面宿舍拌面泡面食食品 | D28: -2 | E28: -12 | F28: 9 | G28: -1 | H28: -4 | I28: -16 | J28: -9 | K28: =_xlfn.XLOOKUP(A28,'[1]7.20-7.26'!$B:$B,'[1]7.20-7.26'!$AB:$AB,NA(),0) | L28: 0 | M28: -1
A29: 1019397839311 | B29: 多口味混搭 | C29: 营多捞面原味番茄牛肉袋装泡面汤面干拌面方便面宿舍速食旅行宵夜 | D29: -1 | M29: 0
A30: 754828376158 | B30: 六口味混搭 | C30: 进口营多捞面汤面拌面六口味混合方便面速食食品泡面 | D30: -1 | M30: 0
A31: 947413291596 | B31: 杯面混搭 | C31: 印尼进口营多捞面杯面原味甜辣蘑菇味整箱速食拌面拉面泡面方便面 | D31: 0 | E31: -5 | F31: -5 | G31: -1 | H31: -4 | I31: -9 | J31: -10 | L31: 0 | M31: 1
A32: 898120785283 | B32: 番茄 | C32: 进口意大利面风味奶香番茄牛肉味意式营多早餐儿童宝妈家庭餐拌面 | D32: 1 | E32: -3 | F32: 4 | G32: 1 | H32: -2 | I32: -2 | J32: -4 | L32: 11 | M32: 3
A33: 886856687067 | B33: 大骨 | C33: 营多捞面牛系列大骨牛肉味方便面食品泡面拉面汤面宿舍宵夜旅行 | D33: 1 | E33: 2 | F33: -1 | G33: -11 | H33: 4 | I33: 8 | J33: 30 | K33: =_xlfn.XLOOKUP(A33,'[1]7.20-7.26'!$B:$B,'[1]7.20-7.26'!$AB:$AB,NA(),0) | L33: -15 | M33: 7
A34: 971242260371 | B34: 韩式袋面 | C34: 新品营多捞面韩式辣蘑菇汤面泡面方便面速食干拌面宿舍宵夜旅行 | D34: 1 | E34: -56 | F34: -10 | G34: -37 | H34: -48 | I34: -60 | J34: -21 | K34: =_xlfn.XLOOKUP(A34,'[1]7.20-7.26'!$B:$B,'[1]7.20-7.26'!$AB:$AB,NA(),0) | L34: -30 | M34: 15
A35: 1019572719528 | B35: 日韩袋面 | C35: 新品营多捞面韩式辣蘑菇汤面泡面方便面速食干拌面宿舍宵夜旅行 | D35: 2 | H35: 3 | I35: 2 | J35: 2 | M35: 15
A36: 648600900806 | B36: 30包 | C36: 进口营多捞面一整箱30包网红速食方便面宿舍速食泡面干拌面拉面 | D36: 5 | E36: -69 | F36: -187 | G36: -257 | H36: -148 | I36: 41 | J36: -202 | K36: =_xlfn.XLOOKUP(A36,'[1]7.20-7.26'!$B:$B,'[1]7.20-7.26'!$AB:$AB,NA(),0) | L36: -488 | M36: 22
A37: 649731447266 | B37: 20包经典/牛系列 | C37: 营多印尼进口营多捞面方便面火鸡面干拌面20包宿舍速食泡面夜宵 | D37: 12 | E37: -5 | F37: 16 | G37: 46 | H37: 16 | I37: 36 | J37: 21 | K37: =_xlfn.XLOOKUP(A37,'[1]7.20-7.26'!$B:$B,'[1]7.20-7.26'!$AB:$AB,NA(),0) | L37: 30 | M37: 23
A38: 932687928859 | B38: 杯面混搭 | C38: 营多捞面韩式甜辣炸鸡辣蘑菇杯面方便面拌面泡面宿舍速食面 | D38: 14 | F38: 7 | G38: 6 | H38: 4 | I38: 13 | J38: -2 | K38: =_xlfn.XLOOKUP(A38,'[1]7.20-7.26'!$B:$B,'[1]7.20-7.26'!$AB:$AB,NA(),0) | L38: 7 | M38: 39
A39: 648598580775 | B39: 原味大包 | C39: 印尼进口大大包营多原味捞面5包干拌面速食超大包方便面速食宵夜 | D39: 25 | E39: -66 | F39: -70 | G39: -116 | H39: -117 | I39: 64 | J39: -37 | K39: =_xlfn.XLOOKUP(A39,'[1]7.20-7.26'!$B:$B,'[1]7.20-7.26'!$AB:$AB,NA(),0) | L39: -85 | M39: 60
A40: 649369494424 | B40: 24包经典/牛系列 | C40: 营多捞面干拌面一整箱24袋装批发泡面混搭宿舍速食方便面火鸡面 | D40: 102 | E40: 90 | F40: -77 | G40: -107 | H40: 147 | I40: 457 | J40: 247 | K40: =_xlfn.XLOOKUP(A40,'[1]7.20-7.26'!$B:$B,'[1]7.20-7.26'!$AB:$AB,NA(),0) | L40: 131 | M40: 61
A41: 766165464414 | B41: 12包 | C41: 营多印尼进口营多捞面方便面火鸡面干拌面12包宿舍速食泡面夜宵 | D41: 120 | E41: 210 | F41: 84 | G41: 55 | H41: 65 | I41: 129 | J41: 10 | K41: =_xlfn.XLOOKUP(A41,'[1]7.20-7.26'!$B:$B,'[1]7.20-7.26'!$AB:$AB,NA(),0) | L41: 58 | M41: 361
...

Sheet 周报其他费用
A1: 周次 | B1: 周报其他费用
A2: 5.11-5.17 | B2: 1911
A3: 5.25-5.31 | B3: 1911
A4: 6.15-6.21 | B4: 3605
A5: 6.22-6.28 | B5: 3605
A6: 6.29-7.5 | B6: 1951
A7: 7.6-7.12 | B7: 2054
A8: 7.13-7.19 | B8: 2405
A9: 7.20-7.26 | B9: 2097
A10: 7.27-8.2 | B10: 2127

Sheet 数据源1
A1: 全部周合并明细
A2: 周次 | B2: 日期 | C2: 商品ID | D2: 定位 | E2: 商品名称 | F2: 成交金额 | G2: 去税金额 | H2: 成交件数 | I2: 件数占比 | J2: 件单价 | K2: 万相台花费 | L2: 万相台成交 | M2: 万相台ROI | N2: 品销宝花费 | O2: 品销宝成交 | P2: 品销宝ROI | Q2: 推广总花费 | R2: 推广总成交 | S2: 推广总ROI | T2: 推广费占比 | U2: 推广总费率 | V2: 日销成交 | W2: 日销成交占比 | X2: 其他费用 | Y2: 净利润(推广前) | Z2: 净利率(推广前) | AA2: 净利润(万相台) | AB2: 净利率(万相台) | AC2: 净利润(推广后) | AD2: 净利率(推广后)
A3: 5.11-5.17 | B3: 5.11-5.17 | C3: 668566625747 | D3: 袋面主链接 | E3: 印尼营多捞面进口网红泡面袋装方便面速食食品拉面火鸡面拌面整箱 | F3: 31185.63 | G3: =IFERROR(F3/1.13,0) | H3: 1220 | I3: =IFERROR(H3/SUMIF($A:$A,A3,$H:$H),0) | J3: =IFERROR(F3/H3,0) | K3: 5079.8725 | L3: 23465.2 | M3: =IFERROR(L3/K3,0) | N3: 554.76399 | O3: 1481.5078 | P3: =IFERROR(O3/N3,0) | Q3: =K3+N3 | R3: =L3+O3 | S3: =IFERROR(R3/Q3,0) | T3: =IFERROR(Q3/SUMIF($A:$A,A3,$Q:$Q),0) | U3: =IFERROR(Q3/F3,0) | V3: =F3-R3 | W3: =IFERROR(V3/F3,0) | X3: =IFERROR(VLOOKUP(A3,周报其他费用!$A:$B,2,FALSE)*I3,0) | Y3: 4205.259 | Z3: =IFERROR(Y3/G3,0) | AA3: =Y3-K3/1.06 | AB3: =IFERROR(AA3/G3,0) | AC3: =Y3-(Q3+X3)/1.06 | AD3: =IFERROR(AC3/G3,0)
A4: 5.11-5.17 | B4: 5.11-5.17 | C4: 649361890551 | D4: 袋面次链接 | E4: 营多捞面印尼进口Indomie网红夜宵早餐方便面火鸡面泡面拌面 | F4: 28857.24 | G4: =IFERROR(F4/1.13,0) | H4: 1529 | I4: =IFERROR(H4/SUMIF($A:$A,A4,$H:$H),0) | J4: =IFERROR(F4/H4,0) | K4: 5008.2401 | L4: 25554.89 | M4: =IFERROR(L4/K4,0) | N4: 695.27389 | O4: 1856.7421 | P4: =IFERROR(O4/N4,0) | Q4: =K4+N4 | R4: =L4+O4 | S4: =IFERROR(R4/Q4,0) | T4: =IFERROR(Q4/SUMIF($A:$A,A4,$Q:$Q),0) | U4: =IFERROR(Q4/F4,0) | V4: =F4-R4 | W4: =IFERROR(V4/F4,0) | X4: =IFERROR(VLOOKUP(A4,周报其他费用!$A:$B,2,FALSE)*I4,0) | Y4: 2532.806 | Z4: =IFERROR(Y4/G4,0) | AA4: =Y4-K4/1.06 | AB4: =IFERROR(AA4/G4,0) | AC4: =Y4-(Q4+X4)/1.06 | AD4: =IFERROR(AC4/G4,0)
A5: 5.11-5.17 | B5: 5.11-5.17 | C5: 649735171438 | D5: 杯面主链接 | E5: 印尼进口indomie营多捞面杯面速食泡面干拌面盒桶装方便面火鸡面 | F5: 20499.86 | G5: =IFERROR(F5/1.13,0) | H5: 803 | I5: =IFERROR(H5/SUMIF($A:$A,A5,$H:$H),0) | J5: =IFERROR(F5/H5,0) | K5: 3146.9679 | L5: 13817.925 | M5: =IFERROR(L5/K5,0) | N5: 365.14384 | O5: 975.12357 | P5: =IFERROR(O5/N5,0) | Q5: =K5+N5 | R5: =L5+O5 | S5: =IFERROR(R5/Q5,0) | T5: =IFERROR(Q5/SUMIF($A:$A,A5,$Q:$Q),0) | U5: =IFERROR(Q5/F5,0) | V5: =F5-R5 | W5: =IFERROR(V5/F5,0) | X5: =IFERROR(VLOOKUP(A5,周报其他费用!$A:$B,2,FALSE)*I5,0) | Y5: 2323.975 | Z5: =IFERROR(Y5/G5,0) | AA5: =Y5-K5/1.06 | AB5: =IFERROR(AA5/G5,0) | AC5: =Y5-(Q5+X5)/1.06 | AD5: =IFERROR(AC5/G5,0)
A6: 5.11-5.17 | B6: 5.11-5.17 | C6: 648600900806 | D6: 30包 | E6: 进口营多捞面一整箱30包网红速食方便面宿舍速食泡面干拌面拉面 | F6: 10599.77 | G6: =IFERROR(F6/1.13,0) | H6: 154 | I6: =IFERROR(H6/SUMIF($A:$A,A6,$H:$H),0) | J6: =IFERROR(F6/H6,0) | K6: 2033.3414 | L6: 10437.762 | M6: =IFERROR(L6/K6,0) | N6: 70.027586 | O6: 187.01 | P6: =IFERROR(O6/N6,0) | Q6: =K6+N6 | R6: =L6+O6 | S6: =IFERROR(R6/Q6,0) | T6: =IFERROR(Q6/SUMIF($A:$A,A6,$Q:$Q),0) | U6: =IFERROR(Q6/F6,0) | V6: =F6-R6 | W6: =IFERROR(V6/F6,0) | X6: =IFERROR(VLOOKUP(A6,周报其他费用!$A:$B,2,FALSE)*I6,0) | Y6: 2022.481 | Z6: =IFERROR(Y6/G6,0) | AA6: =Y6-K6/1.06 | AB6: =IFERROR(AA6/G6,0) | AC6: =Y6-(Q6+X6)/1.06 | AD6: =IFERROR(AC6/G6,0)
A7: 5.11-5.17 | B7: 5.11-5.17 | C7: 649014937782 | D7: 24包 | E7: 印尼营多捞面干拌面一整箱24袋装批发泡面宿舍速食方便面火鸡面 | F7: 7533.85 | G7: =IFERROR(F7/1.13,0) | H7: 133 | I7: =IFERROR(H7/SUMIF($A:$A,A7,$H:$H),0) | J7: =IFERROR(F7/H7,0) | K7: 1581.3889 | L7: 7074.8484 | M7: =IFERROR(L7/K7,0) | N7: 60.47837 | O7: 161.50864 | P7: =IFERROR(O7/N7,0) | Q7: =K7+N7 | R7: =L7+O7 | S7: =IFERROR(R7/Q7,0) | T7: =IFERROR(Q7/SUMIF($A:$A,A7,$Q:$Q),0) | U7: =IFERROR(Q7/F7,0) | V7: =F7-R7 | W7: =IFERROR(V7/F7,0) | X7: =IFERROR(VLOOKUP(A7,周报其他费用!$A:$B,2,FALSE)*I7,0) | Y7: 1486.131 | Z7: =IFERROR(Y7/G7,0) | AA7: =Y7-K7/1.06 | AB7: =IFERROR(AA7/G7,0) | AC7: =Y7-(Q7+X7)/1.06 | AD7: =IFERROR(AC7/G7,0)
A8: 5.11-5.17 | B8: 5.11-5.17 | C8: 648598580775 | D8: 15包 | E8: 进口营多捞面15包Indomie方便面干拌面夜宵方便速食五连包85g*5 | F8: 6101.9 | G8: =IFERROR(F8/1.13,0) | H8: 165 | I8: =IFERROR(H8/SUMIF($A:$A,A8,$H:$H),0) | J8: =IFERROR(F8/H8,0) | K8: 1044.735 | L8: 4769.4269 | M8: =IFERROR(L8/K8,0) | N8: 75.029557 | O8: 200.36786 | P8: =IFERROR(O8/N8,0) | Q8: =K8+N8 | R8: =L8+O8 | S8: =IFERROR(R8/Q8,0) | T8: =IFERROR(Q8/SUMIF($A:$A,A8,$Q:$Q),0) | U8: =IFERROR(Q8/F8,0) | V8: =F8-R8 | W8: =IFERROR(V8/F8,0) | X8: =IFERROR(VLOOKUP(A8,周报其他费用!$A:$B,2,FALSE)*I8,0) | Y8: 1116.138 | Z8: =IFERROR(Y8/G8,0) | AA8: =Y8-K8/1.06 | AB8: =IFERROR(AA8/G8,0) | AC8: =Y8-(Q8+X8)/1.06 | AD8: =IFERROR(AC8/G8,0)
A9: 5.11-5.17 | B9: 5.11-5.17 | C9: 766165464414 | D9: 12包 | E9: 营多印尼进口营多捞面方便面火鸡面干拌面12包宿舍速食泡面夜宵 | F9: 4330.8 | G9: =IFERROR(F9/1.13,0) | H9: 146 | I9: =IFERROR(H9/SUMIF($A:$A,A9,$H:$H),0) | J9: =IFERROR(F9/H9,0) | K9: 459.94235 | L9: 2383.2228 | M9: =IFERROR(L9/K9,0) | N9: 66.38979 | O9: 177.29519 | P9: =IFERROR(O9/N9,0) | Q9: =K9+N9 | R9: =L9+O9 | S9: =IFERROR(R9/Q9,0) | T9: =IFERROR(Q9/SUMIF($A:$A,A9,$Q:$Q),0) | U9: =IFERROR(Q9/F9,0) | V9: =F9-R9 | W9: =IFERROR(V9/F9,0) | X9: =IFERROR(VLOOKUP(A9,周报其他费用!$A:$B,2,FALSE)*I9,0) | Y9: 647.268 | Z9: =IFERROR(Y9/G9,0) | AA9: =Y9-K9/1.06 | AB9: =IFERROR(AA9/G9,0) | AC9: =Y9-(Q9+X9)/1.06 | AD9: =IFERROR(AC9/G9,0)
A10: 5.11-5.17 | B10: 5.11-5.17 | C10: 735014804839 | D10: 24/30包 | E10: 进口营多捞面多口味Indomie网红方便面干拌面泡面30包整箱批发面 | F10: 2118.55 | G10: =IFERROR(F10/1.13,0) | H10: 31 | I10: =IFERROR(H10/SUMIF($A:$A,A10,$H:$H),0) | J10: =IFERROR(F10/H10,0) | K10: 471.45125 | L10: 1689.0335 | M10: =IFERROR(L10/K10,0) | N10: 14.096462 | O10: 37.64487 | P10: =IFERROR(O10/N10,0) | Q10: =K10+N10 | R10: =L10+O10 | S10: =IFERROR(R10/Q10,0) | T10: =IFERROR(Q10/SUMIF($A:$A,A10,$Q:$Q),0) | U10: =IFERROR(Q10/F10,0) | V10: =F10-R10 | W10: =IFERROR(V10/F10,0) | X10: =IFERROR(VLOOKUP(A10,周报其他费用!$A:$B,2,FALSE)*I10,0) | Y10: 422.008 | Z10: =IFERROR(Y10/G10,0) | AA10: =Y10-K10/1.06 | AB10: =IFERROR(AA10/G10,0) | AC10: =Y10-(Q10+X10)/1.06 | AD10: =IFERROR(AC10/G10,0)
A11: 5.11-5.17 | B11: 5.11-5.17 | C11: 649369494424 | D11: 24包经典/牛系列 | E11: 营多捞面干拌面一整箱24袋装批发泡面混搭宿舍速食方便面火鸡面 | F11: 1718.31 | G11: =IFERROR(F11/1.13,0) | H11: 31 | I11: =IFERROR(H11/SUMIF($A:$A,A11,$H:$H),0) | J11: =IFERROR(F11/H11,0) | K11: 214.93125 | L11: 812.64347 | M11: =IFERROR(L11/K11,0) | N11: 14.096462 | O11: 37.64487 | P11: =IFERROR(O11/N11,0) | Q11: =K11+N11 | R11: =L11+O11 | S11: =IFERROR(R11/Q11,0) | T11: =IFERROR(Q11/SUMIF($A:$A,A11,$Q:$Q),0) | U11: =IFERROR(Q11/F11,0) | V11: =F11-R11 | W11: =IFERROR(V11/F11,0) | X11: =IFERROR(VLOOKUP(A11,周报其他费用!$A:$B,2,FALSE)*I11,0) | Y11: 325.027 | Z11: =IFERROR(Y11/G11,0) | AA11: =Y11-K11/1.06 | AB11: =IFERROR(AA11/G11,0) | AC11: =Y11-(Q11+X11)/1.06 | AD11: =IFERROR(AC11/G11,0)
A12: 5.11-5.17 | B12: 5.11-5.17 | C12: 929504658691 | D12: 日式袋面 | E12: 营多捞面日式鸡肉汤面原味辛辣味袋装泡面方便面速食宿舍夜宵食品 | F12: 626.32 | G12: =IFERROR(F12/1.13,0) | H12: 24 | I12: =IFERROR(H12/SUMIF($A:$A,A12,$H:$H),0) | J12: =IFERROR(F12/H12,0) | K12: 163.4571 | L12: 502.40882 | M12: =IFERROR(L12/K12,0) | N12: 10.91339 | O12: 29.144416 | P12: =IFERROR(O12/N12,0) | Q12: =K12+N12 | R12: =L12+O12 | S12: =IFERROR(R12/Q12,0) | T12: =IFERROR(Q12/SUMIF($A:$A,A12,$Q:$Q),0) | U12: =IFERROR(Q12/F12,0) | V12: =F12-R12 | W12: =IFERROR(V12/F12,0) | X12: =IFERROR(VLOOKUP(A12,周报其他费用!$A:$B,2,FALSE)*I12,0) | Y12: 110.142 | Z12: =IFERROR(Y12/G12,0) | AA12: =Y12-K12/1.06 | AB12: =IFERROR(AA12/G12,0) | AC12: =Y12-(Q12+X12)/1.06 | AD12: =IFERROR(AC12/G12,0)
A13: 5.11-5.17 | B13: 5.11-5.17 | C13: 648681860568 | D13: 杯面次链接 | E13: 营多捞面杯装方便面泡面速食干拌面原味整箱批发印尼进口桶装拌面 | F13: 1000.29 | G13: =IFERROR(F13/1.13,0) | H13: 41 | I13: =IFERROR(H13/SUMIF($A:$A,A13,$H:$H),0) | J13: =IFERROR(F13/H13,0) | K13: 171.61004 | L13: 836.27298 | M13: =IFERROR(L13/K13,0) | N13: 18.643708 | O13: 49.788377 | P13: =IFERROR(O13/N13,0) | Q13: =K13+N13 | R13: =L13+O13 | S13: =IFERROR(R13/Q13,0) | T13: =IFERROR(Q13/SUMIF($A:$A,A13,$Q:$Q),0) | U13: =IFERROR(Q13/F13,0) | V13: =F13-R13 | W13: =IFERROR(V13/F13,0) | X13: =IFERROR(VLOOKUP(A13,周报其他费用!$A:$B,2,FALSE)*I13,0) | Y13: 101.013 | Z13: =IFERROR(Y13/G13,0) | AA13: =Y13-K13/1.06 | AB13: =IFERROR(AA13/G13,0) | AC13: =Y13-(Q13+X13)/1.06 | AD13: =IFERROR(AC13/G13,0)
A14: 5.11-5.17 | B14: 5.11-5.17 | C14: 937005385662 | D14: 日式袋面 | E14: 进口营多正品捞面日式鸡肉鸡汤辛辣味袋装泡面辣味速食方便面汤面 | F14: 425.12 | G14: =IFERROR(F14/1.13,0) | H14: 19 | I14: =IFERROR(H14/SUMIF($A:$A,A14,$H:$H),0) | J14: =IFERROR(F14/H14,0) | K14: 181.7727 | L14: 397.10406 | M14: =IFERROR(L14/K14,0) | N14: 8.6397671 | O14: 23.072662 | P14: =IFERROR(O14/N14,0) | Q14: =K14+N14 | R14: =L14+O14 | S14: =IFERROR(R14/Q14,0) | T14: =IFERROR(Q14/SUMIF($A:$A,A14,$Q:$Q),0) | U14: =IFERROR(Q14/F14,0) | V14: =F14-R14 | W14: =IFERROR(V14/F14,0) | X14: =IFERROR(VLOOKUP(A14,周报其他费用!$A:$B,2,FALSE)*I14,0) | Y14: 75.032 | Z14: =IFERROR(Y14/G14,0) | AA14: =Y14-K14/1.06 | AB14: =IFERROR(AA14/G14,0) | AC14: =Y14-(Q14+X14)/1.06 | AD14: =IFERROR(AC14/G14,0)
... A294: 7.20-7.26 | B294: 7.20-7.26 | C294: 648604228786 | D294: 杯面混搭 | E294: INDOMIE营多日式杯面原味经典泡面整箱批发速食宿舍旅行宵夜宿舍 | F294: 212.58 | G294: =IFERROR(F294/1.13,0) | H294: 8 | I294: =IFERROR(H294/SUMIF($A:$A,A294,$H:$H),0) | J294: =IFERROR(F294/H294,0) | K294: 12.025601 | L294: 8.1008177 | M294: =IFERROR(L294/K294,0) | N294: 4.8269054 | O294: 11.271071 | P294: =IFERROR(O294/N294,0) | Q294: =K294+N294 | R294: =L294+O294 | S294: =IFERROR(R294/Q294,0) | T294: =IFERROR(Q294/SUMIF($A:$A,A294,$Q:$Q),0) | U294: =IFERROR(Q294/F294,0) | V294: =F294-R294 | W294: =IFERROR(V294/F294,0) | X294: =IFERROR(VLOOKUP(A294,周报其他费用!$A:$B,2,FALSE)*I294,0) | Y294: 29.185 | Z294: =IFERROR(Y294/G294,0) | AA294: =Y294-K294/1.06 | AB294: =IFERROR(AA294/G294,0) | AC294: =Y294-(Q294+X294)/1.06 | AD294: =IFERROR(AC294/G294,0)
A295: 7.20-7.26 | B295: 7.20-7.26 | C295: 976535014785 | F295: 6.87 | G295: =IFERROR(F295/1.13,0) | H295: 7 | I295: =IFERROR(H295/SUMIF($A:$A,A295,$H:$H),0) | J295: =IFERROR(F295/H295,0) | K295: 1.6586511 | L295: 7.0882155 | M295: =IFERROR(L295/K295,0) | N295: 4.2235422 | O295: 9.8621874 | P295: =IFERROR(O295/N295,0) | Q295: =K295+N295 | R295: =L295+O295 | S295: =IFERROR(R295/Q295,0) | T295: =IFERROR(Q295/SUMIF($A:$A,A295,$Q:$Q),0) | U295: =IFERROR(Q295/F295,0) | V295: =F295-R295 | W295: =IFERROR(V295/F295,0) | X295: =IFERROR(VLOOKUP(A295,周报其他费用!$A:$B,2,FALSE)*I295,0) | Y295: 0 | Z295: =IFERROR(Y295/G295,0) | AA295: =Y295-K295/1.06 | AB295: =IFERROR(AA295/G295,0) | AC295: =Y295-(Q295+X295)/1.06 | AD295: =IFERROR(AC295/G295,0)
A296: 7.20-7.26 | B296: 7.20-7.26 | C296: 971242260371 | D296: 韩式袋面 | E296: 新品营多捞面韩式辣蘑菇汤面泡面方便面速食干拌面宿舍宵夜旅行 | F296: 164.03 | G296: =IFERROR(F296/1.13,0) | H296: 9 | I296: =IFERROR(H296/SUMIF($A:$A,A296,$H:$H),0) | J296: =IFERROR(F296/H296,0) | K296: 26.578651 | L296: 189.34822 | M296: =IFERROR(L296/K296,0) | N296: 4.2235422 | O296: 9.8621874 | P296: =IFERROR(O296/N296,0) | Q296: =K296+N296 | R296: =L296+O296 | S296: =IFERROR(R296/Q296,0) | T296: =IFERROR(Q296/SUMIF($A:$A,A296,$Q:$Q),0) | U296: =IFERROR(Q296/F296,0) | V296: =F296-R296 | W296: =IFERROR(V296/F296,0) | X296: =IFERROR(VLOOKUP(A296,周报其他费用!$A:$B,2,FALSE)*I296,0) | Y296: 15.887 | Z296: =IFERROR(Y296/G296,0) | AA296: =Y296-K296/1.06 | AB296: =IFERROR(AA296/G296,0) | AC296: =Y296-(Q296+X296)/1.06 | AD296: =IFERROR(AC296/G296,0)
A297: 7.20-7.26 | B297: 7.20-7.26 | C297: 937005385662 | D297: 日式袋面 | E297: 进口营多正品捞面日式鸡肉鸡汤辛辣味袋装泡面辣味速食方便面汤面 | F297: 218.59 | G297: =IFERROR(F297/1.13,0) | H297: 10 | I297: =IFERROR(H297/SUMIF($A:$A,A297,$H:$H),0) | J297: =IFERROR(F297/H297,0) | K297: 43.158651 | L297: 288.08822 | M297: =IFERROR(L297/K297,0) | N297: 4.2235422 | O297: 9.8621874 | P297: =IFERROR(O297/N297,0) | Q297: =K297+N297 | R297: =L297+O297 | S297: =IFERROR(R297/Q297,0) | T297: =IFERROR(Q297/SUMIF($A:$A,A297,$Q:$Q),0) | U297: =IFERROR(Q297/F297,0) | V297: =F297-R297 | W297: =IFERROR(V297/F297,0) | X297: =IFERROR(VLOOKUP(A297,周报其他费用!$A:$B,2,FALSE)*I297,0) | Y297: 30.148 | Z297: =IFERROR(Y297/G297,0) | AA297: =Y297-K297/1.06 | AB297: =IFERROR(AA297/G297,0) | AC297: =Y297-(Q297+X297)/1.06 | AD297: =IFERROR(AC297/G297,0)
A298: 7.20-7.26 | B298: 7.20-7.26 | C298: 969433743398 | D298: 韩蘑菇 | E298: 新品营多捞面韩式辣蘑菇汤面泡面方便面速食干拌面宿舍宵夜旅行 | F298: 142.44 | G298: =IFERROR(F298/1.13,0) | H298: 7 | I298: =IFERROR(H298/SUMIF($A:$A,A298,$H:$H),0) | J298: =IFERROR(F298/H298,0) | K298: 9.001701 | L298: 41.975613 | M298: =IFERROR(L298/K298,0) | N298: 3.6201791 | O298: 8.4533035 | P298: =IFERROR(O298/N298,0) | Q298: =K298+N298 | R298: =L298+O298 | S298: =IFERROR(R298/Q298,0) | T298: =IFERROR(Q298/SUMIF($A:$A,A298,$Q:$Q),0) | U298: =IFERROR(Q298/F298,0) | V298: =F298-R298 | W298: =IFERROR(V298/F298,0) | X298: =IFERROR(VLOOKUP(A298,周报其他费用!$A:$B,2,FALSE)*I298,0) | Y298: 19.197 | Z298: =IFERROR(Y298/G298,0) | AA298: =Y298-K298/1.06 | AB298: =IFERROR(AA298/G298,0) | AC298: =Y298-(Q298+X298)/1.06 | AD298: =IFERROR(AC298/G298,0)
A299: 7.20-7.26 | B299: 7.20-7.26 | C299: 1067363868298 | F299: 93.18 | G299: =IFERROR(F299/1.13,0) | H299: 5 | I299: =IFERROR(H299/SUMIF($A:$A,A299,$H:$H),0) | J299: =IFERROR(F299/H299,0) | K299: 5.8247508 | L299: 5.063011 | M299: =IFERROR(L299/K299,0) | N299: 3.0168159 | O299: 7.0444196 | P299: =IFERROR(O299/N299,0) | Q299: =K299+N299 | R299: =L299+O299 | S299: =IFERROR(R299/Q299,0) | T299: =IFERROR(Q299/SUMIF($A:$A,A299,$Q:$Q),0) | U299: =IFERROR(Q299/F299,0) | V299: =F299-R299 | W299: =IFERROR(V299/F299,0) | X299: =IFERROR(VLOOKUP(A299,周报其他费用!$A:$B,2,FALSE)*I299,0) | Y299: 6.925 | Z299: =IFERROR(Y299/G299,0) | AA299: =Y299-K299/1.06 | AB299: =IFERROR(AA299/G299,0) | AC299: =Y299-(Q299+X299)/1.06 | AD299: =IFERROR(AC299/G299,0)
A300: 7.20-7.26 | B300: 7.20-7.26 | C300: 649731447266 | D300: 20包经典/牛系列 | E300: 营多印尼进口营多捞面方便面火鸡面干拌面20包宿舍速食泡面夜宵 | F300: 243.5 | G300: =IFERROR(F300/1.13,0) | H300: 5 | I300: =IFERROR(H300/SUMIF($A:$A,A300,$H:$H),0) | J300: =IFERROR(F300/H300,0) | K300: 11.094751 | L300: 5.063011 | M300: =IFERROR(L300/K300,0) | N300: 3.0168159 | O300: 7.0444196 | P300: =IFERROR(O300/N300,0) | Q300: =K300+N300 | R300: =L300+O300 | S300: =IFERROR(R300/Q300,0) | T300: =IFERROR(Q300/SUMIF($A:$A,A300,$Q:$Q),0) | U300: =IFERROR(Q300/F300,0) | V300: =F300-R300 | W300: =IFERROR(V300/F300,0) | X300: =IFERROR(VLOOKUP(A300,周报其他费用!$A:$B,2,FALSE)*I300,0) | Y300: 50.194 | Z300: =IFERROR(Y300/G300,0) | AA300: =Y300-K300/1.06 | AB300: =IFERROR(AA300/G300,0) | AC300: =Y300-(Q300+X300)/1.06 | AD300: =IFERROR(AC300/G300,0)
A301: 7.20-7.26 | B301: 7.20-7.26 | C301: 1067957289054 | D301: 巴东牛肉 | E301: 【新口味】印尼进口营多捞面巴东炖牛肉味泡面方便面宿舍速食宵夜 | F301: 60.93 | G301: =IFERROR(F301/1.13,0) | H301: 4 | I301: =IFERROR(H301/SUMIF($A:$A,A301,$H:$H),0) | J301: =IFERROR(F301/H301,0) | K301: 5.8478007 | L301: 4.0504088 | M301: =IFERROR(L301/K301,0) | N301: 2.4134527 | O301: 5.6355357 | P301: =IFERROR(O301/N301,0) | Q301: =K301+N301 | R301: =L301+O301 | S301: =IFERROR(R301/Q301,0) | T301: =IFERROR(Q301/SUMIF($A:$A,A301,$Q:$Q),0) | U301: =IFERROR(Q301/F301,0) | V301: =F301-R301 | W301: =IFERROR(V301/F301,0) | X301: =IFERROR(VLOOKUP(A301,周报其他费用!$A:$B,2,FALSE)*I301,0) | Y301: 4.936 | Z301: =IFERROR(Y301/G301,0) | AA301: =Y301-K301/1.06 | AB301: =IFERROR(AA301/G301,0) | AC301: =Y301-(Q301+X301)/1.06 | AD301: =IFERROR(AC301/G301,0)
A302: 7.20-7.26 | B302: 7.20-7.26 | C302: 976467954327 | D302: 日韩杯面 | E302: 【天猫U选】indomie营多捞面辣蘑菇味日式辣味杯面 | F302: 28.22 | G302: =IFERROR(F302/1.13,0) | H302: 3 | I302: =IFERROR(H302/SUMIF($A:$A,A302,$H:$H),0) | J302: =IFERROR(F302/H302,0) | K302: 0.71085049 | L302: 3.0378066 | M302: =IFERROR(L302/K302,0) | N302: 1.8100895 | O302: 4.2266517 | P302: =IFERROR(O302/N302,0) | Q302: =K302+N302 | R302: =L302+O302 | S302: =IFERROR(R302/Q302,0) | T302: =IFERROR(Q302/SUMIF($A:$A,A302,$Q:$Q),0) | U302: =IFERROR(Q302/F302,0) | V302: =F302-R302 | W302: =IFERROR(V302/F302,0) | X302: =IFERROR(VLOOKUP(A302,周报其他费用!$A:$B,2,FALSE)*I302,0) | Y302: -5.289 | Z302: =IFERROR(Y302/G302,0) | AA302: =Y302-K302/1.06 | AB302: =IFERROR(AA302/G302,0) | AC302: =Y302-(Q302+X302)/1.06 | AD302: =IFERROR(AC302/G302,0)
A303: 7.20-7.26 | B303: 7.20-7.26 | C303: 932687928859 | D303: 8包组合 | E303: 营多捞面八口味袋装泡面拌面速食面干拌面方便面宿舍宵夜速食家用 | F303: 75.92 | G303: =IFERROR(F303/1.13,0) | H303: 3 | I303: =IFERROR(H303/SUMIF($A:$A,A303,$H:$H),0) | J303: =IFERROR(F303/H303,0) | K303: 7.5908505 | L303: 3.0378066 | M303: =IFERROR(L303/K303,0) | N303: 1.8100895 | O303: 4.2266517 | P303: =IFERROR(O303/N303,0) | Q303: =K303+N303 | R303: =L303+O303 | S303: =IFERROR(R303/Q303,0) | T303: =IFERROR(Q303/SUMIF($A:$A,A303,$Q:$Q),0) | U303: =IFERROR(Q303/F303,0) | V303: =F303-R303 | W303: =IFERROR(V303/F303,0) | X303: =IFERROR(VLOOKUP(A303,周报其他费用!$A:$B,2,FALSE)*I303,0) | Y303: 11.502 | Z303: =IFERROR(Y303/G303,0) | AA303: =Y303-K303/1.06 | AB303: =IFERROR(AA303/G303,0) | AC303: =Y303-(Q303+X303)/1.06 | AD303: =IFERROR(AC303/G303,0)
A304: 7.20-7.26 | B304: 7.20-7.26 | C304: 976466902934 | D304: 【U选】日式原杯1+日式辣杯1 | E304: 【天猫U选】indomie营多捞面辣火鸡味日式鸡肉原味杯面 | F304: 29.5 | G304: =IFERROR(F304/1.13,0) | H304: 3 | I304: =IFERROR(H304/SUMIF($A:$A,A304,$H:$H),0) | J304: =IFERROR(F304/H304,0) | K304: 0.71085049 | L304: 3.0378066 | M304: =IFERROR(L304/K304,0) | N304: 1.8100895 | O304: 4.2266517 | P304: =IFERROR(O304/N304,0) | Q304: =K304+N304 | R304: =L304+O304 | S304: =IFERROR(R304/Q304,0) | T304: =IFERROR(Q304/SUMIF($A:$A,A304,$Q:$Q),0) | U304: =IFERROR(Q304/F304,0) | V304: =F304-R304 | W304: =IFERROR(V304/F304,0) | X304: =IFERROR(VLOOKUP(A304,周报其他费用!$A:$B,2,FALSE)*I304,0) | Y304: -4.241 | Z304: =IFERROR(Y304/G304,0) | AA304: =Y304-K304/1.06 | AB304: =IFERROR(AA304/G304,0) | AC304: =Y304-(Q304+X304)/1.06 | AD304: =IFERROR(AC304/G304,0)
A305: 7.20-7.26 | B305: 7.20-7.26 | C305: 1067350828719 | F305: 148.7 | G305: =IFERROR(F305/1.13,0) | H305: 3 | I305: =IFERROR(H305/SUMIF($A:$A,A305,$H:$H),0) | J305: =IFERROR(F305/H305,0) | K305: 3.7539003 | L305: 20.485204 | M305: =IFERROR(L305/K305,0) | N305: 1.2067264 | O305: 2.8177678 | P305: =IFERROR(O305/N305,0) | Q305: =K305+N305 | R305: =L305+O305 | S305: =IFERROR(R305/Q305,0) | T305: =IFERROR(Q305/SUMIF($A:$A,A305,$Q:$Q),0) | U305: =IFERROR(Q305/F305,0) | V305: =F305-R305 | W305: =IFERROR(V305/F305,0) | X305: =IFERROR(VLOOKUP(A305,周报其他费用!$A:$B,2,FALSE)*I305,0) | Y305: 31.483 | Z305: =IFERROR(Y305/G305,0) | AA305: =Y305-K305/1.06 | AB305: =IFERROR(AA305/G305,0) | AC305: =Y305-(Q305+X305)/1.06 | AD305: =IFERROR(AC305/G305,0)
A306: 7.20-7.26 | B306: 7.20-7.26 | C306: 975092562679 | D306: 杯面混搭 | E306: 营多韩式甜辣炸鸡火鸡面辣蘑菇杯面拌面泡面方便面速食宵夜旅行 | F306: 59.33 | G306: =IFERROR(F306/1.13,0) | H306: 2 | I306: =IFERROR(H306/SUMIF($A:$A,A306,$H:$H),0) | J306: =IFERROR(F306/H306,0) | K306: 1.7139003 | L306: 51.925204 | M306: =IFERROR(L306/K306,0) | N306: 1.2067264 | O306: 2.8177678 | P306: =IFERROR(O306/N306,0) | Q306: =K306+N306 | R306: =L306+O306 | S306: =IFERROR(R306/Q306,0) | T306: =IFERROR(Q306/SUMIF($A:$A,A306,$Q:$Q),0) | U306: =IFERROR(Q306/F306,0) | V306: =F306-R306 | W306: =IFERROR(V306/F306,0) | X306: =IFERROR(VLOOKUP(A306,周报其他费用!$A:$B,2,FALSE)*I306,0) | Y306: 12.234 | Z306: =IFERROR(Y306/G306,0) | AA306: =Y306-K306/1.06 | AB306: =IFERROR(AA306/G306,0) | AC306: =Y306-(Q306+X306)/1.06 | AD306: =IFERROR(AC306/G306,0)
A307: 7.20-7.26 | B307: 7.20-7.26 | C307: 869217868453 | D307: 韩式杯面 | E307: 营多捞面韩式甜辣炸鸡辣蘑菇杯面方便面拌面泡面宿舍速食面 | F307: 32.79 | G307: =IFERROR(F307/1.13,0) | H307: 2 | I307: =IFERROR(H307/SUMIF($A:$A,A307,$H:$H),0) | J307: =IFERROR(F307/H307,0) | K307: 13.7639 | L307: 123.4052 | M307: =IFERROR(L307/K307,0) | N307: 1.2067264 | O307: 2.8177678 | P307: =IFERROR(O307/N307,0) | Q307: =K307+N307 | R307: =L307+O307 | S307: =IFERROR(R307/Q307,0) | T307: =IFERROR(Q307/SUMIF($A:$A,A307,$Q:$Q),0) | U307: =IFERROR(Q307/F307,0) | V307: =F307-R307 | W307: =IFERROR(V307/F307,0) | X307: =IFERROR(VLOOKUP(A307,周报其他费用!$A:$B,2,FALSE)*I307,0) | Y307: 0.66 | Z307: =IFERROR(Y307/G307,0) | AA307: =Y307-K307/1.06 | AB307: =IFERROR(AA307/G307,0) | AC307: =Y307-(Q307+X307)/1.06 | AD307: =IFERROR(AC307/G307,0)
A308: 7.20-7.26 | B308: 7.20-7.26 | C308: 976479938842 | D308: 杯面混搭 | E308: 营多捞面韩式甜辣炸鸡辣蘑菇杯面方便面拌面泡面宿舍速食面 | F308: 18.9 | G308: =IFERROR(F308/1.13,0) | H308: 2 | I308: =IFERROR(H308/SUMIF($A:$A,A308,$H:$H),0) | J308: =IFERROR(F308/H308,0) | K308: 0.47390033 | L308: 2.0252044 | M308: =IFERROR(L308/K308,0) | N308: 1.2067264 | O308: 2.8177678 | P308: =IFERROR(O308/N308,0) | Q308: =K308+N308 | R308: =L308+O308 | S308: =IFERROR(R308/Q308,0) | T308: =IFERROR(Q308/SUMIF($A:$A,A308,$Q:$Q),0) | U308: =IFERROR(Q308/F308,0) | V308: =F308-R308 | W308: =IFERROR(V308/F308,0) | X308: =IFERROR(VLOOKUP(A308,周报其他费用!$A:$B,2,FALSE)*I308,0) | Y308: -6.263 | Z308: =IFERROR(Y308/G308,0) | AA308: =Y308-K308/1.06 | AB308: =IFERROR(AA308/G308,0) | AC308: =Y308-(Q308+X308)/1.06 | AD308: =IFERROR(AC308/G308,0)
A309: 7.20-7.26 | B309: 7.20-7.26 | C309: 903183018417 | D309: 杯面混搭 | E309: 印尼进口营多捞面杯面原味甜辣蘑菇味整箱速食拌面拉面泡面方便面 | F309: 38.36 | G309: =IFERROR(F309/1.13,0) | H309: 2 | I309: =IFERROR(H309/SUMIF($A:$A,A309,$H:$H),0) | J309: =IFERROR(F309/H309,0) | K309: 3.5139003 | L309: 2.0252044 | M309: =IFERROR(L309/K309,0) | N309: 1.2067264 | O309: 2.8177678 | P309: =IFERROR(O309/N309,0) | Q309: =K309+N309 | R309: =L309+O309 | S309: =IFERROR(R309/Q309,0) | T309: =IFERROR(Q309/SUMIF($A:$A,A309,$Q:$Q),0) | U309: =IFERROR(Q309/F309,0) | V309: =F309-R309 | W309: =IFERROR(V309/F309,0) | X309: =IFERROR(VLOOKUP(A309,周报其他费用!$A:$B,2,FALSE)*I309,0) | Y309: 3.134 | Z309: =IFERROR(Y309/G309,0) | AA309: =Y309-K309/1.06 | AB309: =IFERROR(AA309/G309,0) | AC309: =Y309-(Q309+X309)/1.06 | AD309: =IFERROR(AC309/G309,0)
A310: 7.27-8.2 | B310: 7.27-8.2 | C310: 668566625747 | D310: 袋面主链接 | E310: 印尼营多捞面进口网红泡面袋装方便面速食食品拉面火鸡面拌面整箱 | F310: 38360 | G310: =IFERROR(F310/1.13,0) | H310: 1566 | I310: =IFERROR(H310/SUMIF($A:$A,A310,$H:$H),0) | J310: =IFERROR(F310/H310,0) | K310: 4534.4611 | L310: 31378.871 | M310: =IFERROR(L310/K310,0) | N310: 788.99058 | O310: 1697.1515 | P310: =IFERROR(O310/N310,0) | Q310: =K310+N310 | R310: =L310+O310 | S310: =IFERROR(R310/Q310,0) | T310: =IFERROR(Q310/SUMIF($A:$A,A310,$Q:$Q),0) | U310: =IFERROR(Q310/F310,0) | V310: =F310-R310 | W310: =IFERROR(V310/F310,0) | X310: =IFERROR(VLOOKUP(A310,周报其他费用!$A:$B,2,FALSE)*I310,0) | Y310: 5163.457 | Z310: =IFERROR(Y310/G310,0) | AA310: =Y310-K310/1.06 | AB310: =IFERROR(AA310/G310,0) | AC310: =Y310-(Q310+X310)/1.06 | AD310: =IFERROR(AC310/G310,0)
A311: 7.27-8.2 | B311: 7.27-8.2 | C311: 649361890551 | D311: 袋面次链接 | E311: 营多捞面印尼进口Indomie网红夜宵早餐方便面火鸡面泡面拌面 | F311: 15822.7 | G311: =IFERROR(F311/1.13,0) | H311: 793 | I311: =IFERROR(H311/SUMIF($A:$A,A311,$H:$H),0) | J311: =IFERROR(F311/H311,0) | K311: 2709.3747 | L311: 14621.872 | M311: =IFERROR(L311/K311,0) | N311: 399.53355 | O311: 859.41326 | P311: =IFERROR(O311/N311,0) | Q311: =K311+N311 | R311: =L311+O311 | S311: =IFERROR(R311/Q311,0) | T311: =IFERROR(Q311/SUMIF($A:$A,A311,$Q:$Q),0) | U311: =IFERROR(Q311/F311,0) | V311: =F311-R311 | W311: =IFERROR(V311/F311,0) | X311: =IFERROR(VLOOKUP(A311,周报其他费用!$A:$B,2,FALSE)*I311,0) | Y311: 1570.043 | Z311: =IFERROR(Y311/G311,0) | AA311: =Y311-K311/1.06 | AB311: =IFERROR(AA311/G311,0) | AC311: =Y311-(Q311+X311)/1.06 | AD311: =IFERROR(AC311/G311,0)
A312: 7.27-8.2 | B312: 7.27-8.2 | C312: 649735171438 | D312: 杯面主链接 | E312: 印尼进口indomie营多捞面杯面速食泡面干拌面盒桶装方便面火鸡面 | F312: 15355.2 | G312: =IFERROR(F312/1.13,0) | H312: 619 | I312: =IFERROR(H312/SUMIF($A:$A,A312,$H:$H),0) | J312: =IFERROR(F312/H312,0) | K312: 2185.0345 | L312: 10082.831 | M312: =IFERROR(L312/K312,0) | N312: 311.86793 | O312: 670.84087 | P312: =IFERROR(O312/N312,0) | Q312: =K312+N312 | R312: =L312+O312 | S312: =IFERROR(R312/Q312,0) | T312: =IFERROR(Q312/SUMIF($A:$A,A312,$Q:$Q),0) | U312: =IFERROR(Q312/F312,0) | V312: =F312-R312 | W312: =IFERROR(V312/F312,0) | X312: =IFERROR(VLOOKUP(A312,周报其他费用!$A:$B,2,FALSE)*I312,0) | Y312: 1871.199 | Z312: =IFERROR(Y312/G312,0) | AA312: =Y312-K312/1.06 | AB312: =IFERROR(AA312/G312,0) | AC312: =Y312-(Q312+X312)/1.06 | AD312: =IFERROR(AC312/G312,0)
A313: 7.27-8.2 | B313: 7.27-8.2 | C313: 1058280415678 | D313: 原味大包 | E313: 印尼进口大大包营多原味捞面5包干拌面速食超大包方便面速食宵夜 | F313: 5107.37 | G313: =IFERROR(F313/1.13,0) | H313: 184 | I313: =IFERROR(H313/SUMIF($A:$A,A313,$H:$H),0) | J313: =IFERROR(F313/H313,0) | K313: 858.63922 | L313: 4651.7177 | M313: =IFERROR(L313/K313,0) | N313: 92.703874 | O313: 199.40989 | P313: =IFERROR(O313/N313,0) | Q313: =K313+N313 | R313: =L313+O313 | S313: =IFERROR(R313/Q313,0) | T313: =IFERROR(Q313/SUMIF($A:$A,A313,$Q:$Q),0) | U313: =IFERROR(Q313/F313,0) | V313: =F313-R313 | W313: =IFERROR(V313/F313,0) | X313: =IFERROR(VLOOKUP(A313,周报其他费用!$A:$B,2,FALSE)*I313,0) | Y313: 1095.84 | Z313: =IFERROR(Y313/G313,0) | AA313: =Y313-K313/1.06 | AB313: =IFERROR(AA313/G313,0) | AC313: =Y313-(Q313+X313)/1.06 | AD313: =IFERROR(AC313/G313,0)
A314: 7.27-8.2 | B314: 7.27-8.2 | C314: 1057479227624 | D314: 巴东牛肉 | E314: 【新口味】印尼进口营多捞面巴东炖牛肉味泡面方便面宿舍速食宵夜 | F314: 2736.09 | G314: =IFERROR(F314/1.13,0) | H314: 157 | I314: =IFERROR(H314/SUMIF($A:$A,A314,$H:$H),0) | J314: =IFERROR(F314/H314,0) | K314: 805.60868 | L314: 3892.9062 | M314: =IFERROR(L314/K314,0) | N314: 79.100589 | O314: 170.14865 | P314: =IFERROR(O314/N314,0) | Q314: =K314+N314 | R314: =L314+O314 | S314: =IFERROR(R314/Q314,0) | T314: =IFERROR(Q314/SUMIF($A:$A,A314,$Q:$Q),0) | U314: =IFERROR(Q314/F314,0) | V314: =F314-R314 | W314: =IFERROR(V314/F314,0) | X314: =IFERROR(VLOOKUP(A314,周报其他费用!$A:$B,2,FALSE)*I314,0) | Y314: 299.643 | Z314: =IFERROR(Y314/G314,0) | AA314: =Y314-K314/1.06 | AB314: =IFERROR(AA314/G314,0) | AC314: =Y314-(Q314+X314)/1.06 | AD314: =IFERROR(AC314/G314,0)
A315: 7.27-8.2 | B315: 7.27-8.2 | C315: 648600900806 | D315: 30包 | E315: 进口营多捞面一整箱30包网红速食方便面宿舍速食泡面干拌面拉面 | F315: 10398.16 | G315: =IFERROR(F315/1.13,0) | H315: 153 | I315: =IFERROR(H315/SUMIF($A:$A,A315,$H:$H),0) | J315: =IFERROR(F315/H315,0) | K315: 2406.263 | L315: 10799.196 | M315: =IFERROR(L315/K315,0) | N315: 77.085287 | O315: 165.81366 | P315: =IFERROR(O315/N315,0) | Q315: =K315+N315 | R315: =L315+O315 | S315: =IFERROR(R315/Q315,0) | T315: =IFERROR(Q315/SUMIF($A:$A,A315,$Q:$Q),0) | U315: =IFERROR(Q315/F315,0) | V315: =F315-R315 | W315: =IFERROR(V315/F315,0) | X315: =IFERROR(VLOOKUP(A315,周报其他费用!$A:$B,2,FALSE)*I315,0) | Y315: 1930.47 | Z315: =IFERROR(Y315/G315,0) | AA315: =Y315-K315/1.06 | AB315: =IFERROR(AA315/G315,0) | AC315: =Y315-(Q315+X315)/1.06 | AD315: =IFERROR(AC315/G315,0)
A316: 7.27-8.2 | B316: 7.27-8.2 | C316: 649369494424 | D316: 24包经典/牛系列 | E316: 营多捞面干拌面一整箱24袋装批发泡面混搭宿舍速食方便面火鸡面 | F316: 4152.8 | G316: =IFERROR(F316/1.13,0) | H316: 75 | I316: =IFERROR(H316/SUMIF($A:$A,A316,$H:$H),0) | J316: =IFERROR(F316/H316,0) | K316: 613.92816 | L316: 2197.7288 | M316: =IFERROR(L316/K316,0) | N316: 37.786905 | O316: 81.281204 | P316: =IFERROR(O316/N316,0) | Q316: =K316+N316 | R316: =L316+O316 | S316: =IFERROR(R316/Q316,0) | T316: =IFERROR(Q316/SUMIF($A:$A,A316,$Q:$Q),0) | U316: =IFERROR(Q316/F316,0) | V316: =F316-R316 | W316: =IFERROR(V316/F316,0) | X316: =IFERROR(VLOOKUP(A316,周报其他费用!$A:$B,2,FALSE)*I316,0) | Y316: 783.066 | Z316: =IFERROR(Y316/G316,0) | AA316: =Y316-K316/1.06 | AB316: =IFERROR(AA316/G316,0) | AC316: =Y316-(Q316+X316)/1.06 | AD316: =IFERROR(AC316/G316,0)
A317: 7.27-8.2 | B317: 7.27-8.2 | C317: 648681860568 | D317: 杯面次链接 | E317: 营多捞面杯装方便面泡面速食干拌面原味整箱批发印尼进口桶装拌面 | F317: 1135.09 | G317: =IFERROR(F317/1.13,0) | H317: 66 | I317: =IFERROR(H317/SUMIF($A:$A,A317,$H:$H),0) | J317: =IFERROR(F317/H317,0) | K317: 250.35798 | L317: 1223.825 | M317: =IFERROR(L317/K317,0) | N317: 33.252477 | O317: 71.52746 | P317: =IFERROR(O317/N317,0) | Q317: =K317+N317 | R317: =L317+O317 | S317: =IFERROR(R317/Q317,0) | T317: =IFERROR(Q317/SUMIF($A:$A,A317,$Q:$Q),0) | U317: =IFERROR(Q317/F317,0) | V317: =F317-R317 | W317: =IFERROR(V317/F317,0) | X317: =IFERROR(VLOOKUP(A317,周报其他费用!$A:$B,2,FALSE)*I317,0) | Y317: 21.311 | Z317: =IFERROR(Y317/G317,0) | AA317: =Y317-K317/1.06 | AB317: =IFERROR(AA317/G317,0) | AC317: =Y317-(Q317+X317)/1.06 | AD317: =IFERROR(AC317/G317,0)
... A346: 7.27-8.2 | B346: 7.27-8.2 | C346: 947413291596 | D346: 杯面混搭 | E346: 印尼进口营多捞面杯面原味甜辣蘑菇味整箱速食拌面拉面泡面方便面 | F346: 55.15 | G346: =IFERROR(F346/1.13,0) | H346: 2 | I346: =IFERROR(H346/SUMIF($A:$A,A346,$H:$H),0) | J346: =IFERROR(F346/H346,0) | K346: 5.5478176 | L346: 2.3453016 | M346: =IFERROR(L346/K346,0) | N346: 1.0076508 | O346: 2.1674988 | P346: =IFERROR(O346/N346,0) | Q346: =K346+N346 | R346: =L346+O346 | S346: =IFERROR(R346/Q346,0) | T346: =IFERROR(Q346/SUMIF($A:$A,A346,$Q:$Q),0) | U346: =IFERROR(Q346/F346,0) | V346: =F346-R346 | W346: =IFERROR(V346/F346,0) | X346: =IFERROR(VLOOKUP(A346,周报其他费用!$A:$B,2,FALSE)*I346,0) | Y346: 6.768 | Z346: =IFERROR(Y346/G346,0) | AA346: =Y346-K346/1.06 | AB346: =IFERROR(AA346/G346,0) | AC346: =Y346-(Q346+X346)/1.06 | AD346: =IFERROR(AC346/G346,0)
