Workbook

Sheet 01-汇报摘要
A1: 天猫近3个月 · ID周净利润分析汇报
A2: 口径：数据源ID周损益｜其他费用按周报校准｜推广后=推广前−(花费+其他费用)/1.06｜打开后请开启自动计算
A4: 一、一句话
A5: 亏在大链接：袋面主链/次链 + 杯面主链贡献大部分亏损。而是“量/规格结构掉 → 推广前掉”，以及局部“加投 → 费率吃利润”。
A7: 二、核心结论
A8: 序号 | B8: 结论
A9: 结论1 | B9: 近三个月ID口径持续亏损；最好一周是7.6-7.12（推广后约-4109），之后再度走弱。
A10: 结论2 | B10: 主亏ID：649361890551（袋面次）、668566625747（袋面主）、649735171438（杯面主）。
A11: 结论3 | B11: 原因要分段：7.6→7.13 主要是推广前利润下降（要看规格搭配）；7.13→7.20 主要是推广费上升（次链/30包加投）。
A12: 结论4 | B12: 价格不是主因：主链推广前利率大体稳定（主链~13%、次链~9%、杯面~11%），更像量与规格结构问题。
A13: 结论5 | B13: 巴东链接推广费率约23%–36%（成交较大周），属推广费偏高型亏损；原味大大包需控加投，但不是主亏源。
A15: 三、请拍板
A16: ① 复盘袋面主链5747：规格搭配与销量结构（推广前）
A17: ② 压降次链0551、30包低效花费（费率）
A18: ③ 巴东减投/停投一周验证
A19: ④ 24/15/30包与头部混搭用「ID×搭配」盯周利润
A20: ⑤ 大大包严控加投侵蚀
A22: 四、数据源周汇总（公式）
A23: 周次 | B23: 成交金额 | C23: 推广前利润 | D23: 推广花费 | E23: 其他费用 | F23: 推广后利润
A24: 5.11-5.17 | B24: =SUMIF(数据源!A:A,A24,数据源!E:E) | C24: =SUMIF(数据源!A:A,A24,数据源!X:X) | D24: =SUMIF(数据源!A:A,A24,数据源!P:P) | E24: =SUMIF(数据源!A:A,A24,数据源!W:W) | F24: =SUMIF(数据源!A:A,A24,数据源!AB:AB)
A25: 5.25-5.31 | B25: =SUMIF(数据源!A:A,A25,数据源!E:E) | C25: =SUMIF(数据源!A:A,A25,数据源!X:X) | D25: =SUMIF(数据源!A:A,A25,数据源!P:P) | E25: =SUMIF(数据源!A:A,A25,数据源!W:W) | F25: =SUMIF(数据源!A:A,A25,数据源!AB:AB)
A26: 6.15-6.21 | B26: =SUMIF(数据源!A:A,A26,数据源!E:E) | C26: =SUMIF(数据源!A:A,A26,数据源!X:X) | D26: =SUMIF(数据源!A:A,A26,数据源!P:P) | E26: =SUMIF(数据源!A:A,A26,数据源!W:W) | F26: =SUMIF(数据源!A:A,A26,数据源!AB:AB)
A27: 6.22-6.28 | B27: =SUMIF(数据源!A:A,A27,数据源!E:E) | C27: =SUMIF(数据源!A:A,A27,数据源!X:X) | D27: =SUMIF(数据源!A:A,A27,数据源!P:P) | E27: =SUMIF(数据源!A:A,A27,数据源!W:W) | F27: =SUMIF(数据源!A:A,A27,数据源!AB:AB)
A28: 6.29-7.5 | B28: =SUMIF(数据源!A:A,A28,数据源!E:E) | C28: =SUMIF(数据源!A:A,A28,数据源!X:X) | D28: =SUMIF(数据源!A:A,A28,数据源!P:P) | E28: =SUMIF(数据源!A:A,A28,数据源!W:W) | F28: =SUMIF(数据源!A:A,A28,数据源!AB:AB)
A29: 7.6-7.12 | B29: =SUMIF(数据源!A:A,A29,数据源!E:E) | C29: =SUMIF(数据源!A:A,A29,数据源!X:X) | D29: =SUMIF(数据源!A:A,A29,数据源!P:P) | E29: =SUMIF(数据源!A:A,A29,数据源!W:W) | F29: =SUMIF(数据源!A:A,A29,数据源!AB:AB)
A30: 7.13-7.19 | B30: =SUMIF(数据源!A:A,A30,数据源!E:E) | C30: =SUMIF(数据源!A:A,A30,数据源!X:X) | D30: =SUMIF(数据源!A:A,A30,数据源!P:P) | E30: =SUMIF(数据源!A:A,A30,数据源!W:W) | F30: =SUMIF(数据源!A:A,A30,数据源!AB:AB)
A31: 7.20-7.26 | B31: =SUMIF(数据源!A:A,A31,数据源!E:E) | C31: =SUMIF(数据源!A:A,A31,数据源!X:X) | D31: =SUMIF(数据源!A:A,A31,数据源!P:P) | E31: =SUMIF(数据源!A:A,A31,数据源!W:W) | F31: =SUMIF(数据源!A:A,A31,数据源!AB:AB)
A32: 7.27-8.2 | B32: =SUMIF(数据源!A:A,A32,数据源!E:E) | C32: =SUMIF(数据源!A:A,A32,数据源!X:X) | D32: =SUMIF(数据源!A:A,A32,数据源!P:P) | E32: =SUMIF(数据源!A:A,A32,数据源!W:W) | F32: =SUMIF(数据源!A:A,A32,数据源!AB:AB)

Sheet 02-整体周趋势
A1: 整体经营周趋势
A2: 仅数据源9周ID口径（不含店铺周报5.18/6.1/6.8）｜数值为公式，请开启自动计算
A3: 周次 | B3: 成交金额 | C3: 推广前净利润 | D3: 推广花费 | E3: 其他费用 | F3: 推广后净利润 | G3: 环比变化
A4: 5.11-5.17 | B4: =SUMIF(数据源!A:A,A4,数据源!E:E) | C4: =SUMIF(数据源!A:A,A4,数据源!X:X) | D4: =SUMIF(数据源!A:A,A4,数据源!P:P) | E4: =SUMIF(数据源!A:A,A4,数据源!W:W) | F4: =SUMIF(数据源!A:A,A4,数据源!AB:AB)
A5: 5.25-5.31 | B5: =SUMIF(数据源!A:A,A5,数据源!E:E) | C5: =SUMIF(数据源!A:A,A5,数据源!X:X) | D5: =SUMIF(数据源!A:A,A5,数据源!P:P) | E5: =SUMIF(数据源!A:A,A5,数据源!W:W) | F5: =SUMIF(数据源!A:A,A5,数据源!AB:AB) | G5: =F5-F4
A6: 6.15-6.21 | B6: =SUMIF(数据源!A:A,A6,数据源!E:E) | C6: =SUMIF(数据源!A:A,A6,数据源!X:X) | D6: =SUMIF(数据源!A:A,A6,数据源!P:P) | E6: =SUMIF(数据源!A:A,A6,数据源!W:W) | F6: =SUMIF(数据源!A:A,A6,数据源!AB:AB) | G6: =F6-F5
A7: 6.22-6.28 | B7: =SUMIF(数据源!A:A,A7,数据源!E:E) | C7: =SUMIF(数据源!A:A,A7,数据源!X:X) | D7: =SUMIF(数据源!A:A,A7,数据源!P:P) | E7: =SUMIF(数据源!A:A,A7,数据源!W:W) | F7: =SUMIF(数据源!A:A,A7,数据源!AB:AB) | G7: =F7-F6
A8: 6.29-7.5 | B8: =SUMIF(数据源!A:A,A8,数据源!E:E) | C8: =SUMIF(数据源!A:A,A8,数据源!X:X) | D8: =SUMIF(数据源!A:A,A8,数据源!P:P) | E8: =SUMIF(数据源!A:A,A8,数据源!W:W) | F8: =SUMIF(数据源!A:A,A8,数据源!AB:AB) | G8: =F8-F7
A9: 7.6-7.12 | B9: =SUMIF(数据源!A:A,A9,数据源!E:E) | C9: =SUMIF(数据源!A:A,A9,数据源!X:X) | D9: =SUMIF(数据源!A:A,A9,数据源!P:P) | E9: =SUMIF(数据源!A:A,A9,数据源!W:W) | F9: =SUMIF(数据源!A:A,A9,数据源!AB:AB) | G9: =F9-F8
A10: 7.13-7.19 | B10: =SUMIF(数据源!A:A,A10,数据源!E:E) | C10: =SUMIF(数据源!A:A,A10,数据源!X:X) | D10: =SUMIF(数据源!A:A,A10,数据源!P:P) | E10: =SUMIF(数据源!A:A,A10,数据源!W:W) | F10: =SUMIF(数据源!A:A,A10,数据源!AB:AB) | G10: =F10-F9
A11: 7.20-7.26 | B11: =SUMIF(数据源!A:A,A11,数据源!E:E) | C11: =SUMIF(数据源!A:A,A11,数据源!X:X) | D11: =SUMIF(数据源!A:A,A11,数据源!P:P) | E11: =SUMIF(数据源!A:A,A11,数据源!W:W) | F11: =SUMIF(数据源!A:A,A11,数据源!AB:AB) | G11: =F11-F10
A12: 7.27-8.2 | B12: =SUMIF(数据源!A:A,A12,数据源!E:E) | C12: =SUMIF(数据源!A:A,A12,数据源!X:X) | D12: =SUMIF(数据源!A:A,A12,数据源!P:P) | E12: =SUMIF(数据源!A:A,A12,数据源!W:W) | F12: =SUMIF(数据源!A:A,A12,数据源!AB:AB) | G12: =F12-F11

Sheet 03-近周回落归因
A1: 近周利润回落归因（7.6-7.12 → 7.13-7.19）
A2: 金额SUMIFS自数据源；变化=后周−前周；定位/名称与数据源当周一致
A4: 拖累 TOP10（变化越负，拖累越大）
A5: 排名 | B5: 商品ID | C5: 定位 | D5: 商品名称 | E5: 7.6-7.12 | F5: 7.13-7.19 | G5: 变化
A6: 1 | B6: 668566625747 | C6: 袋面主链接 | D6: 印尼营多捞面进口网红泡面袋装方便面速食食品拉面火鸡面拌面整箱 | E6: =SUMIFS(数据源!AB:AB,数据源!B:B,B6,数据源!A:A,"7.6-7.12") | F6: =SUMIFS(数据源!AB:AB,数据源!B:B,B6,数据源!A:A,"7.13-7.19") | G6: =F6-E6
A7: 2 | B7: 648600900806 | C7: 30包 | D7: 进口营多捞面一整箱30包网红速食方便面宿舍速食泡面干拌面拉面 | E7: =SUMIFS(数据源!AB:AB,数据源!B:B,B7,数据源!A:A,"7.6-7.12") | F7: =SUMIFS(数据源!AB:AB,数据源!B:B,B7,数据源!A:A,"7.13-7.19") | G7: =F7-E7
A8: 3 | B8: 649369494424 | C8: 24包经典/牛系列 | D8: 营多捞面干拌面一整箱24袋装批发泡面混搭宿舍速食方便面火鸡面 | E8: =SUMIFS(数据源!AB:AB,数据源!B:B,B8,数据源!A:A,"7.6-7.12") | F8: =SUMIFS(数据源!AB:AB,数据源!B:B,B8,数据源!A:A,"7.13-7.19") | G8: =F8-E8
A9: 4 | B9: 766165464414 | C9: 12包 | D9: 营多印尼进口营多捞面方便面火鸡面干拌面12包宿舍速食泡面夜宵 | E9: =SUMIFS(数据源!AB:AB,数据源!B:B,B9,数据源!A:A,"7.6-7.12") | F9: =SUMIFS(数据源!AB:AB,数据源!B:B,B9,数据源!A:A,"7.13-7.19") | G9: =F9-E9
A10: 5 | B10: 648598580775 | C10: 15包 | D10: 进口营多捞面15包Indomie方便面干拌面夜宵方便速食五连包85g*5 | E10: =SUMIFS(数据源!AB:AB,数据源!B:B,B10,数据源!A:A,"7.6-7.12") | F10: =SUMIFS(数据源!AB:AB,数据源!B:B,B10,数据源!A:A,"7.13-7.19") | G10: =F10-E10
A11: 6 | B11: 1059563993918 | C11: 原味大包 | D11: indomie印尼进口营多原味大大包129g捞面方便面速食食品宵夜小吃 | E11: =SUMIFS(数据源!AB:AB,数据源!B:B,B11,数据源!A:A,"7.6-7.12") | F11: =SUMIFS(数据源!AB:AB,数据源!B:B,B11,数据源!A:A,"7.13-7.19") | G11: =F11-E11
A12: 7 | B12: 649014937782 | C12: 24包 | D12: 印尼营多捞面干拌面一整箱24袋装批发泡面宿舍速食方便面火鸡面 | E12: =SUMIFS(数据源!AB:AB,数据源!B:B,B12,数据源!A:A,"7.6-7.12") | F12: =SUMIFS(数据源!AB:AB,数据源!B:B,B12,数据源!A:A,"7.13-7.19") | G12: =F12-E12
A13: 8 | B13: 1013887677295 | C13: 混搭5杯 | D13: 进口营多原味杯面日式杯面韩式杯面泡面方便面汤面宿舍速食夜宵 | E13: =SUMIFS(数据源!AB:AB,数据源!B:B,B13,数据源!A:A,"7.6-7.12") | F13: =SUMIFS(数据源!AB:AB,数据源!B:B,B13,数据源!A:A,"7.13-7.19") | G13: =F13-E13
A14: 9 | B14: 648604228786 | C14: 杯面混搭 | D14: INDOMIE营多日式杯面原味经典泡面整箱批发速食宿舍旅行宵夜宿舍 | E14: =SUMIFS(数据源!AB:AB,数据源!B:B,B14,数据源!A:A,"7.6-7.12") | F14: =SUMIFS(数据源!AB:AB,数据源!B:B,B14,数据源!A:A,"7.13-7.19") | G14: =F14-E14
A15: 10 | B15: 735014804839 | C15: 24/30包 | D15: 进口营多捞面多口味Indomie网红方便面干拌面泡面30包整箱批发面 | E15: =SUMIFS(数据源!AB:AB,数据源!B:B,B15,数据源!A:A,"7.6-7.12") | F15: =SUMIFS(数据源!AB:AB,数据源!B:B,B15,数据源!A:A,"7.13-7.19") | G15: =F15-E15
A17: 改善 TOP5（变化越正，改善越大）
A18: 排名 | B18: 商品ID | C18: 定位 | D18: 商品名称 | E18: 7.6-7.12 | F18: 7.13-7.19 | G18: 变化
A19: 1 | B19: 649361890551 | C19: 袋面次链接 | D19: 营多捞面印尼进口Indomie网红夜宵早餐方便面火鸡面泡面拌面 | E19: =SUMIFS(数据源!AB:AB,数据源!B:B,B19,数据源!A:A,"7.6-7.12") | F19: =SUMIFS(数据源!AB:AB,数据源!B:B,B19,数据源!A:A,"7.13-7.19") | G19: =F19-E19
A20: 2 | B20: 649735171438 | C20: 杯面主链接 | D20: 印尼进口indomie营多捞面杯面速食泡面干拌面盒桶装方便面火鸡面 | E20: =SUMIFS(数据源!AB:AB,数据源!B:B,B20,数据源!A:A,"7.6-7.12") | F20: =SUMIFS(数据源!AB:AB,数据源!B:B,B20,数据源!A:A,"7.13-7.19") | G20: =F20-E20
A21: 3 | B21: 648681860568 | C21: 杯面次链接 | D21: 营多捞面杯装方便面泡面速食干拌面原味整箱批发印尼进口桶装拌面 | E21: =SUMIFS(数据源!AB:AB,数据源!B:B,B21,数据源!A:A,"7.6-7.12") | F21: =SUMIFS(数据源!AB:AB,数据源!B:B,B21,数据源!A:A,"7.13-7.19") | G21: =F21-E21
A22: 4 | B22: 971242260371 | C22: 韩式袋面 | D22: 新品营多捞面韩式辣蘑菇汤面泡面方便面速食干拌面宿舍宵夜旅行 | E22: =SUMIFS(数据源!AB:AB,数据源!B:B,B22,数据源!A:A,"7.6-7.12") | F22: =SUMIFS(数据源!AB:AB,数据源!B:B,B22,数据源!A:A,"7.13-7.19") | G22: =F22-E22
A23: 5 | B23: 1058280415678 | C23: 巴东牛肉 | D23: 【新口味】印尼进口营多捞面巴东炖牛肉味泡面方便面宿舍速食宵夜 | E23: =SUMIFS(数据源!AB:AB,数据源!B:B,B23,数据源!A:A,"7.6-7.12") | F23: =SUMIFS(数据源!AB:AB,数据源!B:B,B23,数据源!A:A,"7.13-7.19") | G23: =F23-E23
A25: 本阶段合计变化 | C25: =SUMIF(数据源!A:A,"7.13-7.19",数据源!AB:AB)-SUMIF(数据源!A:A,"7.6-7.12",数据源!AB:AB)

Sheet 04-各周亏损TOP5
A1: 各周亏损最大的前5个ID
A2: 净利润/成交/占比均SUMIFS自本文件数据源；占比=该ID推广后/当周推广后合计
A3: 周次 | B3: 排名 | C3: 商品ID | D3: 定位 | E3: 商品名称 | F3: 净利润(推广后) | G3: 成交金额 | H3: 占当周总净利
A4: 5.11-5.17 | B4: 1 | C4: 649361890551 | D4: 袋面次链接 | E4: 营多捞面印尼进口Indomie网红夜宵早餐方便面火鸡面泡面拌面 | F4: =SUMIFS(数据源!AB:AB,数据源!B:B,C4,数据源!A:A,A4) | G4: =SUMIFS(数据源!E:E,数据源!B:B,C4,数据源!A:A,A4) | H4: =IFERROR(F4/SUMIF(数据源!A:A,A4,数据源!AB:AB),0)
B5: 2 | C5: 668566625747 | D5: 袋面主链接 | E5: 印尼营多捞面进口网红泡面袋装方便面速食食品拉面火鸡面拌面整箱 | F5: =SUMIFS(数据源!AB:AB,数据源!B:B,C5,数据源!A:A,A4) | G5: =SUMIFS(数据源!E:E,数据源!B:B,C5,数据源!A:A,A4) | H5: =IFERROR(F5/SUMIF(数据源!A:A,A4,数据源!AB:AB),0)
B6: 3 | C6: 649735171438 | D6: 杯面主链接 | E6: 印尼进口indomie营多捞面杯面速食泡面干拌面盒桶装方便面火鸡面 | F6: =SUMIFS(数据源!AB:AB,数据源!B:B,C6,数据源!A:A,A4) | G6: =SUMIFS(数据源!E:E,数据源!B:B,C6,数据源!A:A,A4) | H6: =IFERROR(F6/SUMIF(数据源!A:A,A4,数据源!AB:AB),0)
B7: 4 | C7: 649014937782 | D7: 24包 | E7: 印尼营多捞面干拌面一整箱24袋装批发泡面宿舍速食方便面火鸡面 | F7: =SUMIFS(数据源!AB:AB,数据源!B:B,C7,数据源!A:A,A4) | G7: =SUMIFS(数据源!E:E,数据源!B:B,C7,数据源!A:A,A4) | H7: =IFERROR(F7/SUMIF(数据源!A:A,A4,数据源!AB:AB),0)
B8: 5 | C8: 937005385662 | D8: 日式袋面 | E8: 进口营多正品捞面日式鸡肉鸡汤辛辣味袋装泡面辣味速食方便面汤面 | F8: =SUMIFS(数据源!AB:AB,数据源!B:B,C8,数据源!A:A,A4) | G8: =SUMIFS(数据源!E:E,数据源!B:B,C8,数据源!A:A,A4) | H8: =IFERROR(F8/SUMIF(数据源!A:A,A4,数据源!AB:AB),0)
A9: 5.25-5.31 | B9: 1 | C9: 649361890551 | D9: 袋面次链接 | E9: 营多捞面印尼进口Indomie网红夜宵早餐方便面火鸡面泡面拌面 | F9: =SUMIFS(数据源!AB:AB,数据源!B:B,C9,数据源!A:A,A9) | G9: =SUMIFS(数据源!E:E,数据源!B:B,C9,数据源!A:A,A9) | H9: =IFERROR(F9/SUMIF(数据源!A:A,A9,数据源!AB:AB),0)
B10: 2 | C10: 668566625747 | D10: 袋面主链接 | E10: 印尼营多捞面进口网红泡面袋装方便面速食食品拉面火鸡面拌面整箱 | F10: =SUMIFS(数据源!AB:AB,数据源!B:B,C10,数据源!A:A,A9) | G10: =SUMIFS(数据源!E:E,数据源!B:B,C10,数据源!A:A,A9) | H10: =IFERROR(F10/SUMIF(数据源!A:A,A9,数据源!AB:AB),0)
B11: 3 | C11: 649735171438 | D11: 杯面主链接 | E11: 印尼进口indomie营多捞面杯面速食泡面干拌面盒桶装方便面火鸡面 | F11: =SUMIFS(数据源!AB:AB,数据源!B:B,C11,数据源!A:A,A9) | G11: =SUMIFS(数据源!E:E,数据源!B:B,C11,数据源!A:A,A9) | H11: =IFERROR(F11/SUMIF(数据源!A:A,A9,数据源!AB:AB),0)
B12: 4 | C12: 649014937782 | D12: 24包 | E12: 印尼营多捞面干拌面一整箱24袋装批发泡面宿舍速食方便面火鸡面 | F12: =SUMIFS(数据源!AB:AB,数据源!B:B,C12,数据源!A:A,A9) | G12: =SUMIFS(数据源!E:E,数据源!B:B,C12,数据源!A:A,A9) | H12: =IFERROR(F12/SUMIF(数据源!A:A,A9,数据源!AB:AB),0)
B13: 5 | C13: 1013887677295 | D13: 混搭5杯 | E13: 进口营多原味杯面日式杯面韩式杯面泡面方便面汤面宿舍速食夜宵 | F13: =SUMIFS(数据源!AB:AB,数据源!B:B,C13,数据源!A:A,A9) | G13: =SUMIFS(数据源!E:E,数据源!B:B,C13,数据源!A:A,A9) | H13: =IFERROR(F13/SUMIF(数据源!A:A,A9,数据源!AB:AB),0)
A14: 6.15-6.21 | B14: 1 | C14: 649361890551 | D14: 袋面次链接 | E14: 营多捞面印尼进口Indomie网红夜宵早餐方便面火鸡面泡面拌面 | F14: =SUMIFS(数据源!AB:AB,数据源!B:B,C14,数据源!A:A,A14) | G14: =SUMIFS(数据源!E:E,数据源!B:B,C14,数据源!A:A,A14) | H14: =IFERROR(F14/SUMIF(数据源!A:A,A14,数据源!AB:AB),0)
B15: 2 | C15: 649735171438 | D15: 杯面主链接 | E15: 印尼进口indomie营多捞面杯面速食泡面干拌面盒桶装方便面火鸡面 | F15: =SUMIFS(数据源!AB:AB,数据源!B:B,C15,数据源!A:A,A14) | G15: =SUMIFS(数据源!E:E,数据源!B:B,C15,数据源!A:A,A14) | H15: =IFERROR(F15/SUMIF(数据源!A:A,A14,数据源!AB:AB),0)
B16: 3 | C16: 668566625747 | D16: 袋面主链接 | E16: 印尼营多捞面进口网红泡面袋装方便面速食食品拉面火鸡面拌面整箱 | F16: =SUMIFS(数据源!AB:AB,数据源!B:B,C16,数据源!A:A,A14) | G16: =SUMIFS(数据源!E:E,数据源!B:B,C16,数据源!A:A,A14) | H16: =IFERROR(F16/SUMIF(数据源!A:A,A14,数据源!AB:AB),0)
B17: 4 | C17: 929504658691 | D17: 日式袋面 | E17: 营多捞面日式鸡肉汤面原味辛辣味袋装泡面方便面速食宿舍夜宵食品 | F17: =SUMIFS(数据源!AB:AB,数据源!B:B,C17,数据源!A:A,A14) | G17: =SUMIFS(数据源!E:E,数据源!B:B,C17,数据源!A:A,A14) | H17: =IFERROR(F17/SUMIF(数据源!A:A,A14,数据源!AB:AB),0)
B18: 5 | C18: 648600900806 | D18: 30包 | E18: 进口营多捞面一整箱30包网红速食方便面宿舍速食泡面干拌面拉面 | F18: =SUMIFS(数据源!AB:AB,数据源!B:B,C18,数据源!A:A,A14) | G18: =SUMIFS(数据源!E:E,数据源!B:B,C18,数据源!A:A,A14) | H18: =IFERROR(F18/SUMIF(数据源!A:A,A14,数据源!AB:AB),0)
A19: 6.22-6.28 | B19: 1 | C19: 649361890551 | D19: 袋面次链接 | E19: 营多捞面印尼进口Indomie网红夜宵早餐方便面火鸡面泡面拌面 | F19: =SUMIFS(数据源!AB:AB,数据源!B:B,C19,数据源!A:A,A19) | G19: =SUMIFS(数据源!E:E,数据源!B:B,C19,数据源!A:A,A19) | H19: =IFERROR(F19/SUMIF(数据源!A:A,A19,数据源!AB:AB),0)
B20: 2 | C20: 668566625747 | D20: 袋面主链接 | E20: 印尼营多捞面进口网红泡面袋装方便面速食食品拉面火鸡面拌面整箱 | F20: =SUMIFS(数据源!AB:AB,数据源!B:B,C20,数据源!A:A,A19) | G20: =SUMIFS(数据源!E:E,数据源!B:B,C20,数据源!A:A,A19) | H20: =IFERROR(F20/SUMIF(数据源!A:A,A19,数据源!AB:AB),0)
B21: 3 | C21: 649735171438 | D21: 杯面主链接 | E21: 印尼进口indomie营多捞面杯面速食泡面干拌面盒桶装方便面火鸡面 | F21: =SUMIFS(数据源!AB:AB,数据源!B:B,C21,数据源!A:A,A19) | G21: =SUMIFS(数据源!E:E,数据源!B:B,C21,数据源!A:A,A19) | H21: =IFERROR(F21/SUMIF(数据源!A:A,A19,数据源!AB:AB),0)
B22: 4 | C22: 929504658691 | D22: 日韩袋面 | E22: 营多捞面日式鸡肉汤面原味辛辣味袋装泡面方便面速食宿舍夜宵食品 | F22: =SUMIFS(数据源!AB:AB,数据源!B:B,C22,数据源!A:A,A19) | G22: =SUMIFS(数据源!E:E,数据源!B:B,C22,数据源!A:A,A19) | H22: =IFERROR(F22/SUMIF(数据源!A:A,A19,数据源!AB:AB),0)
B23: 5 | C23: 648600900806 | D23: 30包 | E23: 进口营多捞面一整箱30包网红速食方便面宿舍速食泡面干拌面拉面 | F23: =SUMIFS(数据源!AB:AB,数据源!B:B,C23,数据源!A:A,A19) | G23: =SUMIFS(数据源!E:E,数据源!B:B,C23,数据源!A:A,A19) | H23: =IFERROR(F23/SUMIF(数据源!A:A,A19,数据源!AB:AB),0)
A24: 6.29-7.5 | B24: 1 | C24: 649361890551 | D24: 袋面次链接 | E24: 营多捞面印尼进口Indomie网红夜宵早餐方便面火鸡面泡面拌面 | F24: =SUMIFS(数据源!AB:AB,数据源!B:B,C24,数据源!A:A,A24) | G24: =SUMIFS(数据源!E:E,数据源!B:B,C24,数据源!A:A,A24) | H24: =IFERROR(F24/SUMIF(数据源!A:A,A24,数据源!AB:AB),0)
B25: 2 | C25: 649735171438 | D25: 杯面主链接 | E25: 印尼进口indomie营多捞面杯面速食泡面干拌面盒桶装方便面火鸡面 | F25: =SUMIFS(数据源!AB:AB,数据源!B:B,C25,数据源!A:A,A24) | G25: =SUMIFS(数据源!E:E,数据源!B:B,C25,数据源!A:A,A24) | H25: =IFERROR(F25/SUMIF(数据源!A:A,A24,数据源!AB:AB),0)
B26: 3 | C26: 668566625747 | D26: 袋面主链接 | E26: 印尼营多捞面进口网红泡面袋装方便面速食食品拉面火鸡面拌面整箱 | F26: =SUMIFS(数据源!AB:AB,数据源!B:B,C26,数据源!A:A,A24) | G26: =SUMIFS(数据源!E:E,数据源!B:B,C26,数据源!A:A,A24) | H26: =IFERROR(F26/SUMIF(数据源!A:A,A24,数据源!AB:AB),0)
B27: 4 | C27: 1057479227624 | D27: 巴东牛肉 | E27: 【新口味】印尼进口营多捞面巴东炖牛肉味泡面方便面宿舍速食宵夜 | F27: =SUMIFS(数据源!AB:AB,数据源!B:B,C27,数据源!A:A,A24) | G27: =SUMIFS(数据源!E:E,数据源!B:B,C27,数据源!A:A,A24) | H27: =IFERROR(F27/SUMIF(数据源!A:A,A24,数据源!AB:AB),0)
B28: 5 | C28: 1059563993918 | D28: 巴东牛肉 | E28: 营多进口新口味巴东炖牛肉味捞面印尼料理方便面泡面捞面夜宵速食 | F28: =SUMIFS(数据源!AB:AB,数据源!B:B,C28,数据源!A:A,A24) | G28: =SUMIFS(数据源!E:E,数据源!B:B,C28,数据源!A:A,A24) | H28: =IFERROR(F28/SUMIF(数据源!A:A,A24,数据源!AB:AB),0)
A29: 7.6-7.12 | B29: 1 | C29: 649361890551 | D29: 袋面次链接 | E29: 营多捞面印尼进口Indomie网红夜宵早餐方便面火鸡面泡面拌面 | F29: =SUMIFS(数据源!AB:AB,数据源!B:B,C29,数据源!A:A,A29) | G29: =SUMIFS(数据源!E:E,数据源!B:B,C29,数据源!A:A,A29) | H29: =IFERROR(F29/SUMIF(数据源!A:A,A29,数据源!AB:AB),0)
B30: 2 | C30: 649735171438 | D30: 杯面主链接 | E30: 印尼进口indomie营多捞面杯面速食泡面干拌面盒桶装方便面火鸡面 | F30: =SUMIFS(数据源!AB:AB,数据源!B:B,C30,数据源!A:A,A29) | G30: =SUMIFS(数据源!E:E,数据源!B:B,C30,数据源!A:A,A29) | H30: =IFERROR(F30/SUMIF(数据源!A:A,A29,数据源!AB:AB),0)
B31: 3 | C31: 668566625747 | D31: 袋面主链接 | E31: 印尼营多捞面进口网红泡面袋装方便面速食食品拉面火鸡面拌面整箱 | F31: =SUMIFS(数据源!AB:AB,数据源!B:B,C31,数据源!A:A,A29) | G31: =SUMIFS(数据源!E:E,数据源!B:B,C31,数据源!A:A,A29) | H31: =IFERROR(F31/SUMIF(数据源!A:A,A29,数据源!AB:AB),0)
B32: 4 | C32: 1057479227624 | D32: 巴东牛肉 | E32: 【新口味】印尼进口营多捞面巴东炖牛肉味泡面方便面宿舍速食宵夜 | F32: =SUMIFS(数据源!AB:AB,数据源!B:B,C32,数据源!A:A,A29) | G32: =SUMIFS(数据源!E:E,数据源!B:B,C32,数据源!A:A,A29) | H32: =IFERROR(F32/SUMIF(数据源!A:A,A29,数据源!AB:AB),0)
B33: 5 | C33: 648681860568 | D33: 杯面次链接 | E33: 营多捞面杯装方便面泡面速食干拌面原味整箱批发印尼进口桶装拌面 | F33: =SUMIFS(数据源!AB:AB,数据源!B:B,C33,数据源!A:A,A29) | G33: =SUMIFS(数据源!E:E,数据源!B:B,C33,数据源!A:A,A29) | H33: =IFERROR(F33/SUMIF(数据源!A:A,A29,数据源!AB:AB),0)
A34: 7.13-7.19 | B34: 1 | C34: 668566625747 | D34: 袋面主链接 | E34: 印尼营多捞面进口网红泡面袋装方便面速食食品拉面火鸡面拌面整箱 | F34: =SUMIFS(数据源!AB:AB,数据源!B:B,C34,数据源!A:A,A34) | G34: =SUMIFS(数据源!E:E,数据源!B:B,C34,数据源!A:A,A34) | H34: =IFERROR(F34/SUMIF(数据源!A:A,A34,数据源!AB:AB),0)
B35: 2 | C35: 649361890551 | D35: 袋面次链接 | E35: 营多捞面印尼进口Indomie网红夜宵早餐方便面火鸡面泡面拌面 | F35: =SUMIFS(数据源!AB:AB,数据源!B:B,C35,数据源!A:A,A34) | G35: =SUMIFS(数据源!E:E,数据源!B:B,C35,数据源!A:A,A34) | H35: =IFERROR(F35/SUMIF(数据源!A:A,A34,数据源!AB:AB),0)
B36: 3 | C36: 649735171438 | D36: 杯面主链接 | E36: 印尼进口indomie营多捞面杯面速食泡面干拌面盒桶装方便面火鸡面 | F36: =SUMIFS(数据源!AB:AB,数据源!B:B,C36,数据源!A:A,A34) | G36: =SUMIFS(数据源!E:E,数据源!B:B,C36,数据源!A:A,A34) | H36: =IFERROR(F36/SUMIF(数据源!A:A,A34,数据源!AB:AB),0)
B37: 4 | C37: 1057479227624 | D37: 巴东牛肉 | E37: 【新口味】印尼进口营多捞面巴东炖牛肉味泡面方便面宿舍速食宵夜 | F37: =SUMIFS(数据源!AB:AB,数据源!B:B,C37,数据源!A:A,A34) | G37: =SUMIFS(数据源!E:E,数据源!B:B,C37,数据源!A:A,A34) | H37: =IFERROR(F37/SUMIF(数据源!A:A,A34,数据源!AB:AB),0)
B38: 5 | C38: 648600900806 | D38: 30包 | E38: 进口营多捞面一整箱30包网红速食方便面宿舍速食泡面干拌面拉面 | F38: =SUMIFS(数据源!AB:AB,数据源!B:B,C38,数据源!A:A,A34) | G38: =SUMIFS(数据源!E:E,数据源!B:B,C38,数据源!A:A,A34) | H38: =IFERROR(F38/SUMIF(数据源!A:A,A34,数据源!AB:AB),0)
A39: 7.20-7.26 | B39: 1 | C39: 649361890551 | D39: 袋面次链接 | E39: 营多捞面印尼进口Indomie网红夜宵早餐方便面火鸡面泡面拌面 | F39: =SUMIFS(数据源!AB:AB,数据源!B:B,C39,数据源!A:A,A39) | G39: =SUMIFS(数据源!E:E,数据源!B:B,C39,数据源!A:A,A39) | H39: =IFERROR(F39/SUMIF(数据源!A:A,A39,数据源!AB:AB),0)
B40: 2 | C40: 668566625747 | D40: 袋面主链接 | E40: 印尼营多捞面进口网红泡面袋装方便面速食食品拉面火鸡面拌面整箱 | F40: =SUMIFS(数据源!AB:AB,数据源!B:B,C40,数据源!A:A,A39) | G40: =SUMIFS(数据源!E:E,数据源!B:B,C40,数据源!A:A,A39) | H40: =IFERROR(F40/SUMIF(数据源!A:A,A39,数据源!AB:AB),0)
...

Sheet 05-原味大大
A1: 原味大大包专题
A2: 按数据源当周定位=原味大包；已与修订标签对齐。改回15包/杯面次的ID不再计入。
A4: 汇总按周
A5: 周次 | B5: 成交金额 | C5: 推广前净利润 | D5: 推广花费 | E5: 其他费用 | F5: 推广后净利润 | G5: 推广侵蚀 | H5: 链接数
A6: 6.22-6.28 | B6: =SUMIFS(数据源!E:E,数据源!A:A,A6,数据源!C:C,"原味大包") | C6: =SUMIFS(数据源!X:X,数据源!A:A,A6,数据源!C:C,"原味大包") | D6: =SUMIFS(数据源!P:P,数据源!A:A,A6,数据源!C:C,"原味大包") | E6: =SUMIFS(数据源!W:W,数据源!A:A,A6,数据源!C:C,"原味大包") | F6: =SUMIFS(数据源!AB:AB,数据源!A:A,A6,数据源!C:C,"原味大包") | G6: =C6-F6 | H6: =COUNTIFS(数据源!A:A,A6,数据源!C:C,"原味大包")
A7: 6.29-7.5 | B7: =SUMIFS(数据源!E:E,数据源!A:A,A7,数据源!C:C,"原味大包") | C7: =SUMIFS(数据源!X:X,数据源!A:A,A7,数据源!C:C,"原味大包") | D7: =SUMIFS(数据源!P:P,数据源!A:A,A7,数据源!C:C,"原味大包") | E7: =SUMIFS(数据源!W:W,数据源!A:A,A7,数据源!C:C,"原味大包") | F7: =SUMIFS(数据源!AB:AB,数据源!A:A,A7,数据源!C:C,"原味大包") | G7: =C7-F7 | H7: =COUNTIFS(数据源!A:A,A7,数据源!C:C,"原味大包")
A8: 7.6-7.12 | B8: =SUMIFS(数据源!E:E,数据源!A:A,A8,数据源!C:C,"原味大包") | C8: =SUMIFS(数据源!X:X,数据源!A:A,A8,数据源!C:C,"原味大包") | D8: =SUMIFS(数据源!P:P,数据源!A:A,A8,数据源!C:C,"原味大包") | E8: =SUMIFS(数据源!W:W,数据源!A:A,A8,数据源!C:C,"原味大包") | F8: =SUMIFS(数据源!AB:AB,数据源!A:A,A8,数据源!C:C,"原味大包") | G8: =C8-F8 | H8: =COUNTIFS(数据源!A:A,A8,数据源!C:C,"原味大包")
A9: 7.13-7.19 | B9: =SUMIFS(数据源!E:E,数据源!A:A,A9,数据源!C:C,"原味大包") | C9: =SUMIFS(数据源!X:X,数据源!A:A,A9,数据源!C:C,"原味大包") | D9: =SUMIFS(数据源!P:P,数据源!A:A,A9,数据源!C:C,"原味大包") | E9: =SUMIFS(数据源!W:W,数据源!A:A,A9,数据源!C:C,"原味大包") | F9: =SUMIFS(数据源!AB:AB,数据源!A:A,A9,数据源!C:C,"原味大包") | G9: =C9-F9 | H9: =COUNTIFS(数据源!A:A,A9,数据源!C:C,"原味大包")
A10: 7.20-7.26 | B10: =SUMIFS(数据源!E:E,数据源!A:A,A10,数据源!C:C,"原味大包") | C10: =SUMIFS(数据源!X:X,数据源!A:A,A10,数据源!C:C,"原味大包") | D10: =SUMIFS(数据源!P:P,数据源!A:A,A10,数据源!C:C,"原味大包") | E10: =SUMIFS(数据源!W:W,数据源!A:A,A10,数据源!C:C,"原味大包") | F10: =SUMIFS(数据源!AB:AB,数据源!A:A,A10,数据源!C:C,"原味大包") | G10: =C10-F10 | H10: =COUNTIFS(数据源!A:A,A10,数据源!C:C,"原味大包")
A11: 7.27-8.2 | B11: =SUMIFS(数据源!E:E,数据源!A:A,A11,数据源!C:C,"原味大包") | C11: =SUMIFS(数据源!X:X,数据源!A:A,A11,数据源!C:C,"原味大包") | D11: =SUMIFS(数据源!P:P,数据源!A:A,A11,数据源!C:C,"原味大包") | E11: =SUMIFS(数据源!W:W,数据源!A:A,A11,数据源!C:C,"原味大包") | F11: =SUMIFS(数据源!AB:AB,数据源!A:A,A11,数据源!C:C,"原味大包") | G11: =C11-F11 | H11: =COUNTIFS(数据源!A:A,A11,数据源!C:C,"原味大包")
A14: 明细 ID × 周
A15: 周次 | B15: 商品ID | C15: 定位 | D15: 商品名称 | E15: 成交金额 | F15: 推广前 | G15: 推广花费 | H15: 推广后
A16: 6.22-6.28 | B16: 1058280415678 | C16: 原味大包 | D16: 印尼进口大大包营多原味捞面5包干拌面速食超大包方便面速食宵夜 | E16: =SUMIFS(数据源!E:E,数据源!A:A,A16,数据源!B:B,B16) | F16: =SUMIFS(数据源!X:X,数据源!A:A,A16,数据源!B:B,B16) | G16: =SUMIFS(数据源!P:P,数据源!A:A,A16,数据源!B:B,B16) | H16: =SUMIFS(数据源!AB:AB,数据源!A:A,A16,数据源!B:B,B16)
A17: 6.22-6.28 | B17: 1060999732877 | C17: 原味大包 | D17: indomie印尼进口营多原味大大包129g捞面方便面速食食品宵夜小吃 | E17: =SUMIFS(数据源!E:E,数据源!A:A,A17,数据源!B:B,B17) | F17: =SUMIFS(数据源!X:X,数据源!A:A,A17,数据源!B:B,B17) | G17: =SUMIFS(数据源!P:P,数据源!A:A,A17,数据源!B:B,B17) | H17: =SUMIFS(数据源!AB:AB,数据源!A:A,A17,数据源!B:B,B17)
A18: 6.29-7.5 | B18: 1058280415678 | C18: 原味大包 | D18: 印尼进口大大包营多原味捞面5包干拌面速食超大包方便面速食宵夜 | E18: =SUMIFS(数据源!E:E,数据源!A:A,A18,数据源!B:B,B18) | F18: =SUMIFS(数据源!X:X,数据源!A:A,A18,数据源!B:B,B18) | G18: =SUMIFS(数据源!P:P,数据源!A:A,A18,数据源!B:B,B18) | H18: =SUMIFS(数据源!AB:AB,数据源!A:A,A18,数据源!B:B,B18)
A19: 6.29-7.5 | B19: 1060999732877 | C19: 原味大包 | D19: indomie印尼进口营多原味大大包129g捞面方便面速食食品宵夜小吃 | E19: =SUMIFS(数据源!E:E,数据源!A:A,A19,数据源!B:B,B19) | F19: =SUMIFS(数据源!X:X,数据源!A:A,A19,数据源!B:B,B19) | G19: =SUMIFS(数据源!P:P,数据源!A:A,A19,数据源!B:B,B19) | H19: =SUMIFS(数据源!AB:AB,数据源!A:A,A19,数据源!B:B,B19)
A20: 7.6-7.12 | B20: 1058280415678 | C20: 原味大包 | D20: 印尼进口大大包营多原味捞面5包干拌面速食超大包方便面速食宵夜 | E20: =SUMIFS(数据源!E:E,数据源!A:A,A20,数据源!B:B,B20) | F20: =SUMIFS(数据源!X:X,数据源!A:A,A20,数据源!B:B,B20) | G20: =SUMIFS(数据源!P:P,数据源!A:A,A20,数据源!B:B,B20) | H20: =SUMIFS(数据源!AB:AB,数据源!A:A,A20,数据源!B:B,B20)
A21: 7.6-7.12 | B21: 1060999732877 | C21: 原味大包 | D21: 印尼进口大大包营多原味捞面5包干拌面速食超大包方便面速食宵夜 | E21: =SUMIFS(数据源!E:E,数据源!A:A,A21,数据源!B:B,B21) | F21: =SUMIFS(数据源!X:X,数据源!A:A,A21,数据源!B:B,B21) | G21: =SUMIFS(数据源!P:P,数据源!A:A,A21,数据源!B:B,B21) | H21: =SUMIFS(数据源!AB:AB,数据源!A:A,A21,数据源!B:B,B21)
A22: 7.13-7.19 | B22: 1059563993918 | C22: 原味大包 | D22: indomie印尼进口营多原味大大包129g捞面方便面速食食品宵夜小吃 | E22: =SUMIFS(数据源!E:E,数据源!A:A,A22,数据源!B:B,B22) | F22: =SUMIFS(数据源!X:X,数据源!A:A,A22,数据源!B:B,B22) | G22: =SUMIFS(数据源!P:P,数据源!A:A,A22,数据源!B:B,B22) | H22: =SUMIFS(数据源!AB:AB,数据源!A:A,A22,数据源!B:B,B22)
A23: 7.13-7.19 | B23: 1060999732877 | C23: 原味大包 | D23: indomie印尼进口营多原味大大包129g捞面方便面速食食品宵夜小吃 | E23: =SUMIFS(数据源!E:E,数据源!A:A,A23,数据源!B:B,B23) | F23: =SUMIFS(数据源!X:X,数据源!A:A,A23,数据源!B:B,B23) | G23: =SUMIFS(数据源!P:P,数据源!A:A,A23,数据源!B:B,B23) | H23: =SUMIFS(数据源!AB:AB,数据源!A:A,A23,数据源!B:B,B23)
A24: 7.20-7.26 | B24: 1013887677295 | C24: 原味大包 | D24: indomie印尼进口营多原味大大包129g捞面方便面速食食品宵夜小吃 | E24: =SUMIFS(数据源!E:E,数据源!A:A,A24,数据源!B:B,B24) | F24: =SUMIFS(数据源!X:X,数据源!A:A,A24,数据源!B:B,B24) | G24: =SUMIFS(数据源!P:P,数据源!A:A,A24,数据源!B:B,B24) | H24: =SUMIFS(数据源!AB:AB,数据源!A:A,A24,数据源!B:B,B24)
A25: 7.20-7.26 | B25: 1060999732877 | C25: 原味大包 | D25: indomie印尼进口营多原味大大包129g捞面方便面速食食品宵夜小吃 | E25: =SUMIFS(数据源!E:E,数据源!A:A,A25,数据源!B:B,B25) | F25: =SUMIFS(数据源!X:X,数据源!A:A,A25,数据源!B:B,B25) | G25: =SUMIFS(数据源!P:P,数据源!A:A,A25,数据源!B:B,B25) | H25: =SUMIFS(数据源!AB:AB,数据源!A:A,A25,数据源!B:B,B25)
A26: 7.27-8.2 | B26: 1013887677295 | C26: 原味大包 | D26: indomie印尼进口营多原味大大包129g捞面方便面速食食品宵夜小吃 | E26: =SUMIFS(数据源!E:E,数据源!A:A,A26,数据源!B:B,B26) | F26: =SUMIFS(数据源!X:X,数据源!A:A,A26,数据源!B:B,B26) | G26: =SUMIFS(数据源!P:P,数据源!A:A,A26,数据源!B:B,B26) | H26: =SUMIFS(数据源!AB:AB,数据源!A:A,A26,数据源!B:B,B26)
A27: 7.27-8.2 | B27: 1058280415678 | C27: 原味大包 | D27: 印尼进口大大包营多原味捞面5包干拌面速食超大包方便面速食宵夜 | E27: =SUMIFS(数据源!E:E,数据源!A:A,A27,数据源!B:B,B27) | F27: =SUMIFS(数据源!X:X,数据源!A:A,A27,数据源!B:B,B27) | G27: =SUMIFS(数据源!P:P,数据源!A:A,A27,数据源!B:B,B27) | H27: =SUMIFS(数据源!AB:AB,数据源!A:A,A27,数据源!B:B,B27)
A28: 7.27-8.2 | B28: 1060999732877 | C28: 原味大包 | D28: indomie印尼进口营多原味大大包129g捞面方便面速食食品宵夜小吃 | E28: =SUMIFS(数据源!E:E,数据源!A:A,A28,数据源!B:B,B28) | F28: =SUMIFS(数据源!X:X,数据源!A:A,A28,数据源!B:B,B28) | G28: =SUMIFS(数据源!P:P,数据源!A:A,A28,数据源!B:B,B28) | H28: =SUMIFS(数据源!AB:AB,数据源!A:A,A28,数据源!B:B,B28)

Sheet 06-全量ID每周净利润
A1: 全量商品ID · 每周推广后净利润
A2: 定位/名称=成交加权主标签｜各周与变化列为SUMIFS公式｜请开启Excel自动计算
A4: 商品ID | B4: 定位 | C4: 商品名称 | D4: 5.11-5.17 | E4: 5.25-5.31 | F4: 6.15-6.21 | G4: 6.22-6.28 | H4: 6.29-7.5 | I4: 7.6-7.12 | J4: 7.13-7.19 | K4: 7.20-7.26 | L4: 7.27-8.2 | M4: 7.6→7.13变化 | N4: 7.13→7.20变化
A5: 649361890551 | B5: 袋面次链接 | C5: 营多捞面印尼进口Indomie网红夜宵早餐方便面火鸡面泡面拌面 | D5: =IFERROR(SUMIFS(数据源!AB:AB,数据源!B:B,$A5,数据源!A:A,"5.11-5.17"),0) | E5: =IFERROR(SUMIFS(数据源!AB:AB,数据源!B:B,$A5,数据源!A:A,"5.25-5.31"),0) | F5: =IFERROR(SUMIFS(数据源!AB:AB,数据源!B:B,$A5,数据源!A:A,"6.15-6.21"),0) | G5: =IFERROR(SUMIFS(数据源!AB:AB,数据源!B:B,$A5,数据源!A:A,"6.22-6.28"),0) | H5: =IFERROR(SUMIFS(数据源!AB:AB,数据源!B:B,$A5,数据源!A:A,"6.29-7.5"),0) | I5: =IFERROR(SUMIFS(数据源!AB:AB,数据源!B:B,$A5,数据源!A:A,"7.6-7.12"),0) | J5: =IFERROR(SUMIFS(数据源!AB:AB,数据源!B:B,$A5,数据源!A:A,"7.13-7.19"),0) | K5: =IFERROR(SUMIFS(数据源!AB:AB,数据源!B:B,$A5,数据源!A:A,"7.20-7.26"),0) | L5: =IFERROR(SUMIFS(数据源!AB:AB,数据源!B:B,$A5,数据源!A:A,"7.27-8.2"),0) | M5: =J5-I5 | N5: =K5-J5
A6: 668566625747 | B6: 袋面主链接 | C6: 印尼营多捞面进口网红泡面袋装方便面速食食品拉面火鸡面拌面整箱 | D6: =IFERROR(SUMIFS(数据源!AB:AB,数据源!B:B,$A6,数据源!A:A,"5.11-5.17"),0) | E6: =IFERROR(SUMIFS(数据源!AB:AB,数据源!B:B,$A6,数据源!A:A,"5.25-5.31"),0) | F6: =IFERROR(SUMIFS(数据源!AB:AB,数据源!B:B,$A6,数据源!A:A,"6.15-6.21"),0) | G6: =IFERROR(SUMIFS(数据源!AB:AB,数据源!B:B,$A6,数据源!A:A,"6.22-6.28"),0) | H6: =IFERROR(SUMIFS(数据源!AB:AB,数据源!B:B,$A6,数据源!A:A,"6.29-7.5"),0) | I6: =IFERROR(SUMIFS(数据源!AB:AB,数据源!B:B,$A6,数据源!A:A,"7.6-7.12"),0) | J6: =IFERROR(SUMIFS(数据源!AB:AB,数据源!B:B,$A6,数据源!A:A,"7.13-7.19"),0) | K6: =IFERROR(SUMIFS(数据源!AB:AB,数据源!B:B,$A6,数据源!A:A,"7.20-7.26"),0) | L6: =IFERROR(SUMIFS(数据源!AB:AB,数据源!B:B,$A6,数据源!A:A,"7.27-8.2"),0) | M6: =J6-I6 | N6: =K6-J6
A7: 649735171438 | B7: 杯面主链接 | C7: 印尼进口indomie营多捞面杯面速食泡面干拌面盒桶装方便面火鸡面 | D7: =IFERROR(SUMIFS(数据源!AB:AB,数据源!B:B,$A7,数据源!A:A,"5.11-5.17"),0) | E7: =IFERROR(SUMIFS(数据源!AB:AB,数据源!B:B,$A7,数据源!A:A,"5.25-5.31"),0) | F7: =IFERROR(SUMIFS(数据源!AB:AB,数据源!B:B,$A7,数据源!A:A,"6.15-6.21"),0) | G7: =IFERROR(SUMIFS(数据源!AB:AB,数据源!B:B,$A7,数据源!A:A,"6.22-6.28"),0) | H7: =IFERROR(SUMIFS(数据源!AB:AB,数据源!B:B,$A7,数据源!A:A,"6.29-7.5"),0) | I7: =IFERROR(SUMIFS(数据源!AB:AB,数据源!B:B,$A7,数据源!A:A,"7.6-7.12"),0) | J7: =IFERROR(SUMIFS(数据源!AB:AB,数据源!B:B,$A7,数据源!A:A,"7.13-7.19"),0) | K7: =IFERROR(SUMIFS(数据源!AB:AB,数据源!B:B,$A7,数据源!A:A,"7.20-7.26"),0) | L7: =IFERROR(SUMIFS(数据源!AB:AB,数据源!B:B,$A7,数据源!A:A,"7.27-8.2"),0) | M7: =J7-I7 | N7: =K7-J7
A8: 1057479227624 | B8: 巴东牛肉 | C8: 【新口味】印尼进口营多捞面巴东炖牛肉味泡面方便面宿舍速食宵夜 | D8: =IFERROR(SUMIFS(数据源!AB:AB,数据源!B:B,$A8,数据源!A:A,"5.11-5.17"),0) | E8: =IFERROR(SUMIFS(数据源!AB:AB,数据源!B:B,$A8,数据源!A:A,"5.25-5.31"),0) | F8: =IFERROR(SUMIFS(数据源!AB:AB,数据源!B:B,$A8,数据源!A:A,"6.15-6.21"),0) | G8: =IFERROR(SUMIFS(数据源!AB:AB,数据源!B:B,$A8,数据源!A:A,"6.22-6.28"),0) | H8: =IFERROR(SUMIFS(数据源!AB:AB,数据源!B:B,$A8,数据源!A:A,"6.29-7.5"),0) | I8: =IFERROR(SUMIFS(数据源!AB:AB,数据源!B:B,$A8,数据源!A:A,"7.6-7.12"),0) | J8: =IFERROR(SUMIFS(数据源!AB:AB,数据源!B:B,$A8,数据源!A:A,"7.13-7.19"),0) | K8: =IFERROR(SUMIFS(数据源!AB:AB,数据源!B:B,$A8,数据源!A:A,"7.20-7.26"),0) | L8: =IFERROR(SUMIFS(数据源!AB:AB,数据源!B:B,$A8,数据源!A:A,"7.27-8.2"),0) | M8: =J8-I8 | N8: =K8-J8
A9: 648600900806 | B9: 30包 | C9: 进口营多捞面一整箱30包网红速食方便面宿舍速食泡面干拌面拉面 | D9: =IFERROR(SUMIFS(数据源!AB:AB,数据源!B:B,$A9,数据源!A:A,"5.11-5.17"),0) | E9: =IFERROR(SUMIFS(数据源!AB:AB,数据源!B:B,$A9,数据源!A:A,"5.25-5.31"),0) | F9: =IFERROR(SUMIFS(数据源!AB:AB,数据源!B:B,$A9,数据源!A:A,"6.15-6.21"),0) | G9: =IFERROR(SUMIFS(数据源!AB:AB,数据源!B:B,$A9,数据源!A:A,"6.22-6.28"),0) | H9: =IFERROR(SUMIFS(数据源!AB:AB,数据源!B:B,$A9,数据源!A:A,"6.29-7.5"),0) | I9: =IFERROR(SUMIFS(数据源!AB:AB,数据源!B:B,$A9,数据源!A:A,"7.6-7.12"),0) | J9: =IFERROR(SUMIFS(数据源!AB:AB,数据源!B:B,$A9,数据源!A:A,"7.13-7.19"),0) | K9: =IFERROR(SUMIFS(数据源!AB:AB,数据源!B:B,$A9,数据源!A:A,"7.20-7.26"),0) | L9: =IFERROR(SUMIFS(数据源!AB:AB,数据源!B:B,$A9,数据源!A:A,"7.27-8.2"),0) | M9: =J9-I9 | N9: =K9-J9
A10: 1013887677295 | B10: 混搭5杯 | C10: 进口营多原味杯面日式杯面韩式杯面泡面方便面汤面宿舍速食夜宵 | D10: =IFERROR(SUMIFS(数据源!AB:AB,数据源!B:B,$A10,数据源!A:A,"5.11-5.17"),0) | E10: =IFERROR(SUMIFS(数据源!AB:AB,数据源!B:B,$A10,数据源!A:A,"5.25-5.31"),0) | F10: =IFERROR(SUMIFS(数据源!AB:AB,数据源!B:B,$A10,数据源!A:A,"6.15-6.21"),0) | G10: =IFERROR(SUMIFS(数据源!AB:AB,数据源!B:B,$A10,数据源!A:A,"6.22-6.28"),0) | H10: =IFERROR(SUMIFS(数据源!AB:AB,数据源!B:B,$A10,数据源!A:A,"6.29-7.5"),0) | I10: =IFERROR(SUMIFS(数据源!AB:AB,数据源!B:B,$A10,数据源!A:A,"7.6-7.12"),0) | J10: =IFERROR(SUMIFS(数据源!AB:AB,数据源!B:B,$A10,数据源!A:A,"7.13-7.19"),0) | K10: =IFERROR(SUMIFS(数据源!AB:AB,数据源!B:B,$A10,数据源!A:A,"7.20-7.26"),0) | L10: =IFERROR(SUMIFS(数据源!AB:AB,数据源!B:B,$A10,数据源!A:A,"7.27-8.2"),0) | M10: =J10-I10 | N10: =K10-J10
A11: 929504658691 | B11: 日式袋面 | C11: 营多捞面日式鸡肉汤面原味辛辣味袋装泡面方便面速食宿舍夜宵食品 | D11: =IFERROR(SUMIFS(数据源!AB:AB,数据源!B:B,$A11,数据源!A:A,"5.11-5.17"),0) | E11: =IFERROR(SUMIFS(数据源!AB:AB,数据源!B:B,$A11,数据源!A:A,"5.25-5.31"),0) | F11: =IFERROR(SUMIFS(数据源!AB:AB,数据源!B:B,$A11,数据源!A:A,"6.15-6.21"),0) | G11: =IFERROR(SUMIFS(数据源!AB:AB,数据源!B:B,$A11,数据源!A:A,"6.22-6.28"),0) | H11: =IFERROR(SUMIFS(数据源!AB:AB,数据源!B:B,$A11,数据源!A:A,"6.29-7.5"),0) | I11: =IFERROR(SUMIFS(数据源!AB:AB,数据源!B:B,$A11,数据源!A:A,"7.6-7.12"),0) | J11: =IFERROR(SUMIFS(数据源!AB:AB,数据源!B:B,$A11,数据源!A:A,"7.13-7.19"),0) | K11: =IFERROR(SUMIFS(数据源!AB:AB,数据源!B:B,$A11,数据源!A:A,"7.20-7.26"),0) | L11: =IFERROR(SUMIFS(数据源!AB:AB,数据源!B:B,$A11,数据源!A:A,"7.27-8.2"),0) | M11: =J11-I11 | N11: =K11-J11
A12: 649014937782 | B12: 24包 | C12: 印尼营多捞面干拌面一整箱24袋装批发泡面宿舍速食方便面火鸡面 | D12: =IFERROR(SUMIFS(数据源!AB:AB,数据源!B:B,$A12,数据源!A:A,"5.11-5.17"),0) | E12: =IFERROR(SUMIFS(数据源!AB:AB,数据源!B:B,$A12,数据源!A:A,"5.25-5.31"),0) | F12: =IFERROR(SUMIFS(数据源!AB:AB,数据源!B:B,$A12,数据源!A:A,"6.15-6.21"),0) | G12: =IFERROR(SUMIFS(数据源!AB:AB,数据源!B:B,$A12,数据源!A:A,"6.22-6.28"),0) | H12: =IFERROR(SUMIFS(数据源!AB:AB,数据源!B:B,$A12,数据源!A:A,"6.29-7.5"),0) | I12: =IFERROR(SUMIFS(数据源!AB:AB,数据源!B:B,$A12,数据源!A:A,"7.6-7.12"),0) | J12: =IFERROR(SUMIFS(数据源!AB:AB,数据源!B:B,$A12,数据源!A:A,"7.13-7.19"),0) | K12: =IFERROR(SUMIFS(数据源!AB:AB,数据源!B:B,$A12,数据源!A:A,"7.20-7.26"),0) | L12: =IFERROR(SUMIFS(数据源!AB:AB,数据源!B:B,$A12,数据源!A:A,"7.27-8.2"),0) | M12: =J12-I12 | N12: =K12-J12
A13: 648681860568 | B13: 杯面次链接 | C13: 营多捞面杯装方便面泡面速食干拌面原味整箱批发印尼进口桶装拌面 | D13: =IFERROR(SUMIFS(数据源!AB:AB,数据源!B:B,$A13,数据源!A:A,"5.11-5.17"),0) | E13: =IFERROR(SUMIFS(数据源!AB:AB,数据源!B:B,$A13,数据源!A:A,"5.25-5.31"),0) | F13: =IFERROR(SUMIFS(数据源!AB:AB,数据源!B:B,$A13,数据源!A:A,"6.15-6.21"),0) | G13: =IFERROR(SUMIFS(数据源!AB:AB,数据源!B:B,$A13,数据源!A:A,"6.22-6.28"),0) | H13: =IFERROR(SUMIFS(数据源!AB:AB,数据源!B:B,$A13,数据源!A:A,"6.29-7.5"),0) | I13: =IFERROR(SUMIFS(数据源!AB:AB,数据源!B:B,$A13,数据源!A:A,"7.6-7.12"),0) | J13: =IFERROR(SUMIFS(数据源!AB:AB,数据源!B:B,$A13,数据源!A:A,"7.13-7.19"),0) | K13: =IFERROR(SUMIFS(数据源!AB:AB,数据源!B:B,$A13,数据源!A:A,"7.20-7.26"),0) | L13: =IFERROR(SUMIFS(数据源!AB:AB,数据源!B:B,$A13,数据源!A:A,"7.27-8.2"),0) | M13: =J13-I13 | N13: =K13-J13
A14: 648598580775 | B14: 15包 | C14: 进口营多捞面15包Indomie方便面干拌面夜宵方便速食五连包85g*5 | D14: =IFERROR(SUMIFS(数据源!AB:AB,数据源!B:B,$A14,数据源!A:A,"5.11-5.17"),0) | E14: =IFERROR(SUMIFS(数据源!AB:AB,数据源!B:B,$A14,数据源!A:A,"5.25-5.31"),0) | F14: =IFERROR(SUMIFS(数据源!AB:AB,数据源!B:B,$A14,数据源!A:A,"6.15-6.21"),0) | G14: =IFERROR(SUMIFS(数据源!AB:AB,数据源!B:B,$A14,数据源!A:A,"6.22-6.28"),0) | H14: =IFERROR(SUMIFS(数据源!AB:AB,数据源!B:B,$A14,数据源!A:A,"6.29-7.5"),0) | I14: =IFERROR(SUMIFS(数据源!AB:AB,数据源!B:B,$A14,数据源!A:A,"7.6-7.12"),0) | J14: =IFERROR(SUMIFS(数据源!AB:AB,数据源!B:B,$A14,数据源!A:A,"7.13-7.19"),0) | K14: =IFERROR(SUMIFS(数据源!AB:AB,数据源!B:B,$A14,数据源!A:A,"7.20-7.26"),0) | L14: =IFERROR(SUMIFS(数据源!AB:AB,数据源!B:B,$A14,数据源!A:A,"7.27-8.2"),0) | M14: =J14-I14 | N14: =K14-J14
A15: 1059563993918 | B15: 巴东牛肉 | C15: 营多进口新口味巴东炖牛肉味捞面印尼料理方便面泡面捞面夜宵速食 | D15: =IFERROR(SUMIFS(数据源!AB:AB,数据源!B:B,$A15,数据源!A:A,"5.11-5.17"),0) | E15: =IFERROR(SUMIFS(数据源!AB:AB,数据源!B:B,$A15,数据源!A:A,"5.25-5.31"),0) | F15: =IFERROR(SUMIFS(数据源!AB:AB,数据源!B:B,$A15,数据源!A:A,"6.15-6.21"),0) | G15: =IFERROR(SUMIFS(数据源!AB:AB,数据源!B:B,$A15,数据源!A:A,"6.22-6.28"),0) | H15: =IFERROR(SUMIFS(数据源!AB:AB,数据源!B:B,$A15,数据源!A:A,"6.29-7.5"),0) | I15: =IFERROR(SUMIFS(数据源!AB:AB,数据源!B:B,$A15,数据源!A:A,"7.6-7.12"),0) | J15: =IFERROR(SUMIFS(数据源!AB:AB,数据源!B:B,$A15,数据源!A:A,"7.13-7.19"),0) | K15: =IFERROR(SUMIFS(数据源!AB:AB,数据源!B:B,$A15,数据源!A:A,"7.20-7.26"),0) | L15: =IFERROR(SUMIFS(数据源!AB:AB,数据源!B:B,$A15,数据源!A:A,"7.27-8.2"),0) | M15: =J15-I15 | N15: =K15-J15
A16: 969423151512 | B16: 日韩混搭 | C16: 营多捞面甜辣炸鸡火鸡面辣蘑菇泡面方便面速食干拌面宿舍宵夜旅行 | D16: =IFERROR(SUMIFS(数据源!AB:AB,数据源!B:B,$A16,数据源!A:A,"5.11-5.17"),0) | E16: =IFERROR(SUMIFS(数据源!AB:AB,数据源!B:B,$A16,数据源!A:A,"5.25-5.31"),0) | F16: =IFERROR(SUMIFS(数据源!AB:AB,数据源!B:B,$A16,数据源!A:A,"6.15-6.21"),0) | G16: =IFERROR(SUMIFS(数据源!AB:AB,数据源!B:B,$A16,数据源!A:A,"6.22-6.28"),0) | H16: =IFERROR(SUMIFS(数据源!AB:AB,数据源!B:B,$A16,数据源!A:A,"6.29-7.5"),0) | I16: =IFERROR(SUMIFS(数据源!AB:AB,数据源!B:B,$A16,数据源!A:A,"7.6-7.12"),0) | J16: =IFERROR(SUMIFS(数据源!AB:AB,数据源!B:B,$A16,数据源!A:A,"7.13-7.19"),0) | K16: =IFERROR(SUMIFS(数据源!AB:AB,数据源!B:B,$A16,数据源!A:A,"7.20-7.26"),0) | L16: =IFERROR(SUMIFS(数据源!AB:AB,数据源!B:B,$A16,数据源!A:A,"7.27-8.2"),0) | M16: =J16-I16 | N16: =K16-J16
... A56: 649369494424 | B56: 24包经典/牛系列 | C56: 营多捞面干拌面一整箱24袋装批发泡面混搭宿舍速食方便面火鸡面 | D56: =IFERROR(SUMIFS(数据源!AB:AB,数据源!B:B,$A56,数据源!A:A,"5.11-5.17"),0) | E56: =IFERROR(SUMIFS(数据源!AB:AB,数据源!B:B,$A56,数据源!A:A,"5.25-5.31"),0) | F56: =IFERROR(SUMIFS(数据源!AB:AB,数据源!B:B,$A56,数据源!A:A,"6.15-6.21"),0) | G56: =IFERROR(SUMIFS(数据源!AB:AB,数据源!B:B,$A56,数据源!A:A,"6.22-6.28"),0) | H56: =IFERROR(SUMIFS(数据源!AB:AB,数据源!B:B,$A56,数据源!A:A,"6.29-7.5"),0) | I56: =IFERROR(SUMIFS(数据源!AB:AB,数据源!B:B,$A56,数据源!A:A,"7.6-7.12"),0) | J56: =IFERROR(SUMIFS(数据源!AB:AB,数据源!B:B,$A56,数据源!A:A,"7.13-7.19"),0) | K56: =IFERROR(SUMIFS(数据源!AB:AB,数据源!B:B,$A56,数据源!A:A,"7.20-7.26"),0) | L56: =IFERROR(SUMIFS(数据源!AB:AB,数据源!B:B,$A56,数据源!A:A,"7.27-8.2"),0) | M56: =J56-I56 | N56: =K56-J56

Sheet 数据源
A1: 数据源 · ID周损益明细（计算列为公式；其他费用=周报×件数占比）
A2: 周次 | B2: 商品ID | C2: 定位 | D2: 商品名称 | E2: 成交金额 | F2: 去税金额 | G2: 成交件数 | H2: 件数占比 | I2: 件单价 | J2: 万相台花费 | K2: 万相台成交 | L2: 万相台ROI | M2: 品销宝花费 | N2: 品销宝成交 | O2: 品销宝ROI | P2: 推广总花费 | Q2: 推广总成交 | R2: 推广总ROI | S2: 推广费占比 | T2: 推广总费率 | U2: 日销成交 | V2: 日销成交占比 | W2: 其他费用 | X2: 净利润(推广前) | Y2: 净利率(推广前) | Z2: 净利润(万相台) | AA2: 净利率(万相台) | AB2: 净利润(推广后) | AC2: 净利率(推广后)
A3: 5.11-5.17 | B3: 668566625747 | C3: 袋面主链接 | D3: 印尼营多捞面进口网红泡面袋装方便面速食食品拉面火鸡面拌面整箱 | E3: 31185.63 | F3: =IFERROR(E3/1.13,0) | G3: 1220 | H3: =IFERROR(G3/SUMIF($A:$A,A3,$G:$G),0) | I3: =IFERROR(E3/G3,0) | J3: 5079.8725 | K3: 23465.2 | L3: =IFERROR(K3/J3,0) | M3: 554.76399 | N3: 1481.5078 | O3: =IFERROR(N3/M3,0) | P3: =J3+M3 | Q3: =K3+N3 | R3: =IFERROR(Q3/P3,0) | S3: =IFERROR(P3/SUMIF($A:$A,A3,$P:$P),0) | T3: =IFERROR(P3/E3,0) | U3: =E3-Q3 | V3: =IFERROR(U3/E3,0) | W3: =IFERROR(VLOOKUP(A3,周报其他费用!$A:$B,2,FALSE)*H3,0) | X3: 4205.259 | Y3: =IFERROR(X3/F3,0) | Z3: =X3-J3/1.06 | AA3: =IFERROR(Z3/F3,0) | AB3: =X3-(P3+W3)/1.06 | AC3: =IFERROR(AB3/F3,0)
A4: 5.11-5.17 | B4: 649361890551 | C4: 袋面次链接 | D4: 营多捞面印尼进口Indomie网红夜宵早餐方便面火鸡面泡面拌面 | E4: 28857.24 | F4: =IFERROR(E4/1.13,0) | G4: 1529 | H4: =IFERROR(G4/SUMIF($A:$A,A4,$G:$G),0) | I4: =IFERROR(E4/G4,0) | J4: 5008.2401 | K4: 25554.89 | L4: =IFERROR(K4/J4,0) | M4: 695.27389 | N4: 1856.7421 | O4: =IFERROR(N4/M4,0) | P4: =J4+M4 | Q4: =K4+N4 | R4: =IFERROR(Q4/P4,0) | S4: =IFERROR(P4/SUMIF($A:$A,A4,$P:$P),0) | T4: =IFERROR(P4/E4,0) | U4: =E4-Q4 | V4: =IFERROR(U4/E4,0) | W4: =IFERROR(VLOOKUP(A4,周报其他费用!$A:$B,2,FALSE)*H4,0) | X4: 2532.806 | Y4: =IFERROR(X4/F4,0) | Z4: =X4-J4/1.06 | AA4: =IFERROR(Z4/F4,0) | AB4: =X4-(P4+W4)/1.06 | AC4: =IFERROR(AB4/F4,0)
A5: 5.11-5.17 | B5: 649735171438 | C5: 杯面主链接 | D5: 印尼进口indomie营多捞面杯面速食泡面干拌面盒桶装方便面火鸡面 | E5: 20499.86 | F5: =IFERROR(E5/1.13,0) | G5: 803 | H5: =IFERROR(G5/SUMIF($A:$A,A5,$G:$G),0) | I5: =IFERROR(E5/G5,0) | J5: 3146.9679 | K5: 13817.925 | L5: =IFERROR(K5/J5,0) | M5: 365.14384 | N5: 975.12357 | O5: =IFERROR(N5/M5,0) | P5: =J5+M5 | Q5: =K5+N5 | R5: =IFERROR(Q5/P5,0) | S5: =IFERROR(P5/SUMIF($A:$A,A5,$P:$P),0) | T5: =IFERROR(P5/E5,0) | U5: =E5-Q5 | V5: =IFERROR(U5/E5,0) | W5: =IFERROR(VLOOKUP(A5,周报其他费用!$A:$B,2,FALSE)*H5,0) | X5: 2323.975 | Y5: =IFERROR(X5/F5,0) | Z5: =X5-J5/1.06 | AA5: =IFERROR(Z5/F5,0) | AB5: =X5-(P5+W5)/1.06 | AC5: =IFERROR(AB5/F5,0)
A6: 5.11-5.17 | B6: 648600900806 | C6: 30包 | D6: 进口营多捞面一整箱30包网红速食方便面宿舍速食泡面干拌面拉面 | E6: 10599.77 | F6: =IFERROR(E6/1.13,0) | G6: 154 | H6: =IFERROR(G6/SUMIF($A:$A,A6,$G:$G),0) | I6: =IFERROR(E6/G6,0) | J6: 2033.3414 | K6: 10437.762 | L6: =IFERROR(K6/J6,0) | M6: 70.027586 | N6: 187.01 | O6: =IFERROR(N6/M6,0) | P6: =J6+M6 | Q6: =K6+N6 | R6: =IFERROR(Q6/P6,0) | S6: =IFERROR(P6/SUMIF($A:$A,A6,$P:$P),0) | T6: =IFERROR(P6/E6,0) | U6: =E6-Q6 | V6: =IFERROR(U6/E6,0) | W6: =IFERROR(VLOOKUP(A6,周报其他费用!$A:$B,2,FALSE)*H6,0) | X6: 2022.481 | Y6: =IFERROR(X6/F6,0) | Z6: =X6-J6/1.06 | AA6: =IFERROR(Z6/F6,0) | AB6: =X6-(P6+W6)/1.06 | AC6: =IFERROR(AB6/F6,0)
A7: 5.11-5.17 | B7: 649014937782 | C7: 24包 | D7: 印尼营多捞面干拌面一整箱24袋装批发泡面宿舍速食方便面火鸡面 | E7: 7533.85 | F7: =IFERROR(E7/1.13,0) | G7: 133 | H7: =IFERROR(G7/SUMIF($A:$A,A7,$G:$G),0) | I7: =IFERROR(E7/G7,0) | J7: 1581.3889 | K7: 7074.8484 | L7: =IFERROR(K7/J7,0) | M7: 60.47837 | N7: 161.50864 | O7: =IFERROR(N7/M7,0) | P7: =J7+M7 | Q7: =K7+N7 | R7: =IFERROR(Q7/P7,0) | S7: =IFERROR(P7/SUMIF($A:$A,A7,$P:$P),0) | T7: =IFERROR(P7/E7,0) | U7: =E7-Q7 | V7: =IFERROR(U7/E7,0) | W7: =IFERROR(VLOOKUP(A7,周报其他费用!$A:$B,2,FALSE)*H7,0) | X7: 1486.131 | Y7: =IFERROR(X7/F7,0) | Z7: =X7-J7/1.06 | AA7: =IFERROR(Z7/F7,0) | AB7: =X7-(P7+W7)/1.06 | AC7: =IFERROR(AB7/F7,0)
A8: 5.11-5.17 | B8: 648598580775 | C8: 15包 | D8: 进口营多捞面15包Indomie方便面干拌面夜宵方便速食五连包85g*5 | E8: 6101.9 | F8: =IFERROR(E8/1.13,0) | G8: 165 | H8: =IFERROR(G8/SUMIF($A:$A,A8,$G:$G),0) | I8: =IFERROR(E8/G8,0) | J8: 1044.735 | K8: 4769.4269 | L8: =IFERROR(K8/J8,0) | M8: 75.029557 | N8: 200.36786 | O8: =IFERROR(N8/M8,0) | P8: =J8+M8 | Q8: =K8+N8 | R8: =IFERROR(Q8/P8,0) | S8: =IFERROR(P8/SUMIF($A:$A,A8,$P:$P),0) | T8: =IFERROR(P8/E8,0) | U8: =E8-Q8 | V8: =IFERROR(U8/E8,0) | W8: =IFERROR(VLOOKUP(A8,周报其他费用!$A:$B,2,FALSE)*H8,0) | X8: 1116.138 | Y8: =IFERROR(X8/F8,0) | Z8: =X8-J8/1.06 | AA8: =IFERROR(Z8/F8,0) | AB8: =X8-(P8+W8)/1.06 | AC8: =IFERROR(AB8/F8,0)
A9: 5.11-5.17 | B9: 766165464414 | C9: 12包 | D9: 营多印尼进口营多捞面方便面火鸡面干拌面12包宿舍速食泡面夜宵 | E9: 4330.8 | F9: =IFERROR(E9/1.13,0) | G9: 146 | H9: =IFERROR(G9/SUMIF($A:$A,A9,$G:$G),0) | I9: =IFERROR(E9/G9,0) | J9: 459.94235 | K9: 2383.2228 | L9: =IFERROR(K9/J9,0) | M9: 66.38979 | N9: 177.29519 | O9: =IFERROR(N9/M9,0) | P9: =J9+M9 | Q9: =K9+N9 | R9: =IFERROR(Q9/P9,0) | S9: =IFERROR(P9/SUMIF($A:$A,A9,$P:$P),0) | T9: =IFERROR(P9/E9,0) | U9: =E9-Q9 | V9: =IFERROR(U9/E9,0) | W9: =IFERROR(VLOOKUP(A9,周报其他费用!$A:$B,2,FALSE)*H9,0) | X9: 647.268 | Y9: =IFERROR(X9/F9,0) | Z9: =X9-J9/1.06 | AA9: =IFERROR(Z9/F9,0) | AB9: =X9-(P9+W9)/1.06 | AC9: =IFERROR(AB9/F9,0)
A10: 5.11-5.17 | B10: 735014804839 | C10: 24/30包 | D10: 进口营多捞面多口味Indomie网红方便面干拌面泡面30包整箱批发面 | E10: 2118.55 | F10: =IFERROR(E10/1.13,0) | G10: 31 | H10: =IFERROR(G10/SUMIF($A:$A,A10,$G:$G),0) | I10: =IFERROR(E10/G10,0) | J10: 471.45125 | K10: 1689.0335 | L10: =IFERROR(K10/J10,0) | M10: 14.096462 | N10: 37.64487 | O10: =IFERROR(N10/M10,0) | P10: =J10+M10 | Q10: =K10+N10 | R10: =IFERROR(Q10/P10,0) | S10: =IFERROR(P10/SUMIF($A:$A,A10,$P:$P),0) | T10: =IFERROR(P10/E10,0) | U10: =E10-Q10 | V10: =IFERROR(U10/E10,0) | W10: =IFERROR(VLOOKUP(A10,周报其他费用!$A:$B,2,FALSE)*H10,0) | X10: 422.008 | Y10: =IFERROR(X10/F10,0) | Z10: =X10-J10/1.06 | AA10: =IFERROR(Z10/F10,0) | AB10: =X10-(P10+W10)/1.06 | AC10: =IFERROR(AB10/F10,0)
A11: 5.11-5.17 | B11: 649369494424 | C11: 24包经典/牛系列 | D11: 营多捞面干拌面一整箱24袋装批发泡面混搭宿舍速食方便面火鸡面 | E11: 1718.31 | F11: =IFERROR(E11/1.13,0) | G11: 31 | H11: =IFERROR(G11/SUMIF($A:$A,A11,$G:$G),0) | I11: =IFERROR(E11/G11,0) | J11: 214.93125 | K11: 812.64347 | L11: =IFERROR(K11/J11,0) | M11: 14.096462 | N11: 37.64487 | O11: =IFERROR(N11/M11,0) | P11: =J11+M11 | Q11: =K11+N11 | R11: =IFERROR(Q11/P11,0) | S11: =IFERROR(P11/SUMIF($A:$A,A11,$P:$P),0) | T11: =IFERROR(P11/E11,0) | U11: =E11-Q11 | V11: =IFERROR(U11/E11,0) | W11: =IFERROR(VLOOKUP(A11,周报其他费用!$A:$B,2,FALSE)*H11,0) | X11: 325.027 | Y11: =IFERROR(X11/F11,0) | Z11: =X11-J11/1.06 | AA11: =IFERROR(Z11/F11,0) | AB11: =X11-(P11+W11)/1.06 | AC11: =IFERROR(AB11/F11,0)
A12: 5.11-5.17 | B12: 929504658691 | C12: 日式袋面 | D12: 营多捞面日式鸡肉汤面原味辛辣味袋装泡面方便面速食宿舍夜宵食品 | E12: 626.32 | F12: =IFERROR(E12/1.13,0) | G12: 24 | H12: =IFERROR(G12/SUMIF($A:$A,A12,$G:$G),0) | I12: =IFERROR(E12/G12,0) | J12: 163.4571 | K12: 502.40882 | L12: =IFERROR(K12/J12,0) | M12: 10.91339 | N12: 29.144416 | O12: =IFERROR(N12/M12,0) | P12: =J12+M12 | Q12: =K12+N12 | R12: =IFERROR(Q12/P12,0) | S12: =IFERROR(P12/SUMIF($A:$A,A12,$P:$P),0) | T12: =IFERROR(P12/E12,0) | U12: =E12-Q12 | V12: =IFERROR(U12/E12,0) | W12: =IFERROR(VLOOKUP(A12,周报其他费用!$A:$B,2,FALSE)*H12,0) | X12: 110.142 | Y12: =IFERROR(X12/F12,0) | Z12: =X12-J12/1.06 | AA12: =IFERROR(Z12/F12,0) | AB12: =X12-(P12+W12)/1.06 | AC12: =IFERROR(AB12/F12,0)
A13: 5.11-5.17 | B13: 648681860568 | C13: 杯面次链接 | D13: 营多捞面杯装方便面泡面速食干拌面原味整箱批发印尼进口桶装拌面 | E13: 1000.29 | F13: =IFERROR(E13/1.13,0) | G13: 41 | H13: =IFERROR(G13/SUMIF($A:$A,A13,$G:$G),0) | I13: =IFERROR(E13/G13,0) | J13: 171.61004 | K13: 836.27298 | L13: =IFERROR(K13/J13,0) | M13: 18.643708 | N13: 49.788377 | O13: =IFERROR(N13/M13,0) | P13: =J13+M13 | Q13: =K13+N13 | R13: =IFERROR(Q13/P13,0) | S13: =IFERROR(P13/SUMIF($A:$A,A13,$P:$P),0) | T13: =IFERROR(P13/E13,0) | U13: =E13-Q13 | V13: =IFERROR(U13/E13,0) | W13: =IFERROR(VLOOKUP(A13,周报其他费用!$A:$B,2,FALSE)*H13,0) | X13: 101.013 | Y13: =IFERROR(X13/F13,0) | Z13: =X13-J13/1.06 | AA13: =IFERROR(Z13/F13,0) | AB13: =X13-(P13+W13)/1.06 | AC13: =IFERROR(AB13/F13,0)
A14: 5.11-5.17 | B14: 937005385662 | C14: 日式袋面 | D14: 进口营多正品捞面日式鸡肉鸡汤辛辣味袋装泡面辣味速食方便面汤面 | E14: 425.12 | F14: =IFERROR(E14/1.13,0) | G14: 19 | H14: =IFERROR(G14/SUMIF($A:$A,A14,$G:$G),0) | I14: =IFERROR(E14/G14,0) | J14: 181.7727 | K14: 397.10406 | L14: =IFERROR(K14/J14,0) | M14: 8.6397671 | N14: 23.072662 | O14: =IFERROR(N14/M14,0) | P14: =J14+M14 | Q14: =K14+N14 | R14: =IFERROR(Q14/P14,0) | S14: =IFERROR(P14/SUMIF($A:$A,A14,$P:$P),0) | T14: =IFERROR(P14/E14,0) | U14: =E14-Q14 | V14: =IFERROR(U14/E14,0) | W14: =IFERROR(VLOOKUP(A14,周报其他费用!$A:$B,2,FALSE)*H14,0) | X14: 75.032 | Y14: =IFERROR(X14/F14,0) | Z14: =X14-J14/1.06 | AA14: =IFERROR(Z14/F14,0) | AB14: =X14-(P14+W14)/1.06 | AC14: =IFERROR(AB14/F14,0)
... A294: 7.20-7.26 | B294: 648604228786 | C294: 杯面混搭 | D294: INDOMIE营多日式杯面原味经典泡面整箱批发速食宿舍旅行宵夜宿舍 | E294: 212.58 | F294: =IFERROR(E294/1.13,0) | G294: 8 | H294: =IFERROR(G294/SUMIF($A:$A,A294,$G:$G),0) | I294: =IFERROR(E294/G294,0) | J294: 12.025601 | K294: 8.1008177 | L294: =IFERROR(K294/J294,0) | M294: 4.8269054 | N294: 11.271071 | O294: =IFERROR(N294/M294,0) | P294: =J294+M294 | Q294: =K294+N294 | R294: =IFERROR(Q294/P294,0) | S294: =IFERROR(P294/SUMIF($A:$A,A294,$P:$P),0) | T294: =IFERROR(P294/E294,0) | U294: =E294-Q294 | V294: =IFERROR(U294/E294,0) | W294: =IFERROR(VLOOKUP(A294,周报其他费用!$A:$B,2,FALSE)*H294,0) | X294: 29.185 | Y294: =IFERROR(X294/F294,0) | Z294: =X294-J294/1.06 | AA294: =IFERROR(Z294/F294,0) | AB294: =X294-(P294+W294)/1.06 | AC294: =IFERROR(AB294/F294,0)
A295: 7.20-7.26 | B295: 976535014785 | C295: 未标注 | E295: 6.87 | F295: =IFERROR(E295/1.13,0) | G295: 7 | H295: =IFERROR(G295/SUMIF($A:$A,A295,$G:$G),0) | I295: =IFERROR(E295/G295,0) | J295: 1.6586511 | K295: 7.0882155 | L295: =IFERROR(K295/J295,0) | M295: 4.2235422 | N295: 9.8621874 | O295: =IFERROR(N295/M295,0) | P295: =J295+M295 | Q295: =K295+N295 | R295: =IFERROR(Q295/P295,0) | S295: =IFERROR(P295/SUMIF($A:$A,A295,$P:$P),0) | T295: =IFERROR(P295/E295,0) | U295: =E295-Q295 | V295: =IFERROR(U295/E295,0) | W295: =IFERROR(VLOOKUP(A295,周报其他费用!$A:$B,2,FALSE)*H295,0) | X295: 0 | Y295: =IFERROR(X295/F295,0) | Z295: =X295-J295/1.06 | AA295: =IFERROR(Z295/F295,0) | AB295: =X295-(P295+W295)/1.06 | AC295: =IFERROR(AB295/F295,0)
A296: 7.20-7.26 | B296: 971242260371 | C296: 韩式袋面 | D296: 新品营多捞面韩式辣蘑菇汤面泡面方便面速食干拌面宿舍宵夜旅行 | E296: 164.03 | F296: =IFERROR(E296/1.13,0) | G296: 9 | H296: =IFERROR(G296/SUMIF($A:$A,A296,$G:$G),0) | I296: =IFERROR(E296/G296,0) | J296: 26.578651 | K296: 189.34822 | L296: =IFERROR(K296/J296,0) | M296: 4.2235422 | N296: 9.8621874 | O296: =IFERROR(N296/M296,0) | P296: =J296+M296 | Q296: =K296+N296 | R296: =IFERROR(Q296/P296,0) | S296: =IFERROR(P296/SUMIF($A:$A,A296,$P:$P),0) | T296: =IFERROR(P296/E296,0) | U296: =E296-Q296 | V296: =IFERROR(U296/E296,0) | W296: =IFERROR(VLOOKUP(A296,周报其他费用!$A:$B,2,FALSE)*H296,0) | X296: 15.887 | Y296: =IFERROR(X296/F296,0) | Z296: =X296-J296/1.06 | AA296: =IFERROR(Z296/F296,0) | AB296: =X296-(P296+W296)/1.06 | AC296: =IFERROR(AB296/F296,0)
A297: 7.20-7.26 | B297: 937005385662 | C297: 日式袋面 | D297: 进口营多正品捞面日式鸡肉鸡汤辛辣味袋装泡面辣味速食方便面汤面 | E297: 218.59 | F297: =IFERROR(E297/1.13,0) | G297: 10 | H297: =IFERROR(G297/SUMIF($A:$A,A297,$G:$G),0) | I297: =IFERROR(E297/G297,0) | J297: 43.158651 | K297: 288.08822 | L297: =IFERROR(K297/J297,0) | M297: 4.2235422 | N297: 9.8621874 | O297: =IFERROR(N297/M297,0) | P297: =J297+M297 | Q297: =K297+N297 | R297: =IFERROR(Q297/P297,0) | S297: =IFERROR(P297/SUMIF($A:$A,A297,$P:$P),0) | T297: =IFERROR(P297/E297,0) | U297: =E297-Q297 | V297: =IFERROR(U297/E297,0) | W297: =IFERROR(VLOOKUP(A297,周报其他费用!$A:$B,2,FALSE)*H297,0) | X297: 30.148 | Y297: =IFERROR(X297/F297,0) | Z297: =X297-J297/1.06 | AA297: =IFERROR(Z297/F297,0) | AB297: =X297-(P297+W297)/1.06 | AC297: =IFERROR(AB297/F297,0)
A298: 7.20-7.26 | B298: 969433743398 | C298: 韩蘑菇 | D298: 新品营多捞面韩式辣蘑菇汤面泡面方便面速食干拌面宿舍宵夜旅行 | E298: 142.44 | F298: =IFERROR(E298/1.13,0) | G298: 7 | H298: =IFERROR(G298/SUMIF($A:$A,A298,$G:$G),0) | I298: =IFERROR(E298/G298,0) | J298: 9.001701 | K298: 41.975613 | L298: =IFERROR(K298/J298,0) | M298: 3.6201791 | N298: 8.4533035 | O298: =IFERROR(N298/M298,0) | P298: =J298+M298 | Q298: =K298+N298 | R298: =IFERROR(Q298/P298,0) | S298: =IFERROR(P298/SUMIF($A:$A,A298,$P:$P),0) | T298: =IFERROR(P298/E298,0) | U298: =E298-Q298 | V298: =IFERROR(U298/E298,0) | W298: =IFERROR(VLOOKUP(A298,周报其他费用!$A:$B,2,FALSE)*H298,0) | X298: 19.197 | Y298: =IFERROR(X298/F298,0) | Z298: =X298-J298/1.06 | AA298: =IFERROR(Z298/F298,0) | AB298: =X298-(P298+W298)/1.06 | AC298: =IFERROR(AB298/F298,0)
A299: 7.20-7.26 | B299: 1067363868298 | C299: 未标注 | E299: 93.18 | F299: =IFERROR(E299/1.13,0) | G299: 5 | H299: =IFERROR(G299/SUMIF($A:$A,A299,$G:$G),0) | I299: =IFERROR(E299/G299,0) | J299: 5.8247508 | K299: 5.063011 | L299: =IFERROR(K299/J299,0) | M299: 3.0168159 | N299: 7.0444196 | O299: =IFERROR(N299/M299,0) | P299: =J299+M299 | Q299: =K299+N299 | R299: =IFERROR(Q299/P299,0) | S299: =IFERROR(P299/SUMIF($A:$A,A299,$P:$P),0) | T299: =IFERROR(P299/E299,0) | U299: =E299-Q299 | V299: =IFERROR(U299/E299,0) | W299: =IFERROR(VLOOKUP(A299,周报其他费用!$A:$B,2,FALSE)*H299,0) | X299: 6.925 | Y299: =IFERROR(X299/F299,0) | Z299: =X299-J299/1.06 | AA299: =IFERROR(Z299/F299,0) | AB299: =X299-(P299+W299)/1.06 | AC299: =IFERROR(AB299/F299,0)
A300: 7.20-7.26 | B300: 649731447266 | C300: 20包经典/牛系列 | D300: 营多印尼进口营多捞面方便面火鸡面干拌面20包宿舍速食泡面夜宵 | E300: 243.5 | F300: =IFERROR(E300/1.13,0) | G300: 5 | H300: =IFERROR(G300/SUMIF($A:$A,A300,$G:$G),0) | I300: =IFERROR(E300/G300,0) | J300: 11.094751 | K300: 5.063011 | L300: =IFERROR(K300/J300,0) | M300: 3.0168159 | N300: 7.0444196 | O300: =IFERROR(N300/M300,0) | P300: =J300+M300 | Q300: =K300+N300 | R300: =IFERROR(Q300/P300,0) | S300: =IFERROR(P300/SUMIF($A:$A,A300,$P:$P),0) | T300: =IFERROR(P300/E300,0) | U300: =E300-Q300 | V300: =IFERROR(U300/E300,0) | W300: =IFERROR(VLOOKUP(A300,周报其他费用!$A:$B,2,FALSE)*H300,0) | X300: 50.194 | Y300: =IFERROR(X300/F300,0) | Z300: =X300-J300/1.06 | AA300: =IFERROR(Z300/F300,0) | AB300: =X300-(P300+W300)/1.06 | AC300: =IFERROR(AB300/F300,0)
A301: 7.20-7.26 | B301: 1067957289054 | C301: 巴东牛肉 | D301: 【新口味】印尼进口营多捞面巴东炖牛肉味泡面方便面宿舍速食宵夜 | E301: 60.93 | F301: =IFERROR(E301/1.13,0) | G301: 4 | H301: =IFERROR(G301/SUMIF($A:$A,A301,$G:$G),0) | I301: =IFERROR(E301/G301,0) | J301: 5.8478007 | K301: 4.0504088 | L301: =IFERROR(K301/J301,0) | M301: 2.4134527 | N301: 5.6355357 | O301: =IFERROR(N301/M301,0) | P301: =J301+M301 | Q301: =K301+N301 | R301: =IFERROR(Q301/P301,0) | S301: =IFERROR(P301/SUMIF($A:$A,A301,$P:$P),0) | T301: =IFERROR(P301/E301,0) | U301: =E301-Q301 | V301: =IFERROR(U301/E301,0) | W301: =IFERROR(VLOOKUP(A301,周报其他费用!$A:$B,2,FALSE)*H301,0) | X301: 4.936 | Y301: =IFERROR(X301/F301,0) | Z301: =X301-J301/1.06 | AA301: =IFERROR(Z301/F301,0) | AB301: =X301-(P301+W301)/1.06 | AC301: =IFERROR(AB301/F301,0)
A302: 7.20-7.26 | B302: 976467954327 | C302: 日韩杯面 | D302: 【天猫U选】indomie营多捞面辣蘑菇味日式辣味杯面 | E302: 28.22 | F302: =IFERROR(E302/1.13,0) | G302: 3 | H302: =IFERROR(G302/SUMIF($A:$A,A302,$G:$G),0) | I302: =IFERROR(E302/G302,0) | J302: 0.71085049 | K302: 3.0378066 | L302: =IFERROR(K302/J302,0) | M302: 1.8100895 | N302: 4.2266517 | O302: =IFERROR(N302/M302,0) | P302: =J302+M302 | Q302: =K302+N302 | R302: =IFERROR(Q302/P302,0) | S302: =IFERROR(P302/SUMIF($A:$A,A302,$P:$P),0) | T302: =IFERROR(P302/E302,0) | U302: =E302-Q302 | V302: =IFERROR(U302/E302,0) | W302: =IFERROR(VLOOKUP(A302,周报其他费用!$A:$B,2,FALSE)*H302,0) | X302: -5.289 | Y302: =IFERROR(X302/F302,0) | Z302: =X302-J302/1.06 | AA302: =IFERROR(Z302/F302,0) | AB302: =X302-(P302+W302)/1.06 | AC302: =IFERROR(AB302/F302,0)
A303: 7.20-7.26 | B303: 932687928859 | C303: 8包组合 | D303: 营多捞面八口味袋装泡面拌面速食面干拌面方便面宿舍宵夜速食家用 | E303: 75.92 | F303: =IFERROR(E303/1.13,0) | G303: 3 | H303: =IFERROR(G303/SUMIF($A:$A,A303,$G:$G),0) | I303: =IFERROR(E303/G303,0) | J303: 7.5908505 | K303: 3.0378066 | L303: =IFERROR(K303/J303,0) | M303: 1.8100895 | N303: 4.2266517 | O303: =IFERROR(N303/M303,0) | P303: =J303+M303 | Q303: =K303+N303 | R303: =IFERROR(Q303/P303,0) | S303: =IFERROR(P303/SUMIF($A:$A,A303,$P:$P),0) | T303: =IFERROR(P303/E303,0) | U303: =E303-Q303 | V303: =IFERROR(U303/E303,0) | W303: =IFERROR(VLOOKUP(A303,周报其他费用!$A:$B,2,FALSE)*H303,0) | X303: 11.502 | Y303: =IFERROR(X303/F303,0) | Z303: =X303-J303/1.06 | AA303: =IFERROR(Z303/F303,0) | AB303: =X303-(P303+W303)/1.06 | AC303: =IFERROR(AB303/F303,0)
A304: 7.20-7.26 | B304: 976466902934 | C304: 【U选】日式原杯1+日式辣杯1 | D304: 【天猫U选】indomie营多捞面辣火鸡味日式鸡肉原味杯面 | E304: 29.5 | F304: =IFERROR(E304/1.13,0) | G304: 3 | H304: =IFERROR(G304/SUMIF($A:$A,A304,$G:$G),0) | I304: =IFERROR(E304/G304,0) | J304: 0.71085049 | K304: 3.0378066 | L304: =IFERROR(K304/J304,0) | M304: 1.8100895 | N304: 4.2266517 | O304: =IFERROR(N304/M304,0) | P304: =J304+M304 | Q304: =K304+N304 | R304: =IFERROR(Q304/P304,0) | S304: =IFERROR(P304/SUMIF($A:$A,A304,$P:$P),0) | T304: =IFERROR(P304/E304,0) | U304: =E304-Q304 | V304: =IFERROR(U304/E304,0) | W304: =IFERROR(VLOOKUP(A304,周报其他费用!$A:$B,2,FALSE)*H304,0) | X304: -4.241 | Y304: =IFERROR(X304/F304,0) | Z304: =X304-J304/1.06 | AA304: =IFERROR(Z304/F304,0) | AB304: =X304-(P304+W304)/1.06 | AC304: =IFERROR(AB304/F304,0)
A305: 7.20-7.26 | B305: 1067350828719 | C305: 未标注 | E305: 148.7 | F305: =IFERROR(E305/1.13,0) | G305: 3 | H305: =IFERROR(G305/SUMIF($A:$A,A305,$G:$G),0) | I305: =IFERROR(E305/G305,0) | J305: 3.7539003 | K305: 20.485204 | L305: =IFERROR(K305/J305,0) | M305: 1.2067264 | N305: 2.8177678 | O305: =IFERROR(N305/M305,0) | P305: =J305+M305 | Q305: =K305+N305 | R305: =IFERROR(Q305/P305,0) | S305: =IFERROR(P305/SUMIF($A:$A,A305,$P:$P),0) | T305: =IFERROR(P305/E305,0) | U305: =E305-Q305 | V305: =IFERROR(U305/E305,0) | W305: =IFERROR(VLOOKUP(A305,周报其他费用!$A:$B,2,FALSE)*H305,0) | X305: 31.483 | Y305: =IFERROR(X305/F305,0) | Z305: =X305-J305/1.06 | AA305: =IFERROR(Z305/F305,0) | AB305: =X305-(P305+W305)/1.06 | AC305: =IFERROR(AB305/F305,0)
A306: 7.20-7.26 | B306: 975092562679 | C306: 杯面混搭 | D306: 营多韩式甜辣炸鸡火鸡面辣蘑菇杯面拌面泡面方便面速食宵夜旅行 | E306: 59.33 | F306: =IFERROR(E306/1.13,0) | G306: 2 | H306: =IFERROR(G306/SUMIF($A:$A,A306,$G:$G),0) | I306: =IFERROR(E306/G306,0) | J306: 1.7139003 | K306: 51.925204 | L306: =IFERROR(K306/J306,0) | M306: 1.2067264 | N306: 2.8177678 | O306: =IFERROR(N306/M306,0) | P306: =J306+M306 | Q306: =K306+N306 | R306: =IFERROR(Q306/P306,0) | S306: =IFERROR(P306/SUMIF($A:$A,A306,$P:$P),0) | T306: =IFERROR(P306/E306,0) | U306: =E306-Q306 | V306: =IFERROR(U306/E306,0) | W306: =IFERROR(VLOOKUP(A306,周报其他费用!$A:$B,2,FALSE)*H306,0) | X306: 12.234 | Y306: =IFERROR(X306/F306,0) | Z306: =X306-J306/1.06 | AA306: =IFERROR(Z306/F306,0) | AB306: =X306-(P306+W306)/1.06 | AC306: =IFERROR(AB306/F306,0)
A307: 7.20-7.26 | B307: 869217868453 | C307: 韩式杯面 | D307: 营多捞面韩式甜辣炸鸡辣蘑菇杯面方便面拌面泡面宿舍速食面 | E307: 32.79 | F307: =IFERROR(E307/1.13,0) | G307: 2 | H307: =IFERROR(G307/SUMIF($A:$A,A307,$G:$G),0) | I307: =IFERROR(E307/G307,0) | J307: 13.7639 | K307: 123.4052 | L307: =IFERROR(K307/J307,0) | M307: 1.2067264 | N307: 2.8177678 | O307: =IFERROR(N307/M307,0) | P307: =J307+M307 | Q307: =K307+N307 | R307: =IFERROR(Q307/P307,0) | S307: =IFERROR(P307/SUMIF($A:$A,A307,$P:$P),0) | T307: =IFERROR(P307/E307,0) | U307: =E307-Q307 | V307: =IFERROR(U307/E307,0) | W307: =IFERROR(VLOOKUP(A307,周报其他费用!$A:$B,2,FALSE)*H307,0) | X307: 0.66 | Y307: =IFERROR(X307/F307,0) | Z307: =X307-J307/1.06 | AA307: =IFERROR(Z307/F307,0) | AB307: =X307-(P307+W307)/1.06 | AC307: =IFERROR(AB307/F307,0)
A308: 7.20-7.26 | B308: 976479938842 | C308: 杯面混搭 | D308: 营多捞面韩式甜辣炸鸡辣蘑菇杯面方便面拌面泡面宿舍速食面 | E308: 18.9 | F308: =IFERROR(E308/1.13,0) | G308: 2 | H308: =IFERROR(G308/SUMIF($A:$A,A308,$G:$G),0) | I308: =IFERROR(E308/G308,0) | J308: 0.47390033 | K308: 2.0252044 | L308: =IFERROR(K308/J308,0) | M308: 1.2067264 | N308: 2.8177678 | O308: =IFERROR(N308/M308,0) | P308: =J308+M308 | Q308: =K308+N308 | R308: =IFERROR(Q308/P308,0) | S308: =IFERROR(P308/SUMIF($A:$A,A308,$P:$P),0) | T308: =IFERROR(P308/E308,0) | U308: =E308-Q308 | V308: =IFERROR(U308/E308,0) | W308: =IFERROR(VLOOKUP(A308,周报其他费用!$A:$B,2,FALSE)*H308,0) | X308: -6.263 | Y308: =IFERROR(X308/F308,0) | Z308: =X308-J308/1.06 | AA308: =IFERROR(Z308/F308,0) | AB308: =X308-(P308+W308)/1.06 | AC308: =IFERROR(AB308/F308,0)
A309: 7.20-7.26 | B309: 903183018417 | C309: 杯面混搭 | D309: 印尼进口营多捞面杯面原味甜辣蘑菇味整箱速食拌面拉面泡面方便面 | E309: 38.36 | F309: =IFERROR(E309/1.13,0) | G309: 2 | H309: =IFERROR(G309/SUMIF($A:$A,A309,$G:$G),0) | I309: =IFERROR(E309/G309,0) | J309: 3.5139003 | K309: 2.0252044 | L309: =IFERROR(K309/J309,0) | M309: 1.2067264 | N309: 2.8177678 | O309: =IFERROR(N309/M309,0) | P309: =J309+M309 | Q309: =K309+N309 | R309: =IFERROR(Q309/P309,0) | S309: =IFERROR(P309/SUMIF($A:$A,A309,$P:$P),0) | T309: =IFERROR(P309/E309,0) | U309: =E309-Q309 | V309: =IFERROR(U309/E309,0) | W309: =IFERROR(VLOOKUP(A309,周报其他费用!$A:$B,2,FALSE)*H309,0) | X309: 3.134 | Y309: =IFERROR(X309/F309,0) | Z309: =X309-J309/1.06 | AA309: =IFERROR(Z309/F309,0) | AB309: =X309-(P309+W309)/1.06 | AC309: =IFERROR(AB309/F309,0)
A310: 7.27-8.2 | B310: 668566625747 | C310: 袋面主链接 | D310: 印尼营多捞面进口网红泡面袋装方便面速食食品拉面火鸡面拌面整箱 | E310: 38360 | F310: =IFERROR(E310/1.13,0) | G310: 1566 | H310: =IFERROR(G310/SUMIF($A:$A,A310,$G:$G),0) | I310: =IFERROR(E310/G310,0) | J310: 4534.4611 | K310: 31378.871 | L310: =IFERROR(K310/J310,0) | M310: 788.99058 | N310: 1697.1515 | O310: =IFERROR(N310/M310,0) | P310: =J310+M310 | Q310: =K310+N310 | R310: =IFERROR(Q310/P310,0) | S310: =IFERROR(P310/SUMIF($A:$A,A310,$P:$P),0) | T310: =IFERROR(P310/E310,0) | U310: =E310-Q310 | V310: =IFERROR(U310/E310,0) | W310: =IFERROR(VLOOKUP(A310,周报其他费用!$A:$B,2,FALSE)*H310,0) | X310: 5163.457 | Y310: =IFERROR(X310/F310,0) | Z310: =X310-J310/1.06 | AA310: =IFERROR(Z310/F310,0) | AB310: =X310-(P310+W310)/1.06 | AC310: =IFERROR(AB310/F310,0)
A311: 7.27-8.2 | B311: 649361890551 | C311: 袋面次链接 | D311: 营多捞面印尼进口Indomie网红夜宵早餐方便面火鸡面泡面拌面 | E311: 15822.7 | F311: =IFERROR(E311/1.13,0) | G311: 793 | H311: =IFERROR(G311/SUMIF($A:$A,A311,$G:$G),0) | I311: =IFERROR(E311/G311,0) | J311: 2709.3747 | K311: 14621.872 | L311: =IFERROR(K311/J311,0) | M311: 399.53355 | N311: 859.41326 | O311: =IFERROR(N311/M311,0) | P311: =J311+M311 | Q311: =K311+N311 | R311: =IFERROR(Q311/P311,0) | S311: =IFERROR(P311/SUMIF($A:$A,A311,$P:$P),0) | T311: =IFERROR(P311/E311,0) | U311: =E311-Q311 | V311: =IFERROR(U311/E311,0) | W311: =IFERROR(VLOOKUP(A311,周报其他费用!$A:$B,2,FALSE)*H311,0) | X311: 1570.043 | Y311: =IFERROR(X311/F311,0) | Z311: =X311-J311/1.06 | AA311: =IFERROR(Z311/F311,0) | AB311: =X311-(P311+W311)/1.06 | AC311: =IFERROR(AB311/F311,0)
A312: 7.27-8.2 | B312: 649735171438 | C312: 杯面主链接 | D312: 印尼进口indomie营多捞面杯面速食泡面干拌面盒桶装方便面火鸡面 | E312: 15355.2 | F312: =IFERROR(E312/1.13,0) | G312: 619 | H312: =IFERROR(G312/SUMIF($A:$A,A312,$G:$G),0) | I312: =IFERROR(E312/G312,0) | J312: 2185.0345 | K312: 10082.831 | L312: =IFERROR(K312/J312,0) | M312: 311.86793 | N312: 670.84087 | O312: =IFERROR(N312/M312,0) | P312: =J312+M312 | Q312: =K312+N312 | R312: =IFERROR(Q312/P312,0) | S312: =IFERROR(P312/SUMIF($A:$A,A312,$P:$P),0) | T312: =IFERROR(P312/E312,0) | U312: =E312-Q312 | V312: =IFERROR(U312/E312,0) | W312: =IFERROR(VLOOKUP(A312,周报其他费用!$A:$B,2,FALSE)*H312,0) | X312: 1871.199 | Y312: =IFERROR(X312/F312,0) | Z312: =X312-J312/1.06 | AA312: =IFERROR(Z312/F312,0) | AB312: =X312-(P312+W312)/1.06 | AC312: =IFERROR(AB312/F312,0)
A313: 7.27-8.2 | B313: 1058280415678 | C313: 原味大包 | D313: 印尼进口大大包营多原味捞面5包干拌面速食超大包方便面速食宵夜 | E313: 5107.37 | F313: =IFERROR(E313/1.13,0) | G313: 184 | H313: =IFERROR(G313/SUMIF($A:$A,A313,$G:$G),0) | I313: =IFERROR(E313/G313,0) | J313: 858.63922 | K313: 4651.7177 | L313: =IFERROR(K313/J313,0) | M313: 92.703874 | N313: 199.40989 | O313: =IFERROR(N313/M313,0) | P313: =J313+M313 | Q313: =K313+N313 | R313: =IFERROR(Q313/P313,0) | S313: =IFERROR(P313/SUMIF($A:$A,A313,$P:$P),0) | T313: =IFERROR(P313/E313,0) | U313: =E313-Q313 | V313: =IFERROR(U313/E313,0) | W313: =IFERROR(VLOOKUP(A313,周报其他费用!$A:$B,2,FALSE)*H313,0) | X313: 1095.84 | Y313: =IFERROR(X313/F313,0) | Z313: =X313-J313/1.06 | AA313: =IFERROR(Z313/F313,0) | AB313: =X313-(P313+W313)/1.06 | AC313: =IFERROR(AB313/F313,0)
A314: 7.27-8.2 | B314: 1057479227624 | C314: 巴东牛肉 | D314: 【新口味】印尼进口营多捞面巴东炖牛肉味泡面方便面宿舍速食宵夜 | E314: 2736.09 | F314: =IFERROR(E314/1.13,0) | G314: 157 | H314: =IFERROR(G314/SUMIF($A:$A,A314,$G:$G),0) | I314: =IFERROR(E314/G314,0) | J314: 805.60868 | K314: 3892.9062 | L314: =IFERROR(K314/J314,0) | M314: 79.100589 | N314: 170.14865 | O314: =IFERROR(N314/M314,0) | P314: =J314+M314 | Q314: =K314+N314 | R314: =IFERROR(Q314/P314,0) | S314: =IFERROR(P314/SUMIF($A:$A,A314,$P:$P),0) | T314: =IFERROR(P314/E314,0) | U314: =E314-Q314 | V314: =IFERROR(U314/E314,0) | W314: =IFERROR(VLOOKUP(A314,周报其他费用!$A:$B,2,FALSE)*H314,0) | X314: 299.643 | Y314: =IFERROR(X314/F314,0) | Z314: =X314-J314/1.06 | AA314: =IFERROR(Z314/F314,0) | AB314: =X314-(P314+W314)/1.06 | AC314: =IFERROR(AB314/F314,0)
A315: 7.27-8.2 | B315: 648600900806 | C315: 30包 | D315: 进口营多捞面一整箱30包网红速食方便面宿舍速食泡面干拌面拉面 | E315: 10398.16 | F315: =IFERROR(E315/1.13,0) | G315: 153 | H315: =IFERROR(G315/SUMIF($A:$A,A315,$G:$G),0) | I315: =IFERROR(E315/G315,0) | J315: 2406.263 | K315: 10799.196 | L315: =IFERROR(K315/J315,0) | M315: 77.085287 | N315: 165.81366 | O315: =IFERROR(N315/M315,0) | P315: =J315+M315 | Q315: =K315+N315 | R315: =IFERROR(Q315/P315,0) | S315: =IFERROR(P315/SUMIF($A:$A,A315,$P:$P),0) | T315: =IFERROR(P315/E315,0) | U315: =E315-Q315 | V315: =IFERROR(U315/E315,0) | W315: =IFERROR(VLOOKUP(A315,周报其他费用!$A:$B,2,FALSE)*H315,0) | X315: 1930.47 | Y315: =IFERROR(X315/F315,0) | Z315: =X315-J315/1.06 | AA315: =IFERROR(Z315/F315,0) | AB315: =X315-(P315+W315)/1.06 | AC315: =IFERROR(AB315/F315,0)
A316: 7.27-8.2 | B316: 649369494424 | C316: 24包经典/牛系列 | D316: 营多捞面干拌面一整箱24袋装批发泡面混搭宿舍速食方便面火鸡面 | E316: 4152.8 | F316: =IFERROR(E316/1.13,0) | G316: 75 | H316: =IFERROR(G316/SUMIF($A:$A,A316,$G:$G),0) | I316: =IFERROR(E316/G316,0) | J316: 613.92816 | K316: 2197.7288 | L316: =IFERROR(K316/J316,0) | M316: 37.786905 | N316: 81.281204 | O316: =IFERROR(N316/M316,0) | P316: =J316+M316 | Q316: =K316+N316 | R316: =IFERROR(Q316/P316,0) | S316: =IFERROR(P316/SUMIF($A:$A,A316,$P:$P),0) | T316: =IFERROR(P316/E316,0) | U316: =E316-Q316 | V316: =IFERROR(U316/E316,0) | W316: =IFERROR(VLOOKUP(A316,周报其他费用!$A:$B,2,FALSE)*H316,0) | X316: 783.066 | Y316: =IFERROR(X316/F316,0) | Z316: =X316-J316/1.06 | AA316: =IFERROR(Z316/F316,0) | AB316: =X316-(P316+W316)/1.06 | AC316: =IFERROR(AB316/F316,0)
A317: 7.27-8.2 | B317: 648681860568 | C317: 杯面次链接 | D317: 营多捞面杯装方便面泡面速食干拌面原味整箱批发印尼进口桶装拌面 | E317: 1135.09 | F317: =IFERROR(E317/1.13,0) | G317: 66 | H317: =IFERROR(G317/SUMIF($A:$A,A317,$G:$G),0) | I317: =IFERROR(E317/G317,0) | J317: 250.35798 | K317: 1223.825 | L317: =IFERROR(K317/J317,0) | M317: 33.252477 | N317: 71.52746 | O317: =IFERROR(N317/M317,0) | P317: =J317+M317 | Q317: =K317+N317 | R317: =IFERROR(Q317/P317,0) | S317: =IFERROR(P317/SUMIF($A:$A,A317,$P:$P),0) | T317: =IFERROR(P317/E317,0) | U317: =E317-Q317 | V317: =IFERROR(U317/E317,0) | W317: =IFERROR(VLOOKUP(A317,周报其他费用!$A:$B,2,FALSE)*H317,0) | X317: 21.311 | Y317: =IFERROR(X317/F317,0) | Z317: =X317-J317/1.06 | AA317: =IFERROR(Z317/F317,0) | AB317: =X317-(P317+W317)/1.06 | AC317: =IFERROR(AB317/F317,0)
... A346: 7.27-8.2 | B346: 947413291596 | C346: 杯面混搭 | D346: 印尼进口营多捞面杯面原味甜辣蘑菇味整箱速食拌面拉面泡面方便面 | E346: 55.15 | F346: =IFERROR(E346/1.13,0) | G346: 2 | H346: =IFERROR(G346/SUMIF($A:$A,A346,$G:$G),0) | I346: =IFERROR(E346/G346,0) | J346: 5.5478176 | K346: 2.3453016 | L346: =IFERROR(K346/J346,0) | M346: 1.0076508 | N346: 2.1674988 | O346: =IFERROR(N346/M346,0) | P346: =J346+M346 | Q346: =K346+N346 | R346: =IFERROR(Q346/P346,0) | S346: =IFERROR(P346/SUMIF($A:$A,A346,$P:$P),0) | T346: =IFERROR(P346/E346,0) | U346: =E346-Q346 | V346: =IFERROR(U346/E346,0) | W346: =IFERROR(VLOOKUP(A346,周报其他费用!$A:$B,2,FALSE)*H346,0) | X346: 6.768 | Y346: =IFERROR(X346/F346,0) | Z346: =X346-J346/1.06 | AA346: =IFERROR(Z346/F346,0) | AB346: =X346-(P346+W346)/1.06 | AC346: =IFERROR(AB346/F346,0)

Sheet 周报其他费用
A1: 周报其他费用（输入表）
A2: 绿色单元格为输入；数据源其他费用通过 VLOOKUP 引用本表
